Workbook
Name Ath: 'NPC-Rechner'!$N$6
Name athb: 'NPC-Rechner'!$O$6
Name Aur: 'NPC-Rechner'!$E$8
Name Aus: 'NPC-Rechner'!$I$6
Name ausb: 'NPC-Rechner'!$J$6
Name ausdauer: 'NPC-Rechner'!$Y$28
Name ausdauerw: 'NPC-Rechner'!$S$8
Name AW: 'NPC-Rechner'!$Y$20
Name bearme: 'RS-Sheet'!$F$23
Name bebeine: 'RS-Sheet'!$F$31
Name bekopf: 'RS-Sheet'!$F$7
Name betorso: 'RS-Sheet'!$F$15
Name dauerE: 'NPC-Rechner'!$T$21
Name dauerl: 'NPC-Rechner'!$AD$25
Name defaw: 'NPC-Rechner'!$G$14
Name ep: 'NPC-Rechner'!$AO$4
Name epfrei: 'NPC-Rechner'!$AO$6
Name Flieg: 'NPC-Rechner'!$AD$20
Name Fliege: 'NPC-Rechner'!$AD$20
Name Fliegen: 'NPC-Rechner'!$AD$20
Name gAW: 'NPC-Rechner'!$Y$21
Name gawwert: 'NPC-Rechner'!$G$15
Name GBE: 'NPC-Rechner'!$S$13
Name gefins: 'NPC-Rechner'!$Y$33
Name Ges: 'NPC-Rechner'!$N$7
Name GesamteTAP: Talente!$D$146
Name gesb: 'NPC-Rechner'!$O$7
Name gesundheit: 'NPC-Rechner'!$E$20
Name glü: 'NPC-Rechner'!$E$6
Name Hauszauber: 'NPC-Rechner'!$AO$13
Name hochsp: 'NPC-Rechner'!$N$29
Name ini: 'NPC-Rechner'!$G$17
Name Int: 'NPC-Rechner'!$I$7
Name intb: 'NPC-Rechner'!$J$7
Name kar: 'NPC-Rechner'!$E$10
Name Klett: 'NPC-Rechner'!$AD$21
Name Klettern: 'NPC-Rechner'!$AD$21
Name Koerp: 'NPC-Rechner'!$AD$22
Name Koerperb: 'NPC-Rechner'!$AD$22
Name Kon: 'NPC-Rechner'!$N$8
Name konb: 'NPC-Rechner'!$O$8
Name Konzentration: 'NPC-Rechner'!$Y$29
Name kr: 'NPC-Rechner'!$C$6
Name LEbrust: 'NPC-Rechner'!$E$22
Name LEkopf: 'NPC-Rechner'!$E$21
Name LElarm: 'NPC-Rechner'!$E$25
Name lelbein: 'NPC-Rechner'!$E$27
Name LErarm: 'NPC-Rechner'!$E$24
Name lerbein: 'NPC-Rechner'!$E$26
Name LEunter: 'NPC-Rechner'!$E$23
Name lufta: 'NPC-Rechner'!$AD$26
Name ma: 'NPC-Rechner'!$C$8
Name mag: 'NPC-Rechner'!$E$9
Name MagierTAP: Talente!$D$147
Name Manataw: 'NPC-Rechner'!$Y$31
Name mAW: 'NPC-Rechner'!$Y$22
Name mawwert: 'NPC-Rechner'!$G$16
Name mk: 'NPC-Rechner'!$C$10
Name MKTaW: 'NPC-Rechner'!$Y$32
Name mn: 'NPC-Rechner'!$C$9

Sheet NPC-Rechner
A1: NPC-AUSGABE | V1: GENERIERUNG
D3: NPC Name: | X3: Wert | Z3: Bonus | AC3: Wert | AE3: Bonus | AH3: Wert
V4: Ausstrahlung | X4: 14 | Z4: =ROUNDUP((X4+Y4)/2,0)-5 -> 2 | AA4: Athletik | AC4: 16 | AE4: =ROUNDUP((AC4+AD4)/2,0)-5 -> 3 | AF4: Glück | AH4: 3 | AI4: erhaltene EP | AO4: 13692
H5: Artefakt | I5: Wert | J5: Bonus | M5: Artefakt | N5: Wert | O5: Bonus | V5: Intelligenz | X5: 20 | Z5: =ROUNDUP((X5+Y5)/2,0)-5 -> 5 | AA5: Geschicklichkeit | AC5: 16 | AE5: =ROUNDUP((AC5+AD5)/2,0)-5 -> 3 | AF5: Vitalität | AH5: 14 | AI5: verbrauchte EP | AO5: =SUM(AB10:AC14,AJ10:AK13) -> 17207
A6: Kreis | C6: =IF(AO4<Ressourcen!H17,0,(IF(AO4<Ressourcen!H20,1,(IF(AO4<Ressourcen!H25,2,(IF(AO4<Ressourcen!H32,3,(IF(AO4<Ressourcen!H41,4,(IF(AO4<Ressourcen!H52,5,(IF(AO4<Ressourcen!H65,6,7))))))))))))) -> 7 | D6: GLÜ | E6: =AH4 -> 3 | F6: Aus | H6: 7 | I6: =X4+H6 -> 21 | J6: =ROUNDUP(Aus/2,0)-5 -> 6 | K6: Ath | M6: 7 | N6: =AC4+M6 -> 23 | O6: =ROUNDUP(Ath/2,0)-5 -> 7 | V6: Mut | X6: 14 | Z6: =ROUNDUP((X6+Y6)/2,0)-5 -> 2 | AA6: Konstitution | AC6: 31 | AE6: =ROUNDUP((AC6+AD6)/2,0)-5 -> 11 | AF6: Aura | AH6: 5 | AI6: freie EP | AO6: =SUM(AO4-AJ14+6400)-SUM(AB10:AC14,AJ10:AK13) -> 0
A7: Stufe | C7: =IF(AO4<20,0,VLOOKUP(AO4,Ressourcen!H17:J79,2)) -> 58 | D7: VIT | E7: =AH5 -> 14 | F7: Int | H7: 7 | I7: =H7+X5 -> 27 | J7: =ROUNDUP(Int/2,0)-5 -> 9 | K7: Ges | M7: 7 | N7: =AC5+M7 -> 23 | O7: =ROUNDUP(Ges/2,0)-5 -> 7 | V7: Sinnesschärfe | X7: 14 | Z7: =ROUNDUP((X7+Y7)/2,0)-5 -> 2 | AA7: Schnelligkeit | AC7: 14 | AE7: =ROUNDUP((AC7+AD7)/2,0)-5 -> 2 | AF7: Magie | AH7: 5 | AI7: Talentpunkte | AO7: =VLOOKUP(st,Ressourcen!$I$17:$K$80,3,FALSE) -> 310
A8: Macht | C8: =IF(((SUM(Aur+mag+wei+kar+kr+wilb))>=0),(SUM(Aur+mag+kar+wei+kr+wilb)),0) -> 27 | D8: AUR | E8: =AH6 -> 5 | F8: Mut | H8: 7 | I8: =X6+H8 -> 21 | J8: =ROUNDUP(Mut/2,0)-5 -> 6 | K8: Kon | M8: 7 | N8: =AC6+M8 -> 38 | O8: =ROUNDUP(Kon/2,0)-5 -> 14 | P8: Ausdauer | S8: =Ath+2*Kon+ROUNDUP((Stä/2),0)+3*vit+st -> 212 | V8: Willenskraft | X8: 22 | Z8: =ROUNDUP((X8+Y8)/2,0)-5 -> 6 | AA8: Stärke | AC8: 18 | AE8: =ROUNDUP((AC8+AD8)/2,0)-5 -> 4 | AF8: Karma | AH8: 0 | AI8: verbrauchte Talentpunkte | AO8: =[0]!GesamteTAP -> 467
A9: Mana | C9: =IF(((Aur*7+mag*3+3*Wil-30+intb*wei+st+Y31*2)>=0),(Aur*7+mag*3+3*Wil-30+intb*wei+st+Y31*2),0) -> 165 | D9: MAG | E9: =AH7 -> 5 | F9: Sin | H9: 7 | I9: =X7+H9 -> 21 | J9: =ROUNDUP(Sin/2,0)-5 -> 6 | K9: Sch | M9: 7 | N9: =AC7+M9 -> 21 | O9: =ROUNDUP(Sch/2,0)-5 -> 6
A10: MK | C10: =Wil+Aur+st+MKTaW -> 92 | D10: KAR | E10: =AH8 -> 0 | F10: Wil | H10: 7 | I10: =X8+H10 -> 29 | J10: =ROUNDUP(Wil/2,0)-5 -> 10 | K10: Stä | M10: 7 | N10: =AC8+M10 -> 25 | O10: =ROUNDUP(Stä/2,0)-5 -> 8 | V10: Eigenschafts-EP | AB10: =SUM(AI186:AJ190) -> 6579 | AD10: Spruchzauber-Fertigkeiten | AJ10: =SUM(J103:J123,J125:J150,U103:U108,U110:U137,U139:U149,AE103:AE125,AE127:AE150,AP103:AP150,J153:J174,J176:J197,U153:U174,U176:U197,AE153:AE174) -> 3488 | AL10: TAP | AO10: =20+st*5 -> 310
A11: Weisheit | C11: =kr+1 -> 8 | V11: Attributs-EP | AB11: =SUM(AK186:AK190) -> 3200 | AD11: WHKs | AJ11: =SUM(AP20:AP49)+VLOOKUP(AD41,Ressourcen!$A$3:$D$67,4,FALSE)+VLOOKUP(AD42,Ressourcen!$A$3:$D$67,4,FALSE)+VLOOKUP(AD43,Ressourcen!$A$3:$D$67,4,FALSE)+VLOOKUP(AD44,Ressourcen!$A$3:$D$67,4,FALSE)+VLOOKUP(AD45,Ressourcen!$A$3:$D$67,4,FALSE)+VLOOKUP(AD46,Ressourcen!$A$3:$D$67,4,FALSE)+VLOOKUP(AD48,Ressourcen!$A$3:$D$67,4,FALSE)+VLOOKUP(AD49,Ressourcen!$A$3:$D$67,4,FALSE) -> 754 | AL11: TAP frei | AO11: =TaP-[0]!GesamteTAP -> -157
V12: NK-TaW-EP | AB12: =SUM($E$52:$F$74)*25+SUM($K$52:$L$74)*15+SUM($M$52:$N$74)*8+SUM($O$52:$P$74)*4 -> 1332 | AD12: KI-Zauberfertigkeiten | AJ12: =SUM(G83:H97,Q83:R95) -> 0 | AL12: Magier TAP | AO12: =MagierTAP -> 281
A13: Offensives AW | G13: =ROUNDUP((Ath+Sch+glü+AW)/5,0)+2-GBE -> 14 | P13: GBE | V13: FK-TaW-EP | AB13: =SUM($C$77,$C$78)*18+SUM($G$77:$H$80)*10+SUM($I$77:$J$80)*5+SUM($K$77:$L$80)*3 -> 0 | AD13: PSI-Zauberfertigkeiten | AJ13: =E99*9 -> 0 | AL13: Hauszauber | AO13: =IF(MagierTAP<=12,0,IF(MagierTAP<36,1,IF(MagierTAP<72,2,IF(MagierTAP<130,3,IF(MagierTAP<210,4,IF(MagierTAP<280,5,IF(MagierTAP<358,6,7))))))) -> 6
A14: Defensives AW | G14: =ROUNDUP((Ath+Sch+glü+AW)/5,0)+6-GBE -> 18 | V14: Grund- & Sonderfertigkeiten | AB14: =SUM($Y$20:$Y$43,$AD$20:$AD$37)*9 -> 1854 | AD14: EP aus Vor- und Nachteilen | AJ14: =SUM(AE52:AE100,AP52:AP100) -> 2885
A15: Gutes AW | G15: =IF((athb+gAW)<=0,1,ROUNDUP((athb+gAW)/5,0)+1) -> 5 | P15: freie RBE | S15: =ROUNDUP(((ROUNDUP(Kon/5,0)+Stä)/2),0)+RS -> 29
A16: Meisterliches AW | G16: =IF((schb+mAW)<=0,21,ROUNDUP((schb+mAW)/5,0)+21) -> 25
A17: Initiative | G17: =ROUNDUP(((Mut+Sch)/2),0)+ROUNDUP(((Int+Ges+Ath)/6),0) -> 34
A18: Selbstbeherrschung | G18: =ROUNDUP((Mut+Wil+Kon+Stä+SB)/7,0)+vit+12+IF(Talente!E77="Ja",3,IF(Talente!E76="Ja",3,IF(Talente!E75="Ja",1,0))) -> 47 | AK18: Spezialisierung
Q19: GBE-Faktor fehlt | V19: Sonderfertigkeiten | Y19: TaW | Z19: Grundfertigkeiten | AD19: TaW | AE19: WHKs | AI19: TaW | AK19: 1 | AL19: 2 | AM19: 3 | AN19: 4 | AO19: 5 | AP19: EP
A20: Gesundheit | E20: =ROUNDUP((Wil+Kon+kr)/3,0)+vit+IF(Talente!E77="Ja",7,IF(Talente!E76="Ja",4,IF(Talente!E75="Ja",2,0))) -> 46 | H20: Traglast | N20: bis kg | P20: Fortbewegung | T20: m/s | V20: Ausweichen | Y20: 12 | Z20: Fliegen | AD20: 0 | AE20: Bogenbau | AI20: 12 | AK20: 12 | AL20: 10 | AM20: 0 | AN20: 0 | AO20: 0 | AP20: =VLOOKUP(AI20,Ressourcen!$A$3:$E$68,4,FALSE)+VLOOKUP(AK20,Ressourcen!$A$72:$C$111,3,FALSE)+VLOOKUP(AL20,Ressourcen!$A$72:$C$111,3,FALSE)+VLOOKUP(AM20,Ressourcen!$A$72:$C$111,3,FALSE)+VLOOKUP(AN20,Ressourcen!$A$72:$C$111,3,FALSE)+VLOOKUP(AO20,Ressourcen!$A$72:$C$111,3,FALSE) -> 128
A21: LE Kopf | E21: =ROUNDUP((Kon/4),0)+vit+4 -> 28 | H21: Unbelastet | N21: =ROUNDUP((Stä+tragen)*0.5,0) -> 13 | P21: Dauerlauf | T21: =ROUNDUP((Kon+Ath+dauerl)/9,2)+1 -> 8.45 | V21: Gutes AW | Y21: 12 | Z21: Klettern | AD21: 6 | AE21: Überleben | AI21: 12 | AK21: 12 | AL21: 10 | AM21: 0 | AN21: 0 | AO21: 0 | AP21: =VLOOKUP(AI21,Ressourcen!$A$3:$E$68,4,FALSE)+VLOOKUP(AK21,Ressourcen!$A$72:$C$111,3,FALSE)+VLOOKUP(AL21,Ressourcen!$A$72:$C$111,3,FALSE)+VLOOKUP(AM21,Ressourcen!$A$72:$C$111,3,FALSE)+VLOOKUP(AN21,Ressourcen!$A$72:$C$111,3,FALSE)+VLOOKUP(AO21,Ressourcen!$A$72:$C$111,3,FALSE) -> 128
A22: LE Brust | E22: =ROUNDUP((ROUNDUP(Stä*2/5,0)+Kon+vit)/2,0)+10 -> 41 | H22: Ausgerüstet | N22: =ROUNDUP((Stä+tragen)*1.5,0) -> 38 | P22: Sprint | T22: =ROUNDUP(((Ath+Sch+Sprint)/7),2)+4 -> 11.29 | V22: Meisterl. AW | Y22: 12 | Z22: Körperbeherrschung | AD22: 12 | AE22: jagen | AI22: 12 | AK22: 12 | AL22: 10 | AM22: 0 | AN22: 0 | AO22: 0 | AP22: =VLOOKUP(AI22,Ressourcen!$A$3:$E$68,4,FALSE)+VLOOKUP(AK22,Ressourcen!$A$72:$C$111,3,FALSE)+VLOOKUP(AL22,Ressourcen!$A$72:$C$111,3,FALSE)+VLOOKUP(AM22,Ressourcen!$A$72:$C$111,3,FALSE)+VLOOKUP(AN22,Ressourcen!$A$72:$C$111,3,FALSE)+VLOOKUP(AO22,Ressourcen!$A$72:$C$111,3,FALSE) -> 128
A23: LE Unterleib | E23: =(ROUNDUP((Kon+vit)/2,0)+8) -> 34 | H23: Leichtes Marschgepäck | N23: =ROUNDUP((Stä+tragen)*3,0) -> 75 | P23: Schwimmen | T23: =ROUNDUP((Ath+Kon+schwi)/30,2) -> 2.24 | V23: Alchemieresistenz | Y23: 12 | Z23: Springen | AD23: 5 | AE23: Tierkunde | AI23: 12 | AK23: 12 | AL23: 10 | AM23: 0 | AN23: 0 | AO23: 0 | AP23: =VLOOKUP(AI23,Ressourcen!$A$3:$E$68,4,FALSE)+VLOOKUP(AK23,Ressourcen!$A$72:$C$111,3,FALSE)+VLOOKUP(AL23,Ressourcen!$A$72:$C$111,3,FALSE)+VLOOKUP(AM23,Ressourcen!$A$72:$C$111,3,FALSE)+VLOOKUP(AN23,Ressourcen!$A$72:$C$111,3,FALSE)+VLOOKUP(AO23,Ressourcen!$A$72:$C$111,3,FALSE) -> 128
A24: LE r. Arm | E24: =ROUNDUP((((ROUNDUP((Kon/2),0)+Stä)/2)),0)+5 -> 27 | H24: Schweres Marschgepäck | N24: =ROUNDUP((Stä+tragen)*5,0) -> 125 | V24: Fliehen | Y24: 0 | Z24: Sprinten | AD24: 7 | AE24: Pflanzenkunde | AI24: 12 | AK24: 12 | AL24: 10 | AM24: 0 | AN24: 0 | AO24: 0 | AP24: =VLOOKUP(AI24,Ressourcen!$A$3:$E$68,4,FALSE)+VLOOKUP(AK24,Ressourcen!$A$72:$C$111,3,FALSE)+VLOOKUP(AL24,Ressourcen!$A$72:$C$111,3,FALSE)+VLOOKUP(AM24,Ressourcen!$A$72:$C$111,3,FALSE)+VLOOKUP(AN24,Ressourcen!$A$72:$C$111,3,FALSE)+VLOOKUP(AO24,Ressourcen!$A$72:$C$111,3,FALSE) -> 128
A25: LE l. Arm | E25: =ROUNDUP((((ROUNDUP((Kon/2),0)+Stä)/2)),0)+5 -> 27 | H25: Mittel Überladen | N25: =ROUNDUP((Stä+tragen)*7,0) -> 175 | P25: Freiklettern | T25: =ROUNDUP(((Ges+Sch+Stä+8*Klett)/300),2) -> 0.39 | V25: Rüstungsmanöver | Y25: 12 | Z25: Dauerlauf | AD25: 6 | AE25: WHK6 | AI25: 0 | AK25: 0 | AL25: 0 | AM25: 0 | AN25: 0 | AO25: 0 | AP25: =VLOOKUP(AI25,Ressourcen!$A$3:$E$68,4,FALSE)+VLOOKUP(AK25,Ressourcen!$A$72:$C$111,3,FALSE)+VLOOKUP(AL25,Ressourcen!$A$72:$C$111,3,FALSE)+VLOOKUP(AM25,Ressourcen!$A$72:$C$111,3,FALSE)+VLOOKUP(AN25,Ressourcen!$A$72:$C$111,3,FALSE)+VLOOKUP(AO25,Ressourcen!$A$72:$C$111,3,FALSE) -> 0
A26: LE r. Bein | E26: =Kon+8 -> 46 | H26: Schwer schleppend | N26: =ROUNDUP((Stä+tragen)*11,0) -> 275 | P26: Geschirrklettern | T26: =ROUNDUP(((Int+Ges+Stä+63*Klett)/9067),2) -> 0.05 | V26: Selbstbeherrschung | Y26: 12 | Z26: Luft anhalten | AD26: 4 | AE26: WHK7 | AI26: 0 | AK26: 0 | AL26: 0 | AM26: 0 | AN26: 0 | AO26: 0 | AP26: =VLOOKUP(AI26,Ressourcen!$A$3:$E$68,4,FALSE)+VLOOKUP(AK26,Ressourcen!$A$72:$C$111,3,FALSE)+VLOOKUP(AL26,Ressourcen!$A$72:$C$111,3,FALSE)+VLOOKUP(AM26,Ressourcen!$A$72:$C$111,3,FALSE)+VLOOKUP(AN26,Ressourcen!$A$72:$C$111,3,FALSE)+VLOOKUP(AO26,Ressourcen!$A$72:$C$111,3,FALSE) -> 0
A27: LE l. Bein | E27: =Kon+8 -> 46 | H27: max. Hebelast | N27: =ROUNDUP((Stä+tragen)*15,0) -> 375 | P27: Allgemeines | T27: sec | V27: Tragen | Y27: 0 | Z27: Reiten | AD27: 6 | AE27: WHK8 | AI27: 0 | AK27: 0 | AL27: 0 | AM27: 0 | AN27: 0 | AO27: 0 | AP27: =VLOOKUP(AI27,Ressourcen!$A$3:$E$68,4,FALSE)+VLOOKUP(AK27,Ressourcen!$A$72:$C$111,3,FALSE)+VLOOKUP(AL27,Ressourcen!$A$72:$C$111,3,FALSE)+VLOOKUP(AM27,Ressourcen!$A$72:$C$111,3,FALSE)+VLOOKUP(AN27,Ressourcen!$A$72:$C$111,3,FALSE)+VLOOKUP(AO27,Ressourcen!$A$72:$C$111,3,FALSE) -> 0
H28: Springen | N28: m | P28: Luft anhalten | T28: =(Wil+Kon+lufta*12)*3 -> 345 | V28: Ausdauer | Y28: 0 | Z28: Rudern | AD28: 0 | AE28: WHK9 | AI28: 0 | AK28: 0 | AL28: 0 | AM28: 0 | AN28: 0 | AO28: 0 | AP28: =VLOOKUP(AI28,Ressourcen!$A$3:$E$68,4,FALSE)+VLOOKUP(AK28,Ressourcen!$A$72:$C$111,3,FALSE)+VLOOKUP(AL28,Ressourcen!$A$72:$C$111,3,FALSE)+VLOOKUP(AM28,Ressourcen!$A$72:$C$111,3,FALSE)+VLOOKUP(AN28,Ressourcen!$A$72:$C$111,3,FALSE)+VLOOKUP(AO28,Ressourcen!$A$72:$C$111,3,FALSE) -> 0
A29: Trefferschwelle | E29: =vit+5+IF(Talente!E77="Ja",2,IF(Talente!E76="Ja",1,0)) -> 21 | H29: Hoch | N29: =ROUNDUP((Stä+Sch+sprin)/40,2) -> 1.28 | V29: Konzentration | Y29: 12 | Z29: Schleichen | AD29: 6 | AE29: WHK10 | AI29: 0 | AK29: 0 | AL29: 0 | AM29: 0 | AN29: 0 | AO29: 0 | AP29: =VLOOKUP(AI29,Ressourcen!$A$3:$E$68,4,FALSE)+VLOOKUP(AK29,Ressourcen!$A$72:$C$111,3,FALSE)+VLOOKUP(AL29,Ressourcen!$A$72:$C$111,3,FALSE)+VLOOKUP(AM29,Ressourcen!$A$72:$C$111,3,FALSE)+VLOOKUP(AN29,Ressourcen!$A$72:$C$111,3,FALSE)+VLOOKUP(AO29,Ressourcen!$A$72:$C$111,3,FALSE) -> 0
H30: Weit, aus dem Stand | N30: =ROUNDUP((Stä+Ath+sprin)/13,2)+1 -> 5.08 | V30: Meditation | Y30: 0 | Z30: Schwimmen | AD30: 6 | AE30: WHK11 | AI30: 0 | AK30: 0 | AL30: 0 | AM30: 0 | AN30: 0 | AO30: 0 | AP30: =VLOOKUP(AI30,Ressourcen!$A$3:$E$68,4,FALSE)+VLOOKUP(AK30,Ressourcen!$A$72:$C$111,3,FALSE)+VLOOKUP(AL30,Ressourcen!$A$72:$C$111,3,FALSE)+VLOOKUP(AM30,Ressourcen!$A$72:$C$111,3,FALSE)+VLOOKUP(AN30,Ressourcen!$A$72:$C$111,3,FALSE)+VLOOKUP(AO30,Ressourcen!$A$72:$C$111,3,FALSE) -> 0
A31: Summe LE | D31: =SUM(E21:E27,3*gesundheit) -> 387 | H31: Weit, mit kurzem Anlauf | N31: =ROUNDUP((Stä+Sch+sprin)/8,2)+1 -> 7.38 | V31: Mana-Talent | Y31: 0 | Z31: Verstecken | AD31: 10 | AE31: WHK12 | AI31: 0 | AK31: 0 | AL31: 0 | AM31: 0 | AN31: 0 | AO31: 0 | AP31: =VLOOKUP(AI31,Ressourcen!$A$3:$E$68,4,FALSE)+VLOOKUP(AK31,Ressourcen!$A$72:$C$111,3,FALSE)+VLOOKUP(AL31,Ressourcen!$A$72:$C$111,3,FALSE)+VLOOKUP(AM31,Ressourcen!$A$72:$C$111,3,FALSE)+VLOOKUP(AN31,Ressourcen!$A$72:$C$111,3,FALSE)+VLOOKUP(AO31,Ressourcen!$A$72:$C$111,3,FALSE) -> 0
H32: Weit, mit optimalem Anlauf | N32: =ROUNDUP((Stä+Sch+sprin)/6,2)+1 -> 9.5 | V32: Mentale Kapazität | Y32: 0 | Z32: Betören | AD32: 0 | AE32: WHK13 | AI32: 0 | AK32: 0 | AL32: 0 | AM32: 0 | AN32: 0 | AO32: 0 | AP32: =VLOOKUP(AI32,Ressourcen!$A$3:$E$68,4,FALSE)+VLOOKUP(AK32,Ressourcen!$A$72:$C$111,3,FALSE)+VLOOKUP(AL32,Ressourcen!$A$72:$C$111,3,FALSE)+VLOOKUP(AM32,Ressourcen!$A$72:$C$111,3,FALSE)+VLOOKUP(AN32,Ressourcen!$A$72:$C$111,3,FALSE)+VLOOKUP(AO32,Ressourcen!$A$72:$C$111,3,FALSE) -> 0
H33: Werfen | N33: m | V33: Gefahreninstinkt | Y33: 10 | Z33: Einschüchtern | AD33: 10 | AE33: WHK14 | AI33: 0 | AK33: 0 | AL33: 0 | AM33: 0 | AN33: 0 | AO33: 0 | AP33: =VLOOKUP(AI33,Ressourcen!$A$3:$E$68,4,FALSE)+VLOOKUP(AK33,Ressourcen!$A$72:$C$111,3,FALSE)+VLOOKUP(AL33,Ressourcen!$A$72:$C$111,3,FALSE)+VLOOKUP(AM33,Ressourcen!$A$72:$C$111,3,FALSE)+VLOOKUP(AN33,Ressourcen!$A$72:$C$111,3,FALSE)+VLOOKUP(AO33,Ressourcen!$A$72:$C$111,3,FALSE) -> 0
H34: Gegenstand 0,1-0,5kg | N34: =(werfen+Ath+Stä)*2 -> 96 | V34: LS Armbrust | Y34: 0 | Z34: Fährtensuche | AD34: 10 | AE34: WHK15 | AI34: 0 | AK34: 0 | AL34: 0 | AM34: 0 | AN34: 0 | AO34: 0 | AP34: =VLOOKUP(AI34,Ressourcen!$A$3:$E$68,4,FALSE)+VLOOKUP(AK34,Ressourcen!$A$72:$C$111,3,FALSE)+VLOOKUP(AL34,Ressourcen!$A$72:$C$111,3,FALSE)+VLOOKUP(AM34,Ressourcen!$A$72:$C$111,3,FALSE)+VLOOKUP(AN34,Ressourcen!$A$72:$C$111,3,FALSE)+VLOOKUP(AO34,Ressourcen!$A$72:$C$111,3,FALSE) -> 0
A35: Startguthaben: 4000 D | H35: Gegenstand 0,5-1kg | N35: =(werfen+Ath+Stä)*1.5 -> 72 | V35: LS Bogen | Y35: 0 | Z35: Lügen | AD35: 0 | AE35: WHK16 | AI35: 0 | AK35: 0 | AL35: 0 | AM35: 0 | AN35: 0 | AO35: 0 | AP35: =VLOOKUP(AI35,Ressourcen!$A$3:$E$68,4,FALSE)+VLOOKUP(AK35,Ressourcen!$A$72:$C$111,3,FALSE)+VLOOKUP(AL35,Ressourcen!$A$72:$C$111,3,FALSE)+VLOOKUP(AM35,Ressourcen!$A$72:$C$111,3,FALSE)+VLOOKUP(AN35,Ressourcen!$A$72:$C$111,3,FALSE)+VLOOKUP(AO35,Ressourcen!$A$72:$C$111,3,FALSE) -> 0
H36: Gegenstand 1-2kg | N36: =(werfen+Ath+Stä) -> 48 | V36: LS Blasrohr | Y36: 0 | Z36: Orientierung | AD36: 12 | AE36: WHK17 | AI36: 0 | AK36: 0 | AL36: 0 | AM36: 0 | AN36: 0 | AO36: 0 | AP36: =VLOOKUP(AI36,Ressourcen!$A$3:$E$68,4,FALSE)+VLOOKUP(AK36,Ressourcen!$A$72:$C$111,3,FALSE)+VLOOKUP(AL36,Ressourcen!$A$72:$C$111,3,FALSE)+VLOOKUP(AM36,Ressourcen!$A$72:$C$111,3,FALSE)+VLOOKUP(AN36,Ressourcen!$A$72:$C$111,3,FALSE)+VLOOKUP(AO36,Ressourcen!$A$72:$C$111,3,FALSE) -> 0
H37: Wurfspeer | N37: =(werfen+Ath+Sch)*1.5 -> 66 | V37: LS Vorderlader | Y37: 0 | Z37: Menschenkenntnis | AD37: 12 | AE37: WHK18 | AI37: 0 | AK37: 0 | AL37: 0 | AM37: 0 | AN37: 0 | AO37: 0 | AP37: =VLOOKUP(AI37,Ressourcen!$A$3:$E$68,4,FALSE)+VLOOKUP(AK37,Ressourcen!$A$72:$C$111,3,FALSE)+VLOOKUP(AL37,Ressourcen!$A$72:$C$111,3,FALSE)+VLOOKUP(AM37,Ressourcen!$A$72:$C$111,3,FALSE)+VLOOKUP(AN37,Ressourcen!$A$72:$C$111,3,FALSE)+VLOOKUP(AO37,Ressourcen!$A$72:$C$111,3,FALSE) -> 0
V38: LS Patrone | Y38: 0 | AE38: WHK19 | AI38: 0 | AK38: 0 | AL38: 0 | AM38: 0 | AN38: 0 | AO38: 0 | AP38: =VLOOKUP(AI38,Ressourcen!$A$3:$E$68,4,FALSE)+VLOOKUP(AK38,Ressourcen!$A$72:$C$111,3,FALSE)+VLOOKUP(AL38,Ressourcen!$A$72:$C$111,3,FALSE)+VLOOKUP(AM38,Ressourcen!$A$72:$C$111,3,FALSE)+VLOOKUP(AN38,Ressourcen!$A$72:$C$111,3,FALSE)+VLOOKUP(AO38,Ressourcen!$A$72:$C$111,3,FALSE) -> 0
V39: LS Rune | Y39: 0 | AE39: WHK20 | AI39: 0 | AK39: 0 | AL39: 0 | AM39: 0 | AN39: 0 | AO39: 0 | AP39: =VLOOKUP(AI39,Ressourcen!$A$3:$E$68,4,FALSE)+VLOOKUP(AK39,Ressourcen!$A$72:$C$111,3,FALSE)+VLOOKUP(AL39,Ressourcen!$A$72:$C$111,3,FALSE)+VLOOKUP(AM39,Ressourcen!$A$72:$C$111,3,FALSE)+VLOOKUP(AN39,Ressourcen!$A$72:$C$111,3,FALSE)+VLOOKUP(AO39,Ressourcen!$A$72:$C$111,3,FALSE) -> 0
V40: LS Kanone | Y40: 0 | Z40: Sprachfertigkeiten | AD40: TaW | AE40: WHK21 | AI40: 0 | AK40: 0 | AL40: 0 | AM40: 0 | AN40: 0 | AO40: 0 | AP40: =VLOOKUP(AI40,Ressourcen!$A$3:$E$68,4,FALSE)+VLOOKUP(AK40,Ressourcen!$A$72:$C$111,3,FALSE)+VLOOKUP(AL40,Ressourcen!$A$72:$C$111,3,FALSE)+VLOOKUP(AM40,Ressourcen!$A$72:$C$111,3,FALSE)+VLOOKUP(AN40,Ressourcen!$A$72:$C$111,3,FALSE)+VLOOKUP(AO40,Ressourcen!$A$72:$C$111,3,FALSE) -> 0
V41: LS Schleuder | Y41: 0 | Z41: Zwergisch | AD41: 0 | AE41: WHK22 | AI41: 0 | AK41: 0 | AL41: 0 | AM41: 0 | AN41: 0 | AO41: 0 | AP41: =VLOOKUP(AI41,Ressourcen!$A$3:$E$68,4,FALSE)+VLOOKUP(AK41,Ressourcen!$A$72:$C$111,3,FALSE)+VLOOKUP(AL41,Ressourcen!$A$72:$C$111,3,FALSE)+VLOOKUP(AM41,Ressourcen!$A$72:$C$111,3,FALSE)+VLOOKUP(AN41,Ressourcen!$A$72:$C$111,3,FALSE)+VLOOKUP(AO41,Ressourcen!$A$72:$C$111,3,FALSE) -> 0
...

Sheet Talente
A1: Kategorie | B1: Name | C1: Talentpunktkosten | E1: Gewählt? | F1: Beschreibung
A2: Abenteurer | B2: Alchemieresistenz Stufe 1 | C2: 2 | D2: =IF(E2="Ja",C2,0) -> 0 | E2: Nein | F2: Erhöht das Maximum der Sonderfertigkeit "Alchemiresistenz" um 6 Punkte.
A3: Abenteurer | B3: Alchemieresistenz Stufe 2 | C3: 2 | D3: =IF(E3="Ja",C3,0) -> 0 | E3: Nein | F3: Erhöht das Maximum der Sonderfertigkeit "Alchemiresistenz" um 12 Punkte.
A4: Abenteurer | B4: Attributs-Maximum erhöhen +1 AURA | C4: 18 | D4: =IF(E4="Ja",C4,0) -> 0 | E4: Nein | F4: Das Attributs-Maximum wird um 1 erhöht.
A5: Abenteurer | B5: Attributs-Maximum erhöhen +1 GLÜCK | C5: 18 | D5: =IF(E5="Ja",C5,0) -> 0 | E5: Nein | F5: Das Attributs-Maximum wird um 1 erhöht.
A6: Abenteurer | B6: Attributs-Maximum erhöhen +1 KARMA | C6: 18 | D6: =IF(E6="Ja",C6,0) -> 0 | E6: Nein | F6: Das Attributs-Maximum wird um 1 erhöht.
A7: Abenteurer | B7: Attributs-Maximum erhöhen +1 MAGIE | C7: 18 | D7: =IF(E7="Ja",C7,0) -> 0 | E7: Nein | F7: Das Attributs-Maximum wird um 1 erhöht.
A8: Abenteurer | B8: Attributs-Maximum erhöhen +1 VITALITÄT | C8: 18 | D8: =IF(E8="Ja",C8,0) -> 0 | E8: Nein | F8: Das Attributs-Maximum wird um 1 erhöht.
A9: Abenteurer | B9: Ausdauer Stufe 1 | C9: 1 | D9: =IF(E9="Ja",C9,0) -> 0 | E9: Nein | F9: Erhöht das Maximum der Sonderfertigkeit "Ausdauer" um 6 Punkte.
A10: Abenteurer | B10: Ausdauer Stufe 2 | C10: 1 | D10: =IF(E10="Ja",C10,0) -> 0 | E10: Nein | F10: Erhöht das Maximum der Sonderfertigkeit "Ausdauer" um 12 Punkte.
A11: Abenteurer | B11: Ausdauer Stufe 3 | C11: 1 | D11: =IF(E11="Ja",C11,0) -> 0 | E11: Nein | F11: Erhöht das Maximum der Sonderfertigkeit "Ausdauer" um 18 Punkte.
A12: Abenteurer | B12: Ausweichen Stufe 1 | C12: 2 | D12: =IF(E12="Ja",C12,0) -> 0 | E12: Nein | F12: Erhöht das Maximum der Sonderfertigkeit "Ausweichen" um 6 Punkte.
A13: Abenteurer | B13: Ausweichen Stufe 2 | C13: 10 | D13: =IF(E13="Ja",C13,0) -> 0 | E13: Nein | F13: Erhöht das Maximum der Sonderfertigkeit "Ausweichen" um 12 Punkte.
... A145: Schütze | B145: Vorderlader Ladeschütze Stufe2 | C145: 6 | D145: =IF(E145="Ja",C145,0) -> 0 | E145: Nein | F145: Fertigkeitsmaximum der Sonderfertigkeit "Ladeschütze Vorderlader" +15
D146: =SUM(D2:D145) -> 467
D147: =SUM(D78:D102) -> 281
D148: Ja
D149: Nein

Sheet Elementar-Rechner
D1: Dauer (sec) | F1: St. 1 | G1: St. 2 | H1: St. 3 | I1: Mana | J1: Min. Int | L1: =MIN(10)+ROUNDUP(L3*2,0) -> 20
A2: Barriere | D2: =L4 -> 34 | E2: sec | F2: =G69+G70+G74-ROUNDUP(+L4/6,0) -> 24 | G2: =G69+G70+G74-ROUNDUP(L4/3,0) -> 18 | H2: =G69+G70+G74-L4 -> -4 | I2: =SUM(L3+1) -> 6 | J2: Beschwörungsfertigkeit | L2: 24
A3: Beschwörung | D3: =SUM(L3*60) -> 300 | E3: sec | F3: =L2+G69+G70+ROUNDUP(-L4/4,0) -> 21 | G3: =ROUNDUP(-L4/2,0)+L2+G69+G70 -> 13 | H3: =-L4+L2+G69+G70 -> -4 | I3: =SUM(L4*3) -> 102 | J3: Kreis | L3: =VLOOKUP($C$67,Ressourcen!$H$17:$J$79,3) -> 5
A4: Beherrschung | D4: =SUM(L3*2) -> 10 | E4: sec | F4: =ROUNDUP(-L3*2,0)+G75+G69+G70 -> 20 | G4: =ROUNDUP(-L3*4,0)+G75+G69+G70 -> 10 | H4: =SUM(-L3*8)+G75+G69+G70 -> -10 | I4: =SUM(L3*5) -> 25 | J4: Stufe | L4: =VLOOKUP($C$67,Ressourcen!$H$17:$J$79,2) -> 34
A5: Bannung | D5: =L3 -> 5 | E5: sec | F5: =ROUNDUP(-L4/8,0)+G76+G69+G70 -> 25 | G5: =ROUNDUP(-L4/4,0)+G76+G69+G70 -> 21 | H5: =ROUNDUP(-L4/2,0)+G76+G69+G70 -> 13 | I5: =ROUNDUP(L3*3,0) -> 15 | J5: Macht | L5: =L3+M40+M41+M42+E42 -> 21
A6: Zirkel | D6: =L3 -> 5 | E6: h | F6: 12 | H6: =ROUNDUP(PI()*(L3*2)^2,0) -> 315 | I6: m² | J6: Element | L6: Wasser
A9: Ausstrahlung | D9: =D38+IF(L6="Magie",L3,0) -> 6 | E9: =ROUNDUP(D9/2,0)-5 -> -2 | F9: Athletik | I9: =I38+IF(L6="Wasser",L3,0) -> 22 | J9: =ROUNDUP(I9/2,0)-5 -> 6 | K9: Glück | M9: =M38 -> 3
A10: Intelligenz | D10: =D39 -> 9 | E10: =ROUNDUP(D10/2,0)-5 -> 0 | F10: Geschicklichkeit | I10: =I39 -> 13 | J10: =ROUNDUP(I10/2,0)-5 -> 2 | K10: Vitalität | M10: =M39 -> 7
A11: Mut | D11: =D40+IF(L6="Feuer",L3,0) -> 19 | E11: =ROUNDUP(D11/2,0)-5 -> 5 | F11: Konstitution | I11: =I40+IF(L6="Gift",L3,0) -> 21 | J11: =ROUNDUP(I11/2,0)-5 -> 6 | K11: Aura | M11: =M40 -> 5
A12: Sinnesschärfe | D12: =D41 -> 17 | E12: =ROUNDUP(D12/2,0)-5 -> 4 | F12: Schnelligkeit | I12: =I41+IF(L6="Luft",L3,0) -> 13 | J12: =ROUNDUP(I12/2,0)-5 -> 2 | K12: Magie | M12: =M41 -> 5
A13: Willenskraft | D13: =D42 -> 15 | E13: =ROUNDUP(D13/2,0)-5 -> 3 | F13: Stärke | I13: =I42+IF(L6="Luft",L3,0) -> 19 | J13: =ROUNDUP(I13/2,0)-5 -> 5 | K13: Weisheit | M13: =M42 -> 3
A21: Ini | B21: =J49 -> 22
A22: AW | B22: =$C$49 -> 10 | E22: Schaden | G22: WK | H22: nAT | I22: gAT | J22: mAT | K22: nPA | L22: gPA | M22: mPA
A23: gAW | B23: =F49 -> 1 | E23: =VLOOKUP($L$6,$A$59:$D$64,2) -> W10 + | F23: =ROUNDUP($I$42/2,0)-4+$M$40+$D$53 -> 16 | G23: =$L$3+4 -> 9 | H23: =ROUNDUP(($D$40+$I$41+$C$45)/3,0)+$H$46 -> 20 | I23: =1+$I$46 -> 7 | J23: =21+$J$46 -> 23 | K23: =ROUNDUP(($I$38+$I$41+$C$45)/3,0)+$K$46 -> 20 | L23: =1+$L$46 -> 5 | M23: =21+$M$46 -> 24
A24: mAW | B24: =I49 -> 21
A27: RS NK | B27: =J10 -> 2 | C27: RS FK | D27: =I10 -> 13
A28: LE | B28: =(M39*12+I40*3+ROUNDUP(L4/2,0)+L5) -> 185
A29: Mana | B29: =M40*7+M41*3+E42*6+E39*M42+L4 -> 102
D37: Eigenschaften
A38: Ausstrahlung | D38: 6 | E38: =ROUNDUP(D38/2,0)-5 -> -2 | F38: Athletik | I38: 17 | J38: =ROUNDUP(I38/2,0)-5 -> 4 | K38: Glück | M38: 3
A39: Intelligenz | D39: 9 | E39: =ROUNDUP(D39/2,0)-5 -> 0 | F39: Geschicklichkeit | I39: 13 | J39: =ROUNDUP(I39/2,0)-5 -> 2 | K39: Vitalität | M39: 7
A40: Mut | D40: 19 | E40: =ROUNDUP(D40/2,0)-5 -> 5 | F40: Konstitution | I40: 21 | J40: =ROUNDUP(I40/2,0)-5 -> 6 | K40: Aura | M40: 5
A41: Sinnesschärfe | D41: 17 | E41: =ROUNDUP(D41/2,0)-5 -> 4 | F41: Schnelligkeit | I41: 13 | J41: =ROUNDUP(I41/2,0)-5 -> 2 | K41: Magie | M41: 5
A42: Willenskraft | D42: 15 | E42: =ROUNDUP(D42/2,0)-5 -> 3 | F42: Stärke | I42: 19 | J42: =ROUNDUP(I42/2,0)-5 -> 5 | K42: Weisheit | M42: 3
A44: Nahkampf | C44: TaW | D44: Spez | E44: Schaden | G44: WK | H44: nAT | I44: gAT | J44: mAT | K44: nPA | L44: gPA | M44: mPA
A45: Unbewaffnet | C45: 20 | D45: 20 | E45: =VLOOKUP($L$6,$A$59:$D$64,2) -> W10 + | F45: =ROUNDUP($I$42/2,0)-4+$M$40+$D$53 -> 16 | G45: =$L$3+4 -> 9 | H45: =ROUNDUP(($D$40+$I$41+$C$45)/3,0)+$H$46 -> 20 | I45: =1+$I$46 -> 7 | J45: =21+$J$46 -> 23 | K45: =ROUNDUP(($I$38+$I$41+$C$45)/3,0)+$K$46 -> 20 | L45: =1+$L$46 -> 5 | M45: =21+$M$46 -> 24
C46: SpezAT/PA | E46: frei | F46: =D45-SUM(H46:M46) -> 0 | H46: 2 | I46: 6 | J46: 2 | K46: 3 | L46: 4 | M46: 3
B48: TaW | C48: Probe | E48: TaW | F48: Probe | H48: TaW | I48: Probe | J48: Ini | K48: RS NK | M48: RS FK
A49: AW | B49: 0 | C49: =ROUNDUP(($I$38+$I$41+$M$38+$B$49)/5,0)+3 -> 10 | D49: gAW | E49: 0 | F49: =ROUNDUP(($J$38+$E$49)/5,0) -> 1 | G49: mAW | H49: 0 | I49: =ROUNDUP(($H$49+$J$41)/5,0)+20 -> 21 | J49: =ROUNDUP(($D$40+$I$41)/2,0)+ROUNDUP(($D$39+$I$39+$I$38)/6,0)-1 -> 22 | K49: =$J$39 -> 2 | M49: =$I$39 -> 13
A51: Zauber
A52: Name | C52: SP | E52: Spec | F52: Ziel | G52: RW | H52: Vorb | I52: Eff | J52: Wirk | K52: St.1 | L52: St.2 | M52: St.3 | N52: TaW
A53: Elementarfaust | C53: W10 + | D53: =M41 -> 5 | E53: RB 4 | N53: 20
A58: Nahkampf-Schäden
A59: Erde | B59: W10 + | C59: Aura + Magie | D59: RB 3
A60: Feuer | B60: W15 + | C60: Aura + Magie | D60: -
A61: Gift | B61: W10 + | C61: Aura + Magie | D61: permSP
A62: Luft | B62: W8 + | C62: Aura + Magie | D62: TPm zurück
A63: Magie | B63: W10 + | C63: Aura + Magie | D63: SB 5
A64: Wasser | B64: W10 + | C64: Aura + Magie | D64: pro 5TP/1BE
A66: EP des Elementars | B66: EP frei | C66: verbrauchte EP | F66: Beschwörer-Sektion
...

Sheet Ressourcen
A1: Eigenschaften | D1: KI | H1: Attribute
A2: Wert | B2: EP | H2: Wert | I2: Gesamt-EP | J2: EP | N2: MagierTap | O2: Hauszauber
A3: 0 | B3: 0 | C3: 0 | D3: 0 | E3: 0 | H3: 0 | I3: 0 | J3: 0 | N3: 12 | O3: 1
A4: 1 | B4: =30*A4 -> 30 | C4: 30 | D4: 10 | E4: 10 | H4: 1 | I4: =SUM(J4:J4) -> 80 | J4: 80 | N4: 36 | O4: 2
A5: 2 | B5: =30*A5 -> 60 | C5: 30 | D5: =D4+A5-1 -> 11 | E5: =A5-1 -> 1 | H5: 2 | I5: =SUM(J4:J5) -> 180 | J5: =SUM(80+H4*20) -> 100 | N5: 72 | O5: 3
A6: 3 | B6: =30*A6 -> 90 | C6: 30 | D6: =D5+A6-1 -> 13 | E6: =A6-1 -> 2 | H6: 3 | I6: =SUM(J4:J6) -> 300 | J6: =SUM(80+H5*20) -> 120 | N6: 130 | O6: 4
A7: 4 | B7: =30*A7 -> 120 | C7: 30 | D7: =D6+A7-1 -> 16 | E7: =A7-1 -> 3 | H7: 4 | I7: =SUM(J4:J7) -> 440 | J7: =SUM(80+H6*20) -> 140 | N7: 210 | O7: 5
A8: 5 | B8: =30*A8 -> 150 | C8: 30 | D8: =D7+A8-1 -> 20 | E8: =A8-1 -> 4 | H8: 5 | I8: =SUM(J4:J8) -> 600 | J8: =SUM(80+H7*20) -> 160 | N8: 280 | O8: 6
A9: 6 | B9: =30*A9 -> 180 | C9: 30 | D9: =D8+A9-1 -> 25 | E9: =A9-1 -> 5 | H9: 6 | I9: =SUM(J4:J9) -> 780 | J9: =SUM(80+H8*20) -> 180 | N9: 359 | O9: 7
A10: 7 | B10: =30*A10 -> 210 | C10: 30 | D10: =D9+A10-1 -> 31 | E10: =A10-1 -> 6 | H10: 7 | I10: =SUM(J4:J10) -> 980 | J10: =SUM(80+H9*20) -> 200
A11: 8 | B11: =30*A11 -> 240 | C11: 30 | D11: =D10+A11-1 -> 38 | E11: =A11-1 -> 7 | H11: 8 | I11: =SUM(J4:J11) -> 1200 | J11: =SUM(80+H10*20) -> 220
A12: 9 | B12: =30*A12 -> 270 | C12: 30 | D12: =D11+A12-1 -> 46 | E12: =A12-1 -> 8 | H12: 9 | I12: =SUM(J4:J12) -> 1440 | J12: =SUM(80+H11*20) -> 240
A13: 10 | B13: =30*A13 -> 300 | C13: 30 | D13: =D12+A13-1 -> 55 | E13: =A13-1 -> 9 | H13: 10 | I13: =SUM(J4:J13) -> 1700 | J13: =SUM(80+H12*20) -> 260
A14: 11 | B14: =30*A14 -> 330 | C14: 30 | D14: =D13+A14-1 -> 65 | E14: =A14-1 -> 10
A15: 12 | B15: =B14+3*A14 -> 363 | C15: =3*A14 -> 33 | D15: =D14+A15-1 -> 76 | E15: =A15-1 -> 11
A16: 13 | B16: =B15+3*A15 -> 399 | C16: =3*A15 -> 36 | D16: =D15+A16-1 -> 88 | E16: =A16-1 -> 12 | H16: EP | I16: Stufe | J16: Kreis | K16: Talentpunkte
A17: 14 | B17: =B16+3*A16 -> 438 | C17: =3*A16 -> 39 | D17: =D16+A17-1 -> 101 | E17: =A17-1 -> 13 | H17: 20 | I17: 1 | J17: 1 | K17: 25
A18: 15 | B18: =B17+3*A17 -> 480 | C18: =3*A17 -> 42 | D18: =D17+A18-1 -> 115 | E18: =A18-1 -> 14 | H18: 60 | I18: 2 | J18: 1 | K18: =K17+5 -> 30
A19: 16 | B19: =B18+3*A18 -> 525 | C19: =3*A18 -> 45 | D19: =D18+A19-1 -> 130 | E19: =A19-1 -> 15 | H19: 120 | I19: 3 | J19: 1 | K19: =K18+5 -> 35
A20: 17 | B20: =B19+3*A19 -> 573 | C20: =3*A19 -> 48 | D20: =D19+A20-1 -> 146 | E20: =A20-1 -> 16 | H20: 200 | I20: 4 | J20: 2 | K20: =K19+5 -> 40
A21: 18 | B21: =B20+3*A20 -> 624 | C21: =3*A20 -> 51 | D21: =D20+A21-1 -> 163 | E21: =A21-1 -> 17 | H21: 300 | I21: 5 | J21: 2 | K21: =K20+5 -> 45
A22: 19 | B22: =B21+3*A21 -> 678 | C22: =3*A21 -> 54 | D22: =D21+A22-1 -> 181 | E22: =A22-1 -> 18 | H22: 400 | I22: 6 | J22: 2 | K22: =K21+5 -> 50
A23: 20 | B23: =B22+3*A22 -> 735 | C23: =3*A22 -> 57 | D23: =D22+A23-1 -> 200 | E23: =A23-1 -> 19 | H23: 500 | I23: 7 | J23: 2 | K23: =K22+5 -> 55
A24: 21 | B24: =B23+3*A23 -> 795 | C24: =3*A23 -> 60 | D24: =D23+A24-1 -> 220 | E24: =A24-1 -> 20 | H24: 600 | I24: 8 | J24: 2 | K24: =K23+5 -> 60 | L24: SB-Verriss
A25: 22 | B25: =B24+3*A24 -> 858 | C25: =3*A24 -> 63 | D25: =D24+A25-1 -> 241 | E25: =A25-1 -> 21 | H25: 700 | I25: 9 | J25: 3 | K25: =K24+5 -> 65 | L25: <0 | M25: geschafft
A26: 23 | B26: =B25+3*A25 -> 924 | C26: =3*A25 -> 66 | D26: =D25+A26-1 -> 263 | E26: =A26-1 -> 22 | H26: 850 | I26: 10 | J26: 3 | K26: =K25+5 -> 70 | L26: 1 | M26: BE+1, 1 sec AT-Kl.-1 | N26: BE+1
A27: 24 | B27: =B26+3*A26 -> 993 | C27: =3*A26 -> 69 | D27: =D26+A27-1 -> 286 | E27: =A27-1 -> 23 | H27: 1000 | I27: 11 | J27: 3 | K27: =K26+5 -> 75 | L27: 2 | M27: BE+1, 2 sec AT-Kl.-1 | N27: BE+1
A28: 25 | B28: =B27+3*A27 -> 1065 | C28: =3*A27 -> 72 | D28: =D27+A28-1 -> 310 | E28: =A28-1 -> 24 | H28: 1150 | I28: 12 | J28: 3 | K28: =K27+5 -> 80 | L28: 3 | M28: BE+1, 3 sec AT-Kl.-1 | N28: BE+1
A29: 26 | B29: =B28+3*A28 -> 1140 | C29: =3*A28 -> 75 | D29: =D28+A29-1 -> 335 | E29: =A29-1 -> 25 | H29: 1300 | I29: 13 | J29: 3 | K29: =K28+5 -> 85 | L29: 4 | M29: BE+1, 4 sec AT-Kl.-1 | N29: BE+1
A30: 27 | B30: =B29+3*A29 -> 1218 | C30: =3*A29 -> 78 | D30: =D29+A30-1 -> 361 | E30: =A30-1 -> 26 | H30: 1450 | I30: 14 | J30: 3 | K30: =K29+5 -> 90 | L30: 5 | M30: BE+1, 5 sec AT-Kl.-1 | N30: BE+1
A31: 28 | B31: =B30+3*A30 -> 1299 | C31: =3*A30 -> 81 | D31: =D30+A31-1 -> 388 | E31: =A31-1 -> 27 | H31: 1600 | I31: 15 | J31: 3 | K31: =K30+5 -> 95 | L31: 6 | M31: BE+2, Straucheln: 1 sec PA-Kl.-1 | N31: BE+2
A32: 29 | B32: =B31+3*A31 -> 1383 | C32: =3*A31 -> 84 | D32: =D31+A32-1 -> 416 | E32: =A32-1 -> 28 | H32: 1750 | I32: 16 | J32: 4 | K32: =K31+5 -> 100 | L32: 7 | M32: BE+2, Straucheln: 1 sec PA-Kl.-1 | N32: BE+2
A33: 30 | B33: =B32+3*A32 -> 1470 | C33: =3*A32 -> 87 | D33: =D32+A33-1 -> 445 | E33: =A33-1 -> 29 | H33: 1950 | I33: 17 | J33: 4 | K33: =K32+5 -> 105 | L33: 8 | M33: BE+2, Straucheln: 1 sec PA-Kl.-1 | N33: BE+2
A34: 31 | B34: =B33+3*A33 -> 1560 | C34: =3*A33 -> 90 | D34: =D33+A34-1 -> 475 | E34: =A34-1 -> 30 | H34: 2150 | I34: 18 | J34: 4 | K34: =K33+5 -> 110 | L34: 9 | M34: BE+2, Straucheln: 1 sec PA-Kl.-1 | N34: BE+2
A35: 32 | B35: =B34+3*A34 -> 1653 | C35: =3*A34 -> 93 | D35: =D34+A35-1 -> 506 | E35: =A35-1 -> 31 | H35: 2350 | I35: 19 | J35: 4 | K35: =K34+5 -> 115 | L35: 10 | M35: BE+3, Sturz: PA-Kl.-2, jede sec Ath-Probe,um PA-Kl. wieder um 1 zu erhöhen | N35: BE+3
A36: 33 | B36: =B35+3*A35 -> 1749 | C36: =3*A35 -> 96 | D36: =D35+A36-1 -> 538 | E36: =A36-1 -> 32 | H36: 2550 | I36: 20 | J36: 4 | K36: =K35+5 -> 120 | L36: 11 | M36: BE+3, Sturz: PA-Kl.-2, jede sec Ath-Probe,um PA-Kl. wieder um 1 zu erhöhen | N36: BE+3
A37: 34 | B37: =B36+3*A36 -> 1848 | C37: =3*A36 -> 99 | D37: =D36+A37-1 -> 571 | E37: =A37-1 -> 33 | H37: 2750 | I37: 21 | J37: 4 | K37: =K36+5 -> 125 | L37: 12 | M37: BE+4, Waffe verloren: 1 sec PA-Kl.-1 | N37: BE+4
... A42: 39 | B42: =B41+3*A41 -> 2388 | C42: =3*A41 -> 114 | D42: =D41+A42-1 -> 751 | E42: =A42-1 -> 38 | H42: 3800 | I42: 26 | J42: 5 | K42: =K41+5 -> 150 | L42: 17 | M42: BE+7, bewusstlos: jede W30 sec (Kon-BE)-Probe zum Erwachen | N42: BE+7
A43: 40 | B43: =B42+3*A42 -> 2505 | C43: =3*A42 -> 117 | D43: =D42+A43-1 -> 790 | E43: =A43-1 -> 39 | H43: 4050 | I43: 27 | J43: 5 | K43: =K42+5 -> 155
A44: 41 | B44: =B43+3*A43 -> 2625 | C44: =3*A43 -> 120 | D44: =D43+A44-1 -> 830 | E44: =A44-1 -> 40 | H44: 4300 | I44: 28 | J44: 5 | K44: =K43+5 -> 160 | L44: =IF(-'NPC-Rechner'!L31>0,(IF(-'NPC-Rechner'!L31<17,(INDEX(L26:M41,-'NPC-Rechner'!L31,2)),M42)),M25) -> geschafft
...

Sheet S.1
P3: Nasus’Nasus
M7: Name: _______________________________
B11: Kreis | I11: =kr -> 7 | L11: ATTRIBUTE | S11: Spezies | AE11: Größe
B12: Stufe | I12: =st -> 58 | L12: Aura | P12: =Aur -> 5 | S12: Beruf | AE12: Gewicht
B13: Macht | I13: =ma -> 27 | L13: Glück | P13: =glü -> 3 | S13: Alter | AE13: Haarfarbe
B14: Mana | I14: =mn -> 165 | L14: Magie | P14: =mag -> 5 | S14: Geburtstag | AE14: Haarschnitt
B15: Rerolls | I15: =kr-1 -> 6 | L15: Vitalität | P15: =vit -> 14 | S15: Heimat | AE15: Bartwuchs
B16: Erfahrungspkt. | I16: =ep -> 13692 | L16: Karma | P16: =kar -> 0 | S16: Familie | AE16: Hautfarbe
B17: Steigerungspkt. | I17: =epfrei -> 0 | L17: Weisheit | P17: =weisheit -> 8 | S17: Religion | AE17: Augenfarbe
B19: EIGENSCHAFTEN | V19: EIGENSCHAFTEN
B20: Ausstrahlung | V20: Athletik
B21: Intelligenz | V21: Geschicklichkeit
B22: Mut | V22: Konstitution
B23: Sinnesschärfe | V23: Schnelligkeit
B24: Willenskraft | V24: Stärke
B26: TALENTE | V26: VOR- UND NACHTEILE
B35: Ausdauer | M35: SONDERFERTIGKEITEN | X35: NAHKAMPF | AG35: FERNKAMPF
B36: Dauerlauf | M36: Ausweichen | X36: Unbewaffnet | AG36: Bögen
B37: Sprinten (m/s) | M37: Gutes AW | X37: -> Armklingen | AG37: -> Bögen
B38: Hochsprung (m) | M38: Meisterl. AW | X38: -> Messer | AG38: Schusswaffen
B39: Weitsprung (m) | M39: Alchemieresistenz | X39: -> Peitschen | AG39: -> Armbrust
B40: GRUNDFERTIGKEITEN | M40: Fliehen | X40: -> Rüstung | AG40: -> Pistole
B41: Fliegen | M41: Rüstungsmanöver | X41: -> Schild | AG41: -> Musketen
B42: Klettern | M42: Selbstbeherrschung | X42: Stichwaffen | AG42: SPRACHEN
B43: Körperbeherrschung | M43: Tragen | X43: -> Dolche | AG43: Zwergisch
B44: Springen | M44: KI-Meditation | X44: -> Fechtwaffen | AG44: Elfisch
B45: Sprinten | M45: Konzentration | X45: Klingenwaffen | AG45: Orkisch
B46: Dauerlauf | M46: Mana-Meditation | X46: -> Kurzschwerter | AG46: Goblinsch
... B49: Rudern | M49: Gefahreninstinkt | X49: Hiebwaffen | AG49: Straitmor
B50: Schleichen | M50: LS Armbrust | X50: -> Äxte
B51: Schwimmen | M51: LS Bogen | X51: -> Stumpfe HW
B52: Verstecken | M52: LS Blasrohr | X52: -> Kettenwaffen
B53: Betören | M53: LS Vorderlader | X53: -> Beidhändige
B54: Einschüchtern | M54: LS Patrone | X54: Stangenwaffen | AG54: SCHRIFTEN
B55: Fährtensuche | M55: LS Runenwaffen | X55: -> Stäbe | AG55: Zwergisch
B56: Lügen | M56: LS Kanone | X56: -> Speere | AG56: Elfisch
B57: Orientierung | M57: LS Schleuder | X57: -> Hellebarden
B58: Menschenkenntnis | M58: LS Wurfmesser | X58: -> Lanzen

Sheet Sheet2
A1: NPC Bogen 0.1
A3: TS | D3: RS | F3: LE
A4: Kopf | F4: ='NPC-Rechner'!E21 -> 28
A5: Brust | F5: ='NPC-Rechner'!E22 -> 41
A6: Torso | F6: ='NPC-Rechner'!E23 -> 34
A7: R. Arm | F7: ='NPC-Rechner'!E24 -> 27
A8: L. Arm | F8: ='NPC-Rechner'!E25 -> 27
A9: R. Bein | F9: ='NPC-Rechner'!E26 -> 46
A10: L. Bein | F10: ='NPC-Rechner'!E27 -> 46
A11: Ges. | F11: ='NPC-Rechner'!E20 -> 46

Sheet NPC-Ausgabe
A1: Kreis | B1: =kr -> 7 | E1: Name: | L1: Größe:
A2: Stufe | B2: =st -> 58 | E2: Rasse: | L2: Gew:
A3: Macht | B3: =ma -> 27
A4: GLÜ | B4: =glü -> 3 | E4: Vorteile:
A5: VIT | B5: =vit -> 14 | E5: Nachteile:
A6: AUR | B6: =Aur -> 5
A7: MAG | B7: =mag -> 5
A8: WEI | B8: =kr+1 -> 8 | E8: Ini | F8: =ini -> 34 | H8: SB | I8: =sbwert -> 47 | K8: BE | L8: ='[1]NPC-Rechner'!AJ36 -> 0 | O8: defAW | P8: =defaw -> 18 | Q8: offAW | R8: =offaw -> 14 | S8: gAW | T8: =gawwert -> 5 | U8: mAW | V8: =mawwert -> 25
A9: KAR | B9: =kar -> 0
A10: Aus | B10: =Aus -> 21 | C10: =ausb -> 6 | E10: Nahkampf | G10: Ini | H10: WK | I10: W1 | J10: W2 | K10: Stä-Mod | L10: RB | M10: Tarn | O10: nAT | P10: gAT | Q10: mAT | R10: nPA | S10: gPA | T10: mPA | U10: KB | V10: KS
A11: Int | B11: =Int -> 27 | C11: =intb -> 9
A12: Mut | B12: =Mut -> 21 | C12: =mutb -> 6
A13: Sin | B13: =Sin -> 21 | C13: =sinb -> 6
A14: Wil | B14: =Wil -> 29 | C14: =wilb -> 10
A15: Ath | B15: =Ath -> 23 | C15: =athb -> 7
A16: Ges | B16: =Ges -> 23 | C16: =gesb -> 7 | E16: Fernkampf | G16: Schaden | I16: RB | J16: 10m | K16: 30m | L16: 60m | M16: 120m | N16: 210m
A17: Kon | B17: =Kon -> 38 | C17: =konb -> 14
A18: Sch | B18: =Sch -> 21 | C18: =schb -> 6
A19: Stä | B19: =Stä -> 25 | C19: =stäb -> 8
A20: Sprint | B20: =sprintE -> 11.29 | C20: m/sec
A21: Jog | B21: =dauerE -> 8.45 | C21: m/sec
A22: Hochsprung | B22: =hochsp -> 1.28 | C22: m
A23: Weitsprung | B23: =weitsp -> 9.5 | C23: m | E23: Ausdauer | F23: =ausdauerw -> 212
A24: GefSinn Probe | C24: =gefins+Sin -> 31 | E24: Mana | F24: =mn-SUM(G24:V24) -> 165
A25: Gefahrensinn | C25: =gefins -> 10 | E25: MK | F25: =mk -> 92
A26: Ausweichen | C26: =AW -> 12 | E26: BE | F26: =ROUNDUP(((bekopf+betorso+bearme+bebeine)-ROUNDUP((ROUNDUP(Kon/5,0)+Stä)/2,0)-RS)/6,0) -> -3
A27: Konzentration | C27: =Konzentration -> 12
A28: KI-Meditation | C28: ='[1]NPC-Rechner'!S89 -> 0 | I28: TS | J28: =vit+5 -> 19 | L28: Schild | M28: RS | O28: LE
A29: Mana-Meditation | C29: ='[1]NPC-Rechner'!S90 -> 0 | F29: RS
A30: Optio 1 | E30: LE Kopf | F30: =rskopf -> 12 | G30: =LEkopf-IF(H30>0,H30-$F30,0)-IF(I30>0,I30-$F30,0)-IF(J30>0,J30-$F30,0)-IF(K30>0,K30-$F30,0)-IF(L30>0,L30-$F30,0)-IF(M30>0,M30-$F30,0)-IF(N30>0,N30-$F30,0)-IF(M30>0,M30-$F30,0)-IF(O30>0,O30-$F30,0)-IF(P30>0,P30-$F30,0)-IF(Q30>0,Q30-$F30,0)-IF(R30>0,R30-$F30,0)-IF(S30>0,S30-$F30,0)-IF(T30>0,T30-$F30,0)-IF(U30>0,U30-$F30,0)-IF(V30>0,V30-$F30,0) -> 28
A31: Optio 2 | E31: LE Brust | F31: =rstorso -> 12 | G31: =LEbrust-IF(H31>0,H31-$F31,0)-IF(I31>0,I31-$F31,0)-IF(J31>0,J31-$F31,0)-IF(K31>0,K31-$F31,0)-IF(L31>0,L31-$F31,0)-IF(M31>0,M31-$F31,0)-IF(N31>0,N31-$F31,0)-IF(M31>0,M31-$F31,0)-IF(O31>0,O31-$F31,0)-IF(P31>0,P31-$F31,0)-IF(Q31>0,Q31-$F31,0)-IF(R31>0,R31-$F31,0)-IF(S31>0,S31-$F31,0)-IF(T31>0,T31-$F31,0)-IF(U31>0,U31-$F31,0)-IF(V31>0,V31-$F31,0) -> 41
A32: Optio 3 | E32: LE Unterleib | F32: =rstorso -> 12 | G32: =LEunter -> 34
A33: Optio 4 | E33: LE l.Arm | F33: =rsarme -> 12 | G33: =LElarm -> 27
A34: Optio 5 | E34: LE r.Arm | F34: =rsarme -> 12 | G34: =LErarm -> 27
A35: Optio 6 | E35: LE l.Bein | F35: =rsbeine -> 12 | G35: =lelbein -> 46
E36: LE r.Bein | F36: =rsbeine -> 12 | G36: =lerbein -> 46
E37: Ges | G37: =gesundheit -> 46

Sheet RS-Sheet
B1: Kopf | C1: Verarbeitung | D1: Anpassung | E1: RS | F1: BE | G1: Preis | H1: NW | I1: AW
A2: Lage 1 | B2: Schwere Stoffrüstung | C2: Einzelstück | D2: perfekt angepasst | E2: =IF(B2="Keine Rüstung",0,(VLOOKUP(B2,$A$43:$H$67,3,FALSE)+VLOOKUP(C2,$K$51:$Q$54,3,FALSE))) -> 5 | F2: =IF(B2="Keine Rüstung",0,IF(SUM(VLOOKUP(B2,$A$43:$H$67,4,FALSE)+VLOOKUP(D2,$K$57:$Q$60,4,FALSE)+VLOOKUP(C2,$K$51:$Q$54,4,FALSE))<=VLOOKUP(B2,$A$43:$H$67,2,FALSE),VLOOKUP(B2,$A$43:$H$67,2,FALSE),SUM(VLOOKUP(B2,$A$43:$H$67,4,FALSE)+VLOOKUP(D2,$K$57:$Q$60,4,FALSE)+VLOOKUP(C2,$K$51:$Q$54,4,FALSE)))) -> 1 | G2: =VLOOKUP(B2,$A$44:$I$67,8,FALSE)+VLOOKUP(C2,$K$51:$R$54,8,FALSE)*(VLOOKUP(B2,$A$44:$I$67,9,FALSE)+VLOOKUP(D2,$K$56:$R$60,8,FALSE)) -> 758 | H2: =MAX(VLOOKUP(B2,$A$44:$G$67,6,FALSE),VLOOKUP(C2,$K$51:$Q$54,6,FALSE),VLOOKUP(D2,$K$57:$Q$60,6,FALSE)) -> 7 | I2: =MAX(VLOOKUP(B2,$A$44:$G$67,7,FALSE),VLOOKUP(C2,$K$51:$Q$54,7,FALSE),VLOOKUP(D2,$K$57:$Q$60,7,FALSE)) -> 7
A3: Lage 2 | B3: Schwere Lederrüstung | C3: Einzelstück | D3: perfekt angepasst | E3: =IF(B3="Keine Rüstung",0,(VLOOKUP(B3,$A$43:$H$67,3,FALSE)+VLOOKUP(C3,$K$51:$Q$54,3,FALSE))) -> 7 | F3: =IF(B3="Keine Rüstung",0,IF(SUM(VLOOKUP(B3,$A$43:$H$67,4,FALSE)+VLOOKUP(D3,$K$57:$Q$60,4,FALSE)+VLOOKUP(C3,$K$51:$Q$54,4,FALSE))<=VLOOKUP(B3,$A$43:$H$67,2,FALSE),VLOOKUP(B3,$A$43:$H$67,2,FALSE),SUM(VLOOKUP(B3,$A$43:$H$67,4,FALSE)+VLOOKUP(D3,$K$57:$Q$60,4,FALSE)+VLOOKUP(C3,$K$51:$Q$54,4,FALSE)))) -> 2 | G3: =VLOOKUP(B3,$A$44:$I$67,8,FALSE)+VLOOKUP(C3,$K$51:$R$54,8,FALSE)*(VLOOKUP(B3,$A$44:$I$67,9,FALSE)+VLOOKUP(D3,$K$56:$R$60,8,FALSE)) -> 900 | H3: =MAX(VLOOKUP(B3,$A$44:$G$67,6,FALSE),VLOOKUP(C3,$K$51:$Q$54,6,FALSE),VLOOKUP(D3,$K$57:$Q$60,6,FALSE)) -> 7 | I3: =MAX(VLOOKUP(B3,$A$44:$G$67,7,FALSE),VLOOKUP(C3,$K$51:$Q$54,7,FALSE),VLOOKUP(D3,$K$57:$Q$60,7,FALSE)) -> 7
A4: Lage 3 | B4: Keine Rüstung | C4: Gesellenarbeit | D4: von der Stange | E4: =IF(B4="Keine Rüstung",0,(VLOOKUP(B4,$A$43:$H$67,3,FALSE)+VLOOKUP(C4,$K$51:$Q$54,3,FALSE))) -> 0 | F4: =IF(B4="Keine Rüstung",0,IF(SUM(VLOOKUP(B4,$A$43:$H$67,4,FALSE)+VLOOKUP(D4,$K$57:$Q$60,4,FALSE)+VLOOKUP(C4,$K$51:$Q$54,4,FALSE))<=VLOOKUP(B4,$A$43:$H$67,2,FALSE),VLOOKUP(B4,$A$43:$H$67,2,FALSE),SUM(VLOOKUP(B4,$A$43:$H$67,4,FALSE)+VLOOKUP(D4,$K$57:$Q$60,4,FALSE)+VLOOKUP(C4,$K$51:$Q$54,4,FALSE)))) -> 0 | G4: =VLOOKUP(B4,$A$44:$I$67,8,FALSE)+VLOOKUP(C4,$K$51:$R$54,8,FALSE)*(VLOOKUP(B4,$A$44:$I$67,9,FALSE)+VLOOKUP(D4,$K$56:$R$60,8,FALSE)) -> 0 | H4: =MAX(VLOOKUP(B4,$A$44:$G$67,6,FALSE),VLOOKUP(C4,$K$51:$Q$54,6,FALSE),VLOOKUP(D4,$K$57:$Q$60,6,FALSE)) -> 1 | I4: =MAX(VLOOKUP(B4,$A$44:$G$67,7,FALSE),VLOOKUP(C4,$K$51:$Q$54,7,FALSE),VLOOKUP(D4,$K$57:$Q$60,7,FALSE)) -> 1
A5: Lage 4 | B5: Keine Rüstung | C5: Gesellenarbeit | D5: von der Stange | E5: =IF(B5="Keine Rüstung",0,(VLOOKUP(B5,$A$43:$H$67,3,FALSE)+VLOOKUP(C5,$K$51:$Q$54,3,FALSE))) -> 0 | F5: =IF(B5="Keine Rüstung",0,IF(SUM(VLOOKUP(B5,$A$43:$H$67,4,FALSE)+VLOOKUP(D5,$K$57:$Q$60,4,FALSE)+VLOOKUP(C5,$K$51:$Q$54,4,FALSE))<=VLOOKUP(B5,$A$43:$H$67,2,FALSE),VLOOKUP(B5,$A$43:$H$67,2,FALSE),SUM(VLOOKUP(B5,$A$43:$H$67,4,FALSE)+VLOOKUP(D5,$K$57:$Q$60,4,FALSE)+VLOOKUP(C5,$K$51:$Q$54,4,FALSE)))) -> 0 | G5: =VLOOKUP(B5,$A$44:$I$67,8,FALSE)+VLOOKUP(C5,$K$51:$R$54,8,FALSE)*(VLOOKUP(B5,$A$44:$I$67,9,FALSE)+VLOOKUP(D5,$K$56:$R$60,8,FALSE)) -> 0 | H5: =MAX(VLOOKUP(B5,$A$44:$G$67,6,FALSE),VLOOKUP(C5,$K$51:$Q$54,6,FALSE),VLOOKUP(D5,$K$57:$Q$60,6,FALSE)) -> 1 | I5: =MAX(VLOOKUP(B5,$A$44:$G$67,7,FALSE),VLOOKUP(C5,$K$51:$Q$54,7,FALSE),VLOOKUP(D5,$K$57:$Q$60,7,FALSE)) -> 1
A6: Lage 5 | B6: Keine Rüstung | E6: =VLOOKUP(B6,$K$44:$Q$48,3,FALSE) -> 0 | F6: =VLOOKUP(B6,$K$44:$Q$48,3,FALSE) -> 0 | G6: =VLOOKUP(B6,$K$44:$Q$48,5,FALSE) -> 0 | H6: =VLOOKUP(B6,$K$44:$Q$48,6,FALSE) -> 0 | I6: =VLOOKUP(B6,$K$44:$Q$48,6,FALSE) -> 0
C7: =B1 -> Kopf | D7: Gesamt: | E7: =SUM(E2:E6) -> 12 | F7: =SUM(F2:F6) -> 3 | G7: =SUM(G2:G6) -> 1658
B9: Torso | C9: Verarbeitung | D9: Anpassung | E9: RS | F9: BE | G9: Preis | H9: NW | I9: AW
A10: Lage 1 | B10: Schwere Stoffrüstung | C10: Einzelstück | D10: perfekt angepasst | E10: =IF(B10="Keine Rüstung",0,(VLOOKUP(B10,$A$43:$H$67,3,FALSE)+VLOOKUP(C10,$K$51:$Q$54,3,FALSE))) -> 5 | F10: =IF(B10="Keine Rüstung",0,IF(SUM(VLOOKUP(B10,$A$43:$H$67,4,FALSE)+VLOOKUP(D10,$K$57:$Q$60,4,FALSE)+VLOOKUP(C10,$K$51:$Q$54,4,FALSE))<=VLOOKUP(B10,$A$43:$H$67,2,FALSE),VLOOKUP(B10,$A$43:$H$67,2,FALSE),SUM(VLOOKUP(B10,$A$43:$H$67,4,FALSE)+VLOOKUP(D10,$K$57:$Q$60,4,FALSE)+VLOOKUP(C10,$K$51:$Q$54,4,FALSE)))) -> 1 | G10: =VLOOKUP(B10,$A$44:$I$67,8,FALSE)+VLOOKUP(C10,$K$51:$R$54,8,FALSE)*(VLOOKUP(B10,$A$44:$I$67,9,FALSE)+VLOOKUP(D10,$K$56:$R$60,8,FALSE)) -> 758 | H10: =MAX(VLOOKUP(B10,$A$44:$G$67,6,FALSE),VLOOKUP(C10,$K$51:$Q$54,6,FALSE),VLOOKUP(D10,$K$57:$Q$60,6,FALSE)) -> 7 | I10: =MAX(VLOOKUP(B10,$A$44:$G$67,7,FALSE),VLOOKUP(C10,$K$51:$Q$54,7,FALSE),VLOOKUP(D10,$K$57:$Q$60,7,FALSE)) -> 7
A11: Lage 2 | B11: Schwere Lederrüstung | C11: Einzelstück | D11: perfekt angepasst | E11: =IF(B11="Keine Rüstung",0,(VLOOKUP(B11,$A$43:$H$67,3,FALSE)+VLOOKUP(C11,$K$51:$Q$54,3,FALSE))) -> 7 | F11: =IF(B11="Keine Rüstung",0,IF(SUM(VLOOKUP(B11,$A$43:$H$67,4,FALSE)+VLOOKUP(D11,$K$57:$Q$60,4,FALSE)+VLOOKUP(C11,$K$51:$Q$54,4,FALSE))<=VLOOKUP(B11,$A$43:$H$67,2,FALSE),VLOOKUP(B11,$A$43:$H$67,2,FALSE),SUM(VLOOKUP(B11,$A$43:$H$67,4,FALSE)+VLOOKUP(D11,$K$57:$Q$60,4,FALSE)+VLOOKUP(C11,$K$51:$Q$54,4,FALSE)))) -> 2 | G11: =VLOOKUP(B11,$A$44:$I$67,8,FALSE)+VLOOKUP(C11,$K$51:$R$54,8,FALSE)*(VLOOKUP(B11,$A$44:$I$67,9,FALSE)+VLOOKUP(D11,$K$56:$R$60,8,FALSE)) -> 900 | H11: =MAX(VLOOKUP(B11,$A$44:$G$67,6,FALSE),VLOOKUP(C11,$K$51:$Q$54,6,FALSE),VLOOKUP(D11,$K$57:$Q$60,6,FALSE)) -> 7 | I11: =MAX(VLOOKUP(B11,$A$44:$G$67,7,FALSE),VLOOKUP(C11,$K$51:$Q$54,7,FALSE),VLOOKUP(D11,$K$57:$Q$60,7,FALSE)) -> 7 | M11: Kon | N11: =Kon -> 38
A12: Lage 3 | B12: Keine Rüstung | C12: Gesellenarbeit | D12: von der Stange | E12: =IF(B12="Keine Rüstung",0,(VLOOKUP(B12,$A$43:$H$67,3,FALSE)+VLOOKUP(C12,$K$51:$Q$54,3,FALSE))) -> 0 | F12: =IF(B12="Keine Rüstung",0,IF(SUM(VLOOKUP(B12,$A$43:$H$67,4,FALSE)+VLOOKUP(D12,$K$57:$Q$60,4,FALSE)+VLOOKUP(C12,$K$51:$Q$54,4,FALSE))<=VLOOKUP(B12,$A$43:$H$67,2,FALSE),VLOOKUP(B12,$A$43:$H$67,2,FALSE),SUM(VLOOKUP(B12,$A$43:$H$67,4,FALSE)+VLOOKUP(D12,$K$57:$Q$60,4,FALSE)+VLOOKUP(C12,$K$51:$Q$54,4,FALSE)))) -> 0 | G12: =VLOOKUP(B12,$A$44:$I$67,8,FALSE)+VLOOKUP(C12,$K$51:$R$54,8,FALSE)*(VLOOKUP(B12,$A$44:$I$67,9,FALSE)+VLOOKUP(D12,$K$56:$R$60,8,FALSE)) -> 0 | H12: =MAX(VLOOKUP(B12,$A$44:$G$67,6,FALSE),VLOOKUP(C12,$K$51:$Q$54,6,FALSE),VLOOKUP(D12,$K$57:$Q$60,6,FALSE)) -> 1 | I12: =MAX(VLOOKUP(B12,$A$44:$G$67,7,FALSE),VLOOKUP(C12,$K$51:$Q$54,7,FALSE),VLOOKUP(D12,$K$57:$Q$60,7,FALSE)) -> 1 | M12: Stä | N12: =Stä -> 25
A13: Lage 4 | B13: Keine Rüstung | C13: Gesellenarbeit | D13: von der Stange | E13: =IF(B13="Keine Rüstung",0,(VLOOKUP(B13,$A$43:$H$67,3,FALSE)+VLOOKUP(C13,$K$51:$Q$54,3,FALSE))) -> 0 | F13: =IF(B13="Keine Rüstung",0,IF(SUM(VLOOKUP(B13,$A$43:$H$67,4,FALSE)+VLOOKUP(D13,$K$57:$Q$60,4,FALSE)+VLOOKUP(C13,$K$51:$Q$54,4,FALSE))<=VLOOKUP(B13,$A$43:$H$67,2,FALSE),VLOOKUP(B13,$A$43:$H$67,2,FALSE),SUM(VLOOKUP(B13,$A$43:$H$67,4,FALSE)+VLOOKUP(D13,$K$57:$Q$60,4,FALSE)+VLOOKUP(C13,$K$51:$Q$54,4,FALSE)))) -> 0 | G13: =VLOOKUP(B13,$A$44:$I$67,8,FALSE)+VLOOKUP(C13,$K$51:$R$54,8,FALSE)*(VLOOKUP(B13,$A$44:$I$67,9,FALSE)+VLOOKUP(D13,$K$56:$R$60,8,FALSE)) -> 0 | H13: =MAX(VLOOKUP(B13,$A$44:$G$67,6,FALSE),VLOOKUP(C13,$K$51:$Q$54,6,FALSE),VLOOKUP(D13,$K$57:$Q$60,6,FALSE)) -> 1 | I13: =MAX(VLOOKUP(B13,$A$44:$G$67,7,FALSE),VLOOKUP(C13,$K$51:$Q$54,7,FALSE),VLOOKUP(D13,$K$57:$Q$60,7,FALSE)) -> 1 | M13: TaW | N13: =RS -> 12
A14: Lage 5 | B14: Keine Rüstung | E14: =VLOOKUP(B14,$K$44:$Q$48,3,FALSE) -> 0 | F14: =VLOOKUP(B14,$K$44:$Q$48,3,FALSE) -> 0 | G14: =VLOOKUP(B14,$K$44:$Q$48,5,FALSE) -> 0 | H14: =VLOOKUP(B14,$K$44:$Q$48,6,FALSE) -> 0 | I14: =VLOOKUP(B14,$K$44:$Q$48,6,FALSE) -> 0 | N14: =ROUNDUP((ROUNDUP(Kon/5,0)+Stä)/2,0)+RS -> 29
C15: =B9 -> Torso | D15: Gesamt: | E15: =SUM(E10:E14) -> 12 | F15: =SUM(F10:F14) -> 3 | G15: =SUM(G10:G14) -> 1658 | M15: RBE | N15: =F34-N14 -> -17
M16: BE | N16: =ROUNDUP(N15/6,0) -> -3
B17: Arme | C17: Verarbeitung | D17: Anpassung | E17: RS | F17: BE | G17: Preis | H17: NW | I17: AW
A18: Lage 1 | B18: Schwere Stoffrüstung | C18: Einzelstück | D18: perfekt angepasst | E18: =IF(B18="Keine Rüstung",0,(VLOOKUP(B18,$A$43:$H$67,3,FALSE)+VLOOKUP(C18,$K$51:$Q$54,3,FALSE))) -> 5 | F18: =IF(B18="Keine Rüstung",0,IF(SUM(VLOOKUP(B18,$A$43:$H$67,4,FALSE)+VLOOKUP(D18,$K$57:$Q$60,4,FALSE)+VLOOKUP(C18,$K$51:$Q$54,4,FALSE))<=VLOOKUP(B18,$A$43:$H$67,2,FALSE),VLOOKUP(B18,$A$43:$H$67,2,FALSE),SUM(VLOOKUP(B18,$A$43:$H$67,4,FALSE)+VLOOKUP(D18,$K$57:$Q$60,4,FALSE)+VLOOKUP(C18,$K$51:$Q$54,4,FALSE)))) -> 1 | G18: =VLOOKUP(B18,$A$44:$I$67,8,FALSE)+VLOOKUP(C18,$K$51:$R$54,8,FALSE)*(VLOOKUP(B18,$A$44:$I$67,9,FALSE)+VLOOKUP(D18,$K$56:$R$60,8,FALSE)) -> 758 | H18: =MAX(VLOOKUP(B18,$A$44:$G$67,6,FALSE),VLOOKUP(C18,$K$51:$Q$54,6,FALSE),VLOOKUP(D18,$K$57:$Q$60,6,FALSE)) -> 7 | I18: =MAX(VLOOKUP(B18,$A$44:$G$67,7,FALSE),VLOOKUP(C18,$K$51:$Q$54,7,FALSE),VLOOKUP(D18,$K$57:$Q$60,7,FALSE)) -> 7
A19: Lage 2 | B19: Schwere Lederrüstung | C19: Einzelstück | D19: perfekt angepasst | E19: =IF(B19="Keine Rüstung",0,(VLOOKUP(B19,$A$43:$H$67,3,FALSE)+VLOOKUP(C19,$K$51:$Q$54,3,FALSE))) -> 7 | F19: =IF(B19="Keine Rüstung",0,IF(SUM(VLOOKUP(B19,$A$43:$H$67,4,FALSE)+VLOOKUP(D19,$K$57:$Q$60,4,FALSE)+VLOOKUP(C19,$K$51:$Q$54,4,FALSE))<=VLOOKUP(B19,$A$43:$H$67,2,FALSE),VLOOKUP(B19,$A$43:$H$67,2,FALSE),SUM(VLOOKUP(B19,$A$43:$H$67,4,FALSE)+VLOOKUP(D19,$K$57:$Q$60,4,FALSE)+VLOOKUP(C19,$K$51:$Q$54,4,FALSE)))) -> 2 | G19: =VLOOKUP(B19,$A$44:$I$67,8,FALSE)+VLOOKUP(C19,$K$51:$R$54,8,FALSE)*(VLOOKUP(B19,$A$44:$I$67,9,FALSE)+VLOOKUP(D19,$K$56:$R$60,8,FALSE)) -> 900 | H19: =MAX(VLOOKUP(B19,$A$44:$G$67,6,FALSE),VLOOKUP(C19,$K$51:$Q$54,6,FALSE),VLOOKUP(D19,$K$57:$Q$60,6,FALSE)) -> 7 | I19: =MAX(VLOOKUP(B19,$A$44:$G$67,7,FALSE),VLOOKUP(C19,$K$51:$Q$54,7,FALSE),VLOOKUP(D19,$K$57:$Q$60,7,FALSE)) -> 7
A20: Lage 3 | B20: Keine Rüstung | C20: Gesellenarbeit | D20: von der Stange | E20: =IF(B20="Keine Rüstung",0,(VLOOKUP(B20,$A$43:$H$67,3,FALSE)+VLOOKUP(C20,$K$51:$Q$54,3,FALSE))) -> 0 | F20: =IF(B20="Keine Rüstung",0,IF(SUM(VLOOKUP(B20,$A$43:$H$67,4,FALSE)+VLOOKUP(D20,$K$57:$Q$60,4,FALSE)+VLOOKUP(C20,$K$51:$Q$54,4,FALSE))<=VLOOKUP(B20,$A$43:$H$67,2,FALSE),VLOOKUP(B20,$A$43:$H$67,2,FALSE),SUM(VLOOKUP(B20,$A$43:$H$67,4,FALSE)+VLOOKUP(D20,$K$57:$Q$60,4,FALSE)+VLOOKUP(C20,$K$51:$Q$54,4,FALSE)))) -> 0 | G20: =VLOOKUP(B20,$A$44:$I$67,8,FALSE)+VLOOKUP(C20,$K$51:$R$54,8,FALSE)*(VLOOKUP(B20,$A$44:$I$67,9,FALSE)+VLOOKUP(D20,$K$56:$R$60,8,FALSE)) -> 0 | H20: =MAX(VLOOKUP(B20,$A$44:$G$67,6,FALSE),VLOOKUP(C20,$K$51:$Q$54,6,FALSE),VLOOKUP(D20,$K$57:$Q$60,6,FALSE)) -> 1 | I20: =MAX(VLOOKUP(B20,$A$44:$G$67,7,FALSE),VLOOKUP(C20,$K$51:$Q$54,7,FALSE),VLOOKUP(D20,$K$57:$Q$60,7,FALSE)) -> 1
A21: Lage 4 | B21: Keine Rüstung | C21: Gesellenarbeit | D21: von der Stange | E21: =IF(B21="Keine Rüstung",0,(VLOOKUP(B21,$A$43:$H$67,3,FALSE)+VLOOKUP(C21,$K$51:$Q$54,3,FALSE))) -> 0 | F21: =IF(B21="Keine Rüstung",0,IF(SUM(VLOOKUP(B21,$A$43:$H$67,4,FALSE)+VLOOKUP(D21,$K$57:$Q$60,4,FALSE)+VLOOKUP(C21,$K$51:$Q$54,4,FALSE))<=VLOOKUP(B21,$A$43:$H$67,2,FALSE),VLOOKUP(B21,$A$43:$H$67,2,FALSE),SUM(VLOOKUP(B21,$A$43:$H$67,4,FALSE)+VLOOKUP(D21,$K$57:$Q$60,4,FALSE)+VLOOKUP(C21,$K$51:$Q$54,4,FALSE)))) -> 0 | G21: =VLOOKUP(B21,$A$44:$I$67,8,FALSE)+VLOOKUP(C21,$K$51:$R$54,8,FALSE)*(VLOOKUP(B21,$A$44:$I$67,9,FALSE)+VLOOKUP(D21,$K$56:$R$60,8,FALSE)) -> 0 | H21: =MAX(VLOOKUP(B21,$A$44:$G$67,6,FALSE),VLOOKUP(C21,$K$51:$Q$54,6,FALSE),VLOOKUP(D21,$K$57:$Q$60,6,FALSE)) -> 1 | I21: =MAX(VLOOKUP(B21,$A$44:$G$67,7,FALSE),VLOOKUP(C21,$K$51:$Q$54,7,FALSE),VLOOKUP(D21,$K$57:$Q$60,7,FALSE)) -> 1
A22: Lage 5 | B22: Keine Rüstung | E22: =VLOOKUP(B22,$K$44:$Q$48,3,FALSE) -> 0 | F22: =VLOOKUP(B22,$K$44:$Q$48,3,FALSE) -> 0 | G22: =VLOOKUP(B22,$K$44:$Q$48,5,FALSE) -> 0 | H22: =VLOOKUP(B22,$K$44:$Q$48,6,FALSE) -> 0 | I22: =VLOOKUP(B22,$K$44:$Q$48,6,FALSE) -> 0
C23: =B17 -> Arme | D23: Gesamt: | E23: =SUM(E18:E22) -> 12 | F23: =SUM(F18:F22) -> 3 | G23: =SUM(G18:G22) -> 1658
B25: Beine | C25: Verarbeitung | D25: Anpassung | E25: RS | F25: BE | G25: Preis | H25: NW | I25: AW
A26: Lage 1 | B26: Schwere Stoffrüstung | C26: Einzelstück | D26: perfekt angepasst | E26: =IF(B26="Keine Rüstung",0,(VLOOKUP(B26,$A$43:$H$67,3,FALSE)+VLOOKUP(C26,$K$51:$Q$54,3,FALSE))) -> 5 | F26: =IF(B26="Keine Rüstung",0,IF(SUM(VLOOKUP(B26,$A$43:$H$67,4,FALSE)+VLOOKUP(D26,$K$57:$Q$60,4,FALSE)+VLOOKUP(C26,$K$51:$Q$54,4,FALSE))<=VLOOKUP(B26,$A$43:$H$67,2,FALSE),VLOOKUP(B26,$A$43:$H$67,2,FALSE),SUM(VLOOKUP(B26,$A$43:$H$67,4,FALSE)+VLOOKUP(D26,$K$57:$Q$60,4,FALSE)+VLOOKUP(C26,$K$51:$Q$54,4,FALSE)))) -> 1 | G26: =VLOOKUP(B26,$A$44:$I$67,8,FALSE)+VLOOKUP(C26,$K$51:$R$54,8,FALSE)*(VLOOKUP(B26,$A$44:$I$67,9,FALSE)+VLOOKUP(D26,$K$56:$R$60,8,FALSE)) -> 758 | H26: =MAX(VLOOKUP(B26,$A$44:$G$67,6,FALSE),VLOOKUP(C26,$K$51:$Q$54,6,FALSE),VLOOKUP(D26,$K$57:$Q$60,6,FALSE)) -> 7 | I26: =MAX(VLOOKUP(B26,$A$44:$G$67,7,FALSE),VLOOKUP(C26,$K$51:$Q$54,7,FALSE),VLOOKUP(D26,$K$57:$Q$60,7,FALSE)) -> 7
A27: Lage 2 | B27: Schwere Lederrüstung | C27: Einzelstück | D27: perfekt angepasst | E27: =IF(B27="Keine Rüstung",0,(VLOOKUP(B27,$A$43:$H$67,3,FALSE)+VLOOKUP(C27,$K$51:$Q$54,3,FALSE))) -> 7 | F27: =IF(B27="Keine Rüstung",0,IF(SUM(VLOOKUP(B27,$A$43:$H$67,4,FALSE)+VLOOKUP(D27,$K$57:$Q$60,4,FALSE)+VLOOKUP(C27,$K$51:$Q$54,4,FALSE))<=VLOOKUP(B27,$A$43:$H$67,2,FALSE),VLOOKUP(B27,$A$43:$H$67,2,FALSE),SUM(VLOOKUP(B27,$A$43:$H$67,4,FALSE)+VLOOKUP(D27,$K$57:$Q$60,4,FALSE)+VLOOKUP(C27,$K$51:$Q$54,4,FALSE)))) -> 2 | G27: =VLOOKUP(B27,$A$44:$I$67,8,FALSE)+VLOOKUP(C27,$K$51:$R$54,8,FALSE)*(VLOOKUP(B27,$A$44:$I$67,9,FALSE)+VLOOKUP(D27,$K$56:$R$60,8,FALSE)) -> 900 | H27: =MAX(VLOOKUP(B27,$A$44:$G$67,6,FALSE),VLOOKUP(C27,$K$51:$Q$54,6,FALSE),VLOOKUP(D27,$K$57:$Q$60,6,FALSE)) -> 7 | I27: =MAX(VLOOKUP(B27,$A$44:$G$67,7,FALSE),VLOOKUP(C27,$K$51:$Q$54,7,FALSE),VLOOKUP(D27,$K$57:$Q$60,7,FALSE)) -> 7
A28: Lage 3 | B28: Keine Rüstung | C28: Gesellenarbeit | D28: von der Stange | E28: =IF(B28="Keine Rüstung",0,(VLOOKUP(B28,$A$43:$H$67,3,FALSE)+VLOOKUP(C28,$K$51:$Q$54,3,FALSE))) -> 0 | F28: =IF(B28="Keine Rüstung",0,IF(SUM(VLOOKUP(B28,$A$43:$H$67,4,FALSE)+VLOOKUP(D28,$K$57:$Q$60,4,FALSE)+VLOOKUP(C28,$K$51:$Q$54,4,FALSE))<=VLOOKUP(B28,$A$43:$H$67,2,FALSE),VLOOKUP(B28,$A$43:$H$67,2,FALSE),SUM(VLOOKUP(B28,$A$43:$H$67,4,FALSE)+VLOOKUP(D28,$K$57:$Q$60,4,FALSE)+VLOOKUP(C28,$K$51:$Q$54,4,FALSE)))) -> 0 | G28: =VLOOKUP(B28,$A$44:$I$67,8,FALSE)+VLOOKUP(C28,$K$51:$R$54,8,FALSE)*(VLOOKUP(B28,$A$44:$I$67,9,FALSE)+VLOOKUP(D28,$K$56:$R$60,8,FALSE)) -> 0 | H28: =MAX(VLOOKUP(B28,$A$44:$G$67,6,FALSE),VLOOKUP(C28,$K$51:$Q$54,6,FALSE),VLOOKUP(D28,$K$57:$Q$60,6,FALSE)) -> 1 | I28: =MAX(VLOOKUP(B28,$A$44:$G$67,7,FALSE),VLOOKUP(C28,$K$51:$Q$54,7,FALSE),VLOOKUP(D28,$K$57:$Q$60,7,FALSE)) -> 1
A29: Lage 4 | B29: Keine Rüstung | C29: Gesellenarbeit | D29: von der Stange | E29: =IF(B29="Keine Rüstung",0,(VLOOKUP(B29,$A$43:$H$67,3,FALSE)+VLOOKUP(C29,$K$51:$Q$54,3,FALSE))) -> 0 | F29: =IF(B29="Keine Rüstung",0,IF(SUM(VLOOKUP(B29,$A$43:$H$67,4,FALSE)+VLOOKUP(D29,$K$57:$Q$60,4,FALSE)+VLOOKUP(C29,$K$51:$Q$54,4,FALSE))<=VLOOKUP(B29,$A$43:$H$67,2,FALSE),VLOOKUP(B29,$A$43:$H$67,2,FALSE),SUM(VLOOKUP(B29,$A$43:$H$67,4,FALSE)+VLOOKUP(D29,$K$57:$Q$60,4,FALSE)+VLOOKUP(C29,$K$51:$Q$54,4,FALSE)))) -> 0 | G29: =VLOOKUP(B29,$A$44:$I$67,8,FALSE)+VLOOKUP(C29,$K$51:$R$54,8,FALSE)*(VLOOKUP(B29,$A$44:$I$67,9,FALSE)+VLOOKUP(D29,$K$56:$R$60,8,FALSE)) -> 0 | H29: =MAX(VLOOKUP(B29,$A$44:$G$67,6,FALSE),VLOOKUP(C29,$K$51:$Q$54,6,FALSE),VLOOKUP(D29,$K$57:$Q$60,6,FALSE)) -> 1 | I29: =MAX(VLOOKUP(B29,$A$44:$G$67,7,FALSE),VLOOKUP(C29,$K$51:$Q$54,7,FALSE),VLOOKUP(D29,$K$57:$Q$60,7,FALSE)) -> 1
A30: Lage 5 | B30: Keine Rüstung | E30: =VLOOKUP(B30,$K$44:$Q$48,3,FALSE) -> 0 | F30: =VLOOKUP(B30,$K$44:$Q$48,3,FALSE) -> 0 | G30: =VLOOKUP(B30,$K$44:$Q$48,5,FALSE) -> 0 | H30: =VLOOKUP(B30,$K$44:$Q$48,6,FALSE) -> 0 | I30: =VLOOKUP(B30,$K$44:$Q$48,6,FALSE) -> 0
C31: =B25 -> Beine | D31: Gesamt: | E31: =SUM(E26:E30) -> 12 | F31: =SUM(F26:F30) -> 3 | G31: =SUM(G26:G30) -> 1658
F33: BE | G33: Preis
C34: Rüstung | D34: Gesamt: | F34: =SUM(F7,F15,F23,F31) -> 12 | G34: =SUM(G7,G15,G23,G31) -> 6632
A36: Legende:
A37: Hals, Schultergelenk, Ellenbogen, Hände, Knie und Füße werden nur mit halbem RS geschützt. Augen werden nicht geschützt.Für alle nicht genannten kritischen Trefferzonen gilt der volle Rüstungswert.
A38: Jedes Rüstungsteil kann durch Verarbeitung und Anpassung einmalig modifiziert werden.
A39: Jedes Rüstungsteil hat seine Lage als Mindest-RBE. Lage 5 (Umhänge, Aufpanzerungen) sind hiervon ausgenommen.
A40: Drachenschuppen und andere Aufpanzerungen verfügen über bestimmte Boni, die derzeit noch in der alten Waffentabelle aufgeführt sind...
A43: Rüstung | B43: Lage | C43: RS | D43: BE | F43: Verfügbarkeit NW | G43: Verfügbarkeit AW | H43: Materialkosten | I43: Arbeitszeit/d | K43: Addons | L43: Lage | M43: RS | N43: BE | P43: Verfügbarkeit | Q43: Verfügbarkeit
A44: Keine Rüstung | K44: Keine Rüstung
A45: Leichte Stoffrüstung | B45: 1 | C45: 1 | D45: 1 | F45: 1 | G45: 1 | H45: 16 | I45: 1 | K45: Leichte Drachenschuppen | M45: 3 | N45: 2 | P45: 6 | Q45: 6
A46: Stoffrüstung | B46: 1 | C46: 2 | D46: 2 | F46: 1 | G46: 1 | H46: 32 | I46: 1 | K46: Drachenschuppen | M46: 5 | N46: 4 | P46: 6 | Q46: 6
...
