Workbook
Name _FilterDatabase_0: Munition!$A$1:$I$1
Name _FilterDatabase_0: 'Ressourcen-Waffen'!$A$1:$AI$65
Name _FilterDatabase_0: Waffen!$A$1:$AE$90
Name Anpassung: Waffen!$A$91:$A$93
Name gobherstellung: 'Ressourcen-Waffen'!$AL$3:$AL$9
Name Herstellung: 'Ressourcen-Waffen'!$AM$3:$AM$8
Name Modifikatoren: 'Ressourcen-Waffen'!$B$45:$AI$54
Name Res: 'Ressourcen-Waffen'!$A$1:$AI$54
Name Ressourcen: 'Ressourcen-Waffen'!$A$2:$AJ$54
Name Verarb: Waffen!$A$94:$A$100
Name verarbeitung: Waffen!$A$95:$A$100
Name verftab: 'Ressourcen-Waffen'!$AO$3:$AP$9
Name wtab: 'Ressourcen-Waffen'!$AJ$3:$AK$12

Sheet Waffen
A1: Name | B1: Volk | C1: Typ | D1: Bauart | E1: Lademechanik | F1: Schloss | G1: Lauf | H1: Munition | I1: Verarbeitung | J1: Anpassung | K1: Gewicht | L1: Min. Stä | M1: 1.W | N1: 2.W | O1: Fixschaden | P1: RB | Q1: Kaliber | R1: 10m | S1: 30m | T1: 60m | U1: 100m | V1: 150m | W1: 210m | X1: RW | Y1: Nachladezeit | Z1: Nachladen TaW-Teiler | AA1: Patzermodifikator | AB1: Verfügbarkeit | AC1: Preis | AD1: Herstellungszeit | AE1: Materialpreis | AF1: Verfuegbarkeit (1-7)
A2: Hakenbüchse | B2: Dalkinisch | C2: Gewehr | D2: Hakenbüchse | E2: Vorderlader | F2: Luntenschloss | G2: Glattlauf | H2: Blei | I2: Massenfabrikation | J2: Von der Stange | K2: =VLOOKUP(B2,Res,11,0)+VLOOKUP(C2,Res,11,0)+VLOOKUP(D2,Res,11,0)+VLOOKUP(E2,Res,11,0)+VLOOKUP(G2,Res,11,0) -> 6.8 | L2: =VLOOKUP(B2,Res,12,0)+VLOOKUP(C2,Res,12,0)+VLOOKUP(D2,Res,12,0)+VLOOKUP(J2,Res,12,0) -> 14 | M2: =VLOOKUP(VLOOKUP(B2,Res,13,0)+VLOOKUP(C2,Res,13,0)+VLOOKUP(D2,Res,13,0),wtab,2,0) -> W12 | N2: =VLOOKUP(VLOOKUP(B2,Res,14,0)+VLOOKUP(C2,Res,14,0)+VLOOKUP(D2,Res,14,0),wtab,2,0) -> W10 | O2: =VLOOKUP(B2,Res,15,0)+VLOOKUP(C2,Res,15,0)+VLOOKUP(D2,Res,15,0) -> 2 | P2: =VLOOKUP(B2,Res,16,0)+VLOOKUP(C2,Res,16,0)+VLOOKUP(D2,Res,16,0)+VLOOKUP(E2,Res,16,0) -> 14 | Q2: =VLOOKUP(B2,Res,17,0)+VLOOKUP(C2,Res,17,0)+VLOOKUP(D2,Res,17,0)+VLOOKUP(E2,Res,17,0) -> 19 | R2: =VLOOKUP(B2,Res,18,0)+VLOOKUP(C2,Res,18,0)+VLOOKUP(D2,Res,18,0)+VLOOKUP(F2,Res,18,0)+VLOOKUP(G2,Res,18,0)+VLOOKUP(I2,Res,18,0)+VLOOKUP(J2,Res,18,0) -> -1 | S2: =VLOOKUP(B2,Res,19,0)+VLOOKUP(C2,Res,19,0)+VLOOKUP(D2,Res,19,0)+VLOOKUP(F2,Res,19,0)+VLOOKUP(G2,Res,19,0)+VLOOKUP(I2,Res,19,0)+VLOOKUP(J2,Res,19,0) -> -5 | T2: =VLOOKUP(B2,Res,20,0)+VLOOKUP(C2,Res,20,0)+VLOOKUP(D2,Res,20,0)+VLOOKUP(F2,Res,20,0)+VLOOKUP(G2,Res,20,0)+VLOOKUP(I2,Res,20,0)+VLOOKUP(J2,Res,20,0) -> -9 | U2: =VLOOKUP(B2,Res,21,0)+VLOOKUP(C2,Res,21,0)+VLOOKUP(D2,Res,21,0)+VLOOKUP(F2,Res,21,0)+VLOOKUP(G2,Res,21,0)+VLOOKUP(I2,Res,21,0)+VLOOKUP(J2,Res,21,0) -> -15 | V2: =VLOOKUP(B2,Res,22,0)+VLOOKUP(C2,Res,22,0)+VLOOKUP(D2,Res,22,0)+VLOOKUP(F2,Res,22,0)+VLOOKUP(G2,Res,22,0)+VLOOKUP(I2,Res,22,0)+VLOOKUP(J2,Res,22,0) -> -23 | W2: =VLOOKUP(B2,Res,23,0)+VLOOKUP(C2,Res,23,0)+VLOOKUP(D2,Res,23,0)+VLOOKUP(F2,Res,23,0)+VLOOKUP(G2,Res,23,0)+VLOOKUP(I2,Res,23,0)+VLOOKUP(J2,Res,23,0) -> -31 | X2: =VLOOKUP(B2,Res,24,0)+VLOOKUP(C2,Res,24,0)+VLOOKUP(D2,Res,24,0)+VLOOKUP(G2,Res,24,0) -> 60 | Y2: =VLOOKUP(D2,Res,25,0)+VLOOKUP(E2,Res,25,0)+VLOOKUP(F2,Res,25,0) -> 39 | Z2: =VLOOKUP(E2,Res,26,0) -> 3 | AA2: =VLOOKUP(B2,Res,27,0)+VLOOKUP(D2,Res,27,0)+VLOOKUP(F2,Res,27,0)+VLOOKUP(I2,Res,27,0) -> 4 | AB2: =VLOOKUP(B2,Res,28,0)+VLOOKUP(C2,Res,28,0)+VLOOKUP(D2,Res,28,0)+VLOOKUP(E2,Res,28,0)+VLOOKUP(F2,Res,28,0)+VLOOKUP(G2,Res,28,0)+VLOOKUP(I2,Res,28,0)+VLOOKUP(J2,Res,28,0) -> 105 | AC2: =VLOOKUP(I2,Res,31,0)*AD2+AE2 -> 614.7 | AD2: =VLOOKUP(B2,Res,30,0)+VLOOKUP(C2,Res,30,0)+VLOOKUP(D2,Res,30,0)+VLOOKUP(F2,Res,30,0)+VLOOKUP(G2,Res,30,0)+VLOOKUP(I2,Res,30,0)+VLOOKUP(J2,Res,30,0) -> 6.2 | AE2: =(VLOOKUP(C2,Res,32,0)+VLOOKUP(I2,Res,32,0))*(VLOOKUP(B2,Res,34,0)+VLOOKUP(C2,Res,34,0)+VLOOKUP(D2,Res,34,0)+VLOOKUP(E2,Res,34,0)+VLOOKUP(G2,Res,34,0))+VLOOKUP(B2,Res,35,0)+VLOOKUP(C2,Res,35,0)+VLOOKUP(D2,Res,35,0) -> 589.9 | AF2: =VLOOKUP(AB2,verftab,2,1) -> 5
A3: Muskete | B3: Dalkinisch | C3: Gewehr | D3: Normal | E3: Vorderlader | F3: Luntenschloss | G3: Glattlauf | H3: Blei | I3: Massenfabrikation | J3: Von der Stange | K3: =VLOOKUP(B3,Res,11,0)+VLOOKUP(C3,Res,11,0)+VLOOKUP(D3,Res,11,0)+VLOOKUP(E3,Res,11,0)+VLOOKUP(G3,Res,11,0) -> 3.8 | L3: =VLOOKUP(B3,Res,12,0)+VLOOKUP(C3,Res,12,0)+VLOOKUP(D3,Res,12,0)+VLOOKUP(J3,Res,12,0) -> 10 | M3: =VLOOKUP(VLOOKUP(B3,Res,13,0)+VLOOKUP(C3,Res,13,0)+VLOOKUP(D3,Res,13,0),wtab,2,0) -> W8 | N3: =VLOOKUP(VLOOKUP(B3,Res,14,0)+VLOOKUP(C3,Res,14,0)+VLOOKUP(D3,Res,14,0),wtab,2,0) -> W8 | O3: =VLOOKUP(B3,Res,15,0)+VLOOKUP(C3,Res,15,0)+VLOOKUP(D3,Res,15,0) -> 1 | P3: =VLOOKUP(B3,Res,16,0)+VLOOKUP(C3,Res,16,0)+VLOOKUP(D3,Res,16,0)+VLOOKUP(E3,Res,16,0) -> 11 | Q3: =VLOOKUP(B3,Res,17,0)+VLOOKUP(C3,Res,17,0)+VLOOKUP(D3,Res,17,0)+VLOOKUP(E3,Res,17,0) -> 17 | R3: =VLOOKUP(B3,Res,18,0)+VLOOKUP(C3,Res,18,0)+VLOOKUP(D3,Res,18,0)+VLOOKUP(F3,Res,18,0)+VLOOKUP(G3,Res,18,0)+VLOOKUP(I3,Res,18,0)+VLOOKUP(J3,Res,18,0) -> 3 | S3: =VLOOKUP(B3,Res,19,0)+VLOOKUP(C3,Res,19,0)+VLOOKUP(D3,Res,19,0)+VLOOKUP(F3,Res,19,0)+VLOOKUP(G3,Res,19,0)+VLOOKUP(I3,Res,19,0)+VLOOKUP(J3,Res,19,0) -> -3 | T3: =VLOOKUP(B3,Res,20,0)+VLOOKUP(C3,Res,20,0)+VLOOKUP(D3,Res,20,0)+VLOOKUP(F3,Res,20,0)+VLOOKUP(G3,Res,20,0)+VLOOKUP(I3,Res,20,0)+VLOOKUP(J3,Res,20,0) -> -9 | U3: =VLOOKUP(B3,Res,21,0)+VLOOKUP(C3,Res,21,0)+VLOOKUP(D3,Res,21,0)+VLOOKUP(F3,Res,21,0)+VLOOKUP(G3,Res,21,0)+VLOOKUP(I3,Res,21,0)+VLOOKUP(J3,Res,21,0) -> -15 | V3: =VLOOKUP(B3,Res,22,0)+VLOOKUP(C3,Res,22,0)+VLOOKUP(D3,Res,22,0)+VLOOKUP(F3,Res,22,0)+VLOOKUP(G3,Res,22,0)+VLOOKUP(I3,Res,22,0)+VLOOKUP(J3,Res,22,0) -> -23 | W3: =VLOOKUP(B3,Res,23,0)+VLOOKUP(C3,Res,23,0)+VLOOKUP(D3,Res,23,0)+VLOOKUP(F3,Res,23,0)+VLOOKUP(G3,Res,23,0)+VLOOKUP(I3,Res,23,0)+VLOOKUP(J3,Res,23,0) -> -31 | X3: =VLOOKUP(B3,Res,24,0)+VLOOKUP(C3,Res,24,0)+VLOOKUP(D3,Res,24,0)+VLOOKUP(G3,Res,24,0) -> 40 | Y3: =VLOOKUP(D3,Res,25,0)+VLOOKUP(E3,Res,25,0)+VLOOKUP(F3,Res,25,0) -> 31 | Z3: =VLOOKUP(E3,Res,26,0) -> 3 | AA3: =VLOOKUP(B3,Res,27,0)+VLOOKUP(D3,Res,27,0)+VLOOKUP(F3,Res,27,0)+VLOOKUP(I3,Res,27,0) -> 4 | AB3: =VLOOKUP(B3,Res,28,0)+VLOOKUP(C3,Res,28,0)+VLOOKUP(D3,Res,28,0)+VLOOKUP(E3,Res,28,0)+VLOOKUP(F3,Res,28,0)+VLOOKUP(G3,Res,28,0)+VLOOKUP(I3,Res,28,0)+VLOOKUP(J3,Res,28,0) -> 130 | AC3: =VLOOKUP(I3,Res,31,0)*AD3+AE3 -> 242.7 | AD3: =VLOOKUP(B3,Res,30,0)+VLOOKUP(C3,Res,30,0)+VLOOKUP(D3,Res,30,0)+VLOOKUP(F3,Res,30,0)+VLOOKUP(G3,Res,30,0)+VLOOKUP(I3,Res,30,0)+VLOOKUP(J3,Res,30,0) -> 3.2 | AE3: =(VLOOKUP(C3,Res,32,0)+VLOOKUP(I3,Res,32,0))*(VLOOKUP(B3,Res,34,0)+VLOOKUP(C3,Res,34,0)+VLOOKUP(D3,Res,34,0)+VLOOKUP(E3,Res,34,0)+VLOOKUP(G3,Res,34,0))+VLOOKUP(B3,Res,35,0)+VLOOKUP(C3,Res,35,0)+VLOOKUP(D3,Res,35,0) -> 229.9 | AF3: =VLOOKUP(AB3,verftab,2,1) -> 3
A4: Schweres Gewehr | B4: Dalkinisch | C4: Gewehr | D4: Schwer | E4: Vorderlader | F4: Luntenschloss | G4: Glattlauf | H4: Blei | I4: Massenfabrikation | J4: Von der Stange | K4: =VLOOKUP(B4,Res,11,0)+VLOOKUP(C4,Res,11,0)+VLOOKUP(D4,Res,11,0)+VLOOKUP(E4,Res,11,0)+VLOOKUP(G4,Res,11,0) -> 4.8 | L4: =VLOOKUP(B4,Res,12,0)+VLOOKUP(C4,Res,12,0)+VLOOKUP(D4,Res,12,0)+VLOOKUP(J4,Res,12,0) -> 12 | M4: =VLOOKUP(VLOOKUP(B4,Res,13,0)+VLOOKUP(C4,Res,13,0)+VLOOKUP(D4,Res,13,0),wtab,2,0) -> W10 | N4: =VLOOKUP(VLOOKUP(B4,Res,14,0)+VLOOKUP(C4,Res,14,0)+VLOOKUP(D4,Res,14,0),wtab,2,0) -> W10 | O4: =VLOOKUP(B4,Res,15,0)+VLOOKUP(C4,Res,15,0)+VLOOKUP(D4,Res,15,0) -> 2 | P4: =VLOOKUP(B4,Res,16,0)+VLOOKUP(C4,Res,16,0)+VLOOKUP(D4,Res,16,0)+VLOOKUP(E4,Res,16,0) -> 12 | Q4: =VLOOKUP(B4,Res,17,0)+VLOOKUP(C4,Res,17,0)+VLOOKUP(D4,Res,17,0)+VLOOKUP(E4,Res,17,0) -> 18 | R4: =VLOOKUP(B4,Res,18,0)+VLOOKUP(C4,Res,18,0)+VLOOKUP(D4,Res,18,0)+VLOOKUP(F4,Res,18,0)+VLOOKUP(G4,Res,18,0)+VLOOKUP(I4,Res,18,0)+VLOOKUP(J4,Res,18,0) -> 1 | S4: =VLOOKUP(B4,Res,19,0)+VLOOKUP(C4,Res,19,0)+VLOOKUP(D4,Res,19,0)+VLOOKUP(F4,Res,19,0)+VLOOKUP(G4,Res,19,0)+VLOOKUP(I4,Res,19,0)+VLOOKUP(J4,Res,19,0) -> -4 | T4: =VLOOKUP(B4,Res,20,0)+VLOOKUP(C4,Res,20,0)+VLOOKUP(D4,Res,20,0)+VLOOKUP(F4,Res,20,0)+VLOOKUP(G4,Res,20,0)+VLOOKUP(I4,Res,20,0)+VLOOKUP(J4,Res,20,0) -> -9 | U4: =VLOOKUP(B4,Res,21,0)+VLOOKUP(C4,Res,21,0)+VLOOKUP(D4,Res,21,0)+VLOOKUP(F4,Res,21,0)+VLOOKUP(G4,Res,21,0)+VLOOKUP(I4,Res,21,0)+VLOOKUP(J4,Res,21,0) -> -15 | V4: =VLOOKUP(B4,Res,22,0)+VLOOKUP(C4,Res,22,0)+VLOOKUP(D4,Res,22,0)+VLOOKUP(F4,Res,22,0)+VLOOKUP(G4,Res,22,0)+VLOOKUP(I4,Res,22,0)+VLOOKUP(J4,Res,22,0) -> -23 | W4: =VLOOKUP(B4,Res,23,0)+VLOOKUP(C4,Res,23,0)+VLOOKUP(D4,Res,23,0)+VLOOKUP(F4,Res,23,0)+VLOOKUP(G4,Res,23,0)+VLOOKUP(I4,Res,23,0)+VLOOKUP(J4,Res,23,0) -> -31 | X4: =VLOOKUP(B4,Res,24,0)+VLOOKUP(C4,Res,24,0)+VLOOKUP(D4,Res,24,0)+VLOOKUP(G4,Res,24,0) -> 60 | Y4: =VLOOKUP(D4,Res,25,0)+VLOOKUP(E4,Res,25,0)+VLOOKUP(F4,Res,25,0) -> 33 | Z4: =VLOOKUP(E4,Res,26,0) -> 3 | AA4: =VLOOKUP(B4,Res,27,0)+VLOOKUP(D4,Res,27,0)+VLOOKUP(F4,Res,27,0)+VLOOKUP(I4,Res,27,0) -> 4 | AB4: =VLOOKUP(B4,Res,28,0)+VLOOKUP(C4,Res,28,0)+VLOOKUP(D4,Res,28,0)+VLOOKUP(E4,Res,28,0)+VLOOKUP(F4,Res,28,0)+VLOOKUP(G4,Res,28,0)+VLOOKUP(I4,Res,28,0)+VLOOKUP(J4,Res,28,0) -> 120 | AC4: =VLOOKUP(I4,Res,31,0)*AD4+AE4 -> 366.7 | AD4: =VLOOKUP(B4,Res,30,0)+VLOOKUP(C4,Res,30,0)+VLOOKUP(D4,Res,30,0)+VLOOKUP(F4,Res,30,0)+VLOOKUP(G4,Res,30,0)+VLOOKUP(I4,Res,30,0)+VLOOKUP(J4,Res,30,0) -> 4.2 | AE4: =(VLOOKUP(C4,Res,32,0)+VLOOKUP(I4,Res,32,0))*(VLOOKUP(B4,Res,34,0)+VLOOKUP(C4,Res,34,0)+VLOOKUP(D4,Res,34,0)+VLOOKUP(E4,Res,34,0)+VLOOKUP(G4,Res,34,0))+VLOOKUP(B4,Res,35,0)+VLOOKUP(C4,Res,35,0)+VLOOKUP(D4,Res,35,0) -> 349.9 | AF4: =VLOOKUP(AB4,verftab,2,1) -> 4
A5: Langpistole | B5: Dalkinisch | C5: Pistole | D5: Langlauf | E5: Vorderlader | F5: Luntenschloss | G5: Glattlauf | H5: Blei | I5: Massenfabrikation | J5: Von der Stange | K5: =VLOOKUP(B5,Res,11,0)+VLOOKUP(C5,Res,11,0)+VLOOKUP(D5,Res,11,0)+VLOOKUP(E5,Res,11,0)+VLOOKUP(G5,Res,11,0) -> 1.85 | L5: =VLOOKUP(B5,Res,12,0)+VLOOKUP(C5,Res,12,0)+VLOOKUP(D5,Res,12,0)+VLOOKUP(J5,Res,12,0) -> 7 | M5: =VLOOKUP(VLOOKUP(B5,Res,13,0)+VLOOKUP(C5,Res,13,0)+VLOOKUP(D5,Res,13,0),wtab,2,0) -> W8 | N5: =VLOOKUP(VLOOKUP(B5,Res,14,0)+VLOOKUP(C5,Res,14,0)+VLOOKUP(D5,Res,14,0),wtab,2,0) -> W10 | O5: =VLOOKUP(B5,Res,15,0)+VLOOKUP(C5,Res,15,0)+VLOOKUP(D5,Res,15,0) -> 1 | P5: =VLOOKUP(B5,Res,16,0)+VLOOKUP(C5,Res,16,0)+VLOOKUP(D5,Res,16,0)+VLOOKUP(E5,Res,16,0) -> 6 | Q5: =VLOOKUP(B5,Res,17,0)+VLOOKUP(C5,Res,17,0)+VLOOKUP(D5,Res,17,0)+VLOOKUP(E5,Res,17,0) -> 14 | R5: =VLOOKUP(B5,Res,18,0)+VLOOKUP(C5,Res,18,0)+VLOOKUP(D5,Res,18,0)+VLOOKUP(F5,Res,18,0)+VLOOKUP(G5,Res,18,0)+VLOOKUP(I5,Res,18,0)+VLOOKUP(J5,Res,18,0) -> 5 | S5: =VLOOKUP(B5,Res,19,0)+VLOOKUP(C5,Res,19,0)+VLOOKUP(D5,Res,19,0)+VLOOKUP(F5,Res,19,0)+VLOOKUP(G5,Res,19,0)+VLOOKUP(I5,Res,19,0)+VLOOKUP(J5,Res,19,0) -> -1 | T5: =VLOOKUP(B5,Res,20,0)+VLOOKUP(C5,Res,20,0)+VLOOKUP(D5,Res,20,0)+VLOOKUP(F5,Res,20,0)+VLOOKUP(G5,Res,20,0)+VLOOKUP(I5,Res,20,0)+VLOOKUP(J5,Res,20,0) -> -13 | U5: =VLOOKUP(B5,Res,21,0)+VLOOKUP(C5,Res,21,0)+VLOOKUP(D5,Res,21,0)+VLOOKUP(F5,Res,21,0)+VLOOKUP(G5,Res,21,0)+VLOOKUP(I5,Res,21,0)+VLOOKUP(J5,Res,21,0) -> -25 | V5: =VLOOKUP(B5,Res,22,0)+VLOOKUP(C5,Res,22,0)+VLOOKUP(D5,Res,22,0)+VLOOKUP(F5,Res,22,0)+VLOOKUP(G5,Res,22,0)+VLOOKUP(I5,Res,22,0)+VLOOKUP(J5,Res,22,0) -> -40 | W5: =VLOOKUP(B5,Res,23,0)+VLOOKUP(C5,Res,23,0)+VLOOKUP(D5,Res,23,0)+VLOOKUP(F5,Res,23,0)+VLOOKUP(G5,Res,23,0)+VLOOKUP(I5,Res,23,0)+VLOOKUP(J5,Res,23,0) -> -56 | X5: =VLOOKUP(B5,Res,24,0)+VLOOKUP(C5,Res,24,0)+VLOOKUP(D5,Res,24,0)+VLOOKUP(G5,Res,24,0) -> 40 | Y5: =VLOOKUP(D5,Res,25,0)+VLOOKUP(E5,Res,25,0)+VLOOKUP(F5,Res,25,0) -> 31 | Z5: =VLOOKUP(E5,Res,26,0) -> 3 | AA5: =VLOOKUP(B5,Res,27,0)+VLOOKUP(D5,Res,27,0)+VLOOKUP(F5,Res,27,0)+VLOOKUP(I5,Res,27,0) -> 4 | AB5: =VLOOKUP(B5,Res,28,0)+VLOOKUP(C5,Res,28,0)+VLOOKUP(D5,Res,28,0)+VLOOKUP(E5,Res,28,0)+VLOOKUP(F5,Res,28,0)+VLOOKUP(G5,Res,28,0)+VLOOKUP(I5,Res,28,0)+VLOOKUP(J5,Res,28,0) -> 115 | AC5: =VLOOKUP(I5,Res,31,0)*AD5+AE5 -> 170.55 | AD5: =VLOOKUP(B5,Res,30,0)+VLOOKUP(C5,Res,30,0)+VLOOKUP(D5,Res,30,0)+VLOOKUP(F5,Res,30,0)+VLOOKUP(G5,Res,30,0)+VLOOKUP(I5,Res,30,0)+VLOOKUP(J5,Res,30,0) -> 3.5 | AE5: =(VLOOKUP(C5,Res,32,0)+VLOOKUP(I5,Res,32,0))*(VLOOKUP(B5,Res,34,0)+VLOOKUP(C5,Res,34,0)+VLOOKUP(D5,Res,34,0)+VLOOKUP(E5,Res,34,0)+VLOOKUP(G5,Res,34,0))+VLOOKUP(B5,Res,35,0)+VLOOKUP(C5,Res,35,0)+VLOOKUP(D5,Res,35,0) -> 156.55 | AF5: =VLOOKUP(AB5,verftab,2,1) -> 4
A6: Pistole | B6: Dalkinisch | C6: Pistole | D6: Normal P | E6: Vorderlader | F6: Luntenschloss | G6: Glattlauf | H6: Blei | I6: Massenfabrikation | J6: Von der Stange | K6: =VLOOKUP(B6,Res,11,0)+VLOOKUP(C6,Res,11,0)+VLOOKUP(D6,Res,11,0)+VLOOKUP(E6,Res,11,0)+VLOOKUP(G6,Res,11,0) -> 1.55 | L6: =VLOOKUP(B6,Res,12,0)+VLOOKUP(C6,Res,12,0)+VLOOKUP(D6,Res,12,0)+VLOOKUP(J6,Res,12,0) -> 7 | M6: =VLOOKUP(VLOOKUP(B6,Res,13,0)+VLOOKUP(C6,Res,13,0)+VLOOKUP(D6,Res,13,0),wtab,2,0) -> W8 | N6: =VLOOKUP(VLOOKUP(B6,Res,14,0)+VLOOKUP(C6,Res,14,0)+VLOOKUP(D6,Res,14,0),wtab,2,0) -> W8 | O6: =VLOOKUP(B6,Res,15,0)+VLOOKUP(C6,Res,15,0)+VLOOKUP(D6,Res,15,0) -> 0 | P6: =VLOOKUP(B6,Res,16,0)+VLOOKUP(C6,Res,16,0)+VLOOKUP(D6,Res,16,0)+VLOOKUP(E6,Res,16,0) -> 6 | Q6: =VLOOKUP(B6,Res,17,0)+VLOOKUP(C6,Res,17,0)+VLOOKUP(D6,Res,17,0)+VLOOKUP(E6,Res,17,0) -> 14 | R6: =VLOOKUP(B6,Res,18,0)+VLOOKUP(C6,Res,18,0)+VLOOKUP(D6,Res,18,0)+VLOOKUP(F6,Res,18,0)+VLOOKUP(G6,Res,18,0)+VLOOKUP(I6,Res,18,0)+VLOOKUP(J6,Res,18,0) -> 6 | S6: =VLOOKUP(B6,Res,19,0)+VLOOKUP(C6,Res,19,0)+VLOOKUP(D6,Res,19,0)+VLOOKUP(F6,Res,19,0)+VLOOKUP(G6,Res,19,0)+VLOOKUP(I6,Res,19,0)+VLOOKUP(J6,Res,19,0) -> -3 | T6: =VLOOKUP(B6,Res,20,0)+VLOOKUP(C6,Res,20,0)+VLOOKUP(D6,Res,20,0)+VLOOKUP(F6,Res,20,0)+VLOOKUP(G6,Res,20,0)+VLOOKUP(I6,Res,20,0)+VLOOKUP(J6,Res,20,0) -> -14 | U6: =VLOOKUP(B6,Res,21,0)+VLOOKUP(C6,Res,21,0)+VLOOKUP(D6,Res,21,0)+VLOOKUP(F6,Res,21,0)+VLOOKUP(G6,Res,21,0)+VLOOKUP(I6,Res,21,0)+VLOOKUP(J6,Res,21,0) -> -26 | V6: =VLOOKUP(B6,Res,22,0)+VLOOKUP(C6,Res,22,0)+VLOOKUP(D6,Res,22,0)+VLOOKUP(F6,Res,22,0)+VLOOKUP(G6,Res,22,0)+VLOOKUP(I6,Res,22,0)+VLOOKUP(J6,Res,22,0) -> -41 | W6: =VLOOKUP(B6,Res,23,0)+VLOOKUP(C6,Res,23,0)+VLOOKUP(D6,Res,23,0)+VLOOKUP(F6,Res,23,0)+VLOOKUP(G6,Res,23,0)+VLOOKUP(I6,Res,23,0)+VLOOKUP(J6,Res,23,0) -> -57 | X6: =VLOOKUP(B6,Res,24,0)+VLOOKUP(C6,Res,24,0)+VLOOKUP(D6,Res,24,0)+VLOOKUP(G6,Res,24,0) -> 30 | Y6: =VLOOKUP(D6,Res,25,0)+VLOOKUP(E6,Res,25,0)+VLOOKUP(F6,Res,25,0) -> 31 | Z6: =VLOOKUP(E6,Res,26,0) -> 3 | AA6: =VLOOKUP(B6,Res,27,0)+VLOOKUP(D6,Res,27,0)+VLOOKUP(F6,Res,27,0)+VLOOKUP(I6,Res,27,0) -> 4 | AB6: =VLOOKUP(B6,Res,28,0)+VLOOKUP(C6,Res,28,0)+VLOOKUP(D6,Res,28,0)+VLOOKUP(E6,Res,28,0)+VLOOKUP(F6,Res,28,0)+VLOOKUP(G6,Res,28,0)+VLOOKUP(I6,Res,28,0)+VLOOKUP(J6,Res,28,0) -> 130 | AC6: =VLOOKUP(I6,Res,31,0)*AD6+AE6 -> 132.55 | AD6: =VLOOKUP(B6,Res,30,0)+VLOOKUP(C6,Res,30,0)+VLOOKUP(D6,Res,30,0)+VLOOKUP(F6,Res,30,0)+VLOOKUP(G6,Res,30,0)+VLOOKUP(I6,Res,30,0)+VLOOKUP(J6,Res,30,0) -> 3 | AE6: =(VLOOKUP(C6,Res,32,0)+VLOOKUP(I6,Res,32,0))*(VLOOKUP(B6,Res,34,0)+VLOOKUP(C6,Res,34,0)+VLOOKUP(D6,Res,34,0)+VLOOKUP(E6,Res,34,0)+VLOOKUP(G6,Res,34,0))+VLOOKUP(B6,Res,35,0)+VLOOKUP(C6,Res,35,0)+VLOOKUP(D6,Res,35,0) -> 120.55 | AF6: =VLOOKUP(AB6,verftab,2,1) -> 3
A7: verb. Langpistole | B7: Dalkinisch | C7: Pistole | D7: Langlauf | E7: Vorderlader | F7: Steinschloss | G7: Glattlauf | H7: Blei | I7: Massenfabrikation | J7: Von der Stange | K7: =VLOOKUP(B7,Res,11,0)+VLOOKUP(C7,Res,11,0)+VLOOKUP(D7,Res,11,0)+VLOOKUP(E7,Res,11,0)+VLOOKUP(G7,Res,11,0) -> 1.85 | L7: =VLOOKUP(B7,Res,12,0)+VLOOKUP(C7,Res,12,0)+VLOOKUP(D7,Res,12,0)+VLOOKUP(J7,Res,12,0) -> 7 | M7: =VLOOKUP(VLOOKUP(B7,Res,13,0)+VLOOKUP(C7,Res,13,0)+VLOOKUP(D7,Res,13,0),wtab,2,0) -> W8 | N7: =VLOOKUP(VLOOKUP(B7,Res,14,0)+VLOOKUP(C7,Res,14,0)+VLOOKUP(D7,Res,14,0),wtab,2,0) -> W10 | O7: =VLOOKUP(B7,Res,15,0)+VLOOKUP(C7,Res,15,0)+VLOOKUP(D7,Res,15,0) -> 1 | P7: =VLOOKUP(B7,Res,16,0)+VLOOKUP(C7,Res,16,0)+VLOOKUP(D7,Res,16,0)+VLOOKUP(E7,Res,16,0) -> 6 | Q7: =VLOOKUP(B7,Res,17,0)+VLOOKUP(C7,Res,17,0)+VLOOKUP(D7,Res,17,0)+VLOOKUP(E7,Res,17,0) -> 14 | R7: =VLOOKUP(B7,Res,18,0)+VLOOKUP(C7,Res,18,0)+VLOOKUP(D7,Res,18,0)+VLOOKUP(F7,Res,18,0)+VLOOKUP(G7,Res,18,0)+VLOOKUP(I7,Res,18,0)+VLOOKUP(J7,Res,18,0) -> 6 | S7: =VLOOKUP(B7,Res,19,0)+VLOOKUP(C7,Res,19,0)+VLOOKUP(D7,Res,19,0)+VLOOKUP(F7,Res,19,0)+VLOOKUP(G7,Res,19,0)+VLOOKUP(I7,Res,19,0)+VLOOKUP(J7,Res,19,0) -> 0 | T7: =VLOOKUP(B7,Res,20,0)+VLOOKUP(C7,Res,20,0)+VLOOKUP(D7,Res,20,0)+VLOOKUP(F7,Res,20,0)+VLOOKUP(G7,Res,20,0)+VLOOKUP(I7,Res,20,0)+VLOOKUP(J7,Res,20,0) -> -12 | U7: =VLOOKUP(B7,Res,21,0)+VLOOKUP(C7,Res,21,0)+VLOOKUP(D7,Res,21,0)+VLOOKUP(F7,Res,21,0)+VLOOKUP(G7,Res,21,0)+VLOOKUP(I7,Res,21,0)+VLOOKUP(J7,Res,21,0) -> -24 | V7: =VLOOKUP(B7,Res,22,0)+VLOOKUP(C7,Res,22,0)+VLOOKUP(D7,Res,22,0)+VLOOKUP(F7,Res,22,0)+VLOOKUP(G7,Res,22,0)+VLOOKUP(I7,Res,22,0)+VLOOKUP(J7,Res,22,0) -> -39 | W7: =VLOOKUP(B7,Res,23,0)+VLOOKUP(C7,Res,23,0)+VLOOKUP(D7,Res,23,0)+VLOOKUP(F7,Res,23,0)+VLOOKUP(G7,Res,23,0)+VLOOKUP(I7,Res,23,0)+VLOOKUP(J7,Res,23,0) -> -55 | X7: =VLOOKUP(B7,Res,24,0)+VLOOKUP(C7,Res,24,0)+VLOOKUP(D7,Res,24,0)+VLOOKUP(G7,Res,24,0) -> 40 | Y7: =VLOOKUP(D7,Res,25,0)+VLOOKUP(E7,Res,25,0)+VLOOKUP(F7,Res,25,0) -> 30 | Z7: =VLOOKUP(E7,Res,26,0) -> 3 | AA7: =VLOOKUP(B7,Res,27,0)+VLOOKUP(D7,Res,27,0)+VLOOKUP(F7,Res,27,0)+VLOOKUP(I7,Res,27,0) -> 3 | AB7: =VLOOKUP(B7,Res,28,0)+VLOOKUP(C7,Res,28,0)+VLOOKUP(D7,Res,28,0)+VLOOKUP(E7,Res,28,0)+VLOOKUP(F7,Res,28,0)+VLOOKUP(G7,Res,28,0)+VLOOKUP(I7,Res,28,0)+VLOOKUP(J7,Res,28,0) -> 115 | AC7: =VLOOKUP(I7,Res,31,0)*AD7+AE7 -> 174.55 | AD7: =VLOOKUP(B7,Res,30,0)+VLOOKUP(C7,Res,30,0)+VLOOKUP(D7,Res,30,0)+VLOOKUP(F7,Res,30,0)+VLOOKUP(G7,Res,30,0)+VLOOKUP(I7,Res,30,0)+VLOOKUP(J7,Res,30,0) -> 4.5 | AE7: =(VLOOKUP(C7,Res,32,0)+VLOOKUP(I7,Res,32,0))*(VLOOKUP(B7,Res,34,0)+VLOOKUP(C7,Res,34,0)+VLOOKUP(D7,Res,34,0)+VLOOKUP(E7,Res,34,0)+VLOOKUP(G7,Res,34,0))+VLOOKUP(B7,Res,35,0)+VLOOKUP(C7,Res,35,0)+VLOOKUP(D7,Res,35,0) -> 156.55 | AF7: =VLOOKUP(AB7,verftab,2,1) -> 4
A8: Schalarr | B8: Drow | C8: Gewehr | D8: Karabiner | E8: Hinterlader | F8: Nadelzündung | G8: Glattlauf | H8: Papier Patrone | I8: Massenfabrikation | J8: Von der Stange | K8: =VLOOKUP(B8,Res,11,0)+VLOOKUP(C8,Res,11,0)+VLOOKUP(D8,Res,11,0)+VLOOKUP(E8,Res,11,0)+VLOOKUP(G8,Res,11,0) -> 4 | L8: =VLOOKUP(B8,Res,12,0)+VLOOKUP(C8,Res,12,0)+VLOOKUP(D8,Res,12,0)+VLOOKUP(J8,Res,12,0) -> 10 | M8: =VLOOKUP(VLOOKUP(B8,Res,13,0)+VLOOKUP(C8,Res,13,0)+VLOOKUP(D8,Res,13,0),wtab,2,0) -> W12 | N8: =VLOOKUP(VLOOKUP(B8,Res,14,0)+VLOOKUP(C8,Res,14,0)+VLOOKUP(D8,Res,14,0),wtab,2,0) -> W10 | O8: =VLOOKUP(B8,Res,15,0)+VLOOKUP(C8,Res,15,0)+VLOOKUP(D8,Res,15,0) -> 1 | P8: =VLOOKUP(B8,Res,16,0)+VLOOKUP(C8,Res,16,0)+VLOOKUP(D8,Res,16,0)+VLOOKUP(E8,Res,16,0) -> 11 | Q8: =VLOOKUP(B8,Res,17,0)+VLOOKUP(C8,Res,17,0)+VLOOKUP(D8,Res,17,0)+VLOOKUP(E8,Res,17,0) -> 18 | R8: =VLOOKUP(B8,Res,18,0)+VLOOKUP(C8,Res,18,0)+VLOOKUP(D8,Res,18,0)+VLOOKUP(F8,Res,18,0)+VLOOKUP(G8,Res,18,0)+VLOOKUP(I8,Res,18,0)+VLOOKUP(J8,Res,18,0) -> 9 | S8: =VLOOKUP(B8,Res,19,0)+VLOOKUP(C8,Res,19,0)+VLOOKUP(D8,Res,19,0)+VLOOKUP(F8,Res,19,0)+VLOOKUP(G8,Res,19,0)+VLOOKUP(I8,Res,19,0)+VLOOKUP(J8,Res,19,0) -> 1 | T8: =VLOOKUP(B8,Res,20,0)+VLOOKUP(C8,Res,20,0)+VLOOKUP(D8,Res,20,0)+VLOOKUP(F8,Res,20,0)+VLOOKUP(G8,Res,20,0)+VLOOKUP(I8,Res,20,0)+VLOOKUP(J8,Res,20,0) -> -7 | U8: =VLOOKUP(B8,Res,21,0)+VLOOKUP(C8,Res,21,0)+VLOOKUP(D8,Res,21,0)+VLOOKUP(F8,Res,21,0)+VLOOKUP(G8,Res,21,0)+VLOOKUP(I8,Res,21,0)+VLOOKUP(J8,Res,21,0) -> -15 | V8: =VLOOKUP(B8,Res,22,0)+VLOOKUP(C8,Res,22,0)+VLOOKUP(D8,Res,22,0)+VLOOKUP(F8,Res,22,0)+VLOOKUP(G8,Res,22,0)+VLOOKUP(I8,Res,22,0)+VLOOKUP(J8,Res,22,0) -> -25 | W8: =VLOOKUP(B8,Res,23,0)+VLOOKUP(C8,Res,23,0)+VLOOKUP(D8,Res,23,0)+VLOOKUP(F8,Res,23,0)+VLOOKUP(G8,Res,23,0)+VLOOKUP(I8,Res,23,0)+VLOOKUP(J8,Res,23,0) -> -36 | X8: =VLOOKUP(B8,Res,24,0)+VLOOKUP(C8,Res,24,0)+VLOOKUP(D8,Res,24,0)+VLOOKUP(G8,Res,24,0) -> 30 | Y8: =VLOOKUP(D8,Res,25,0)+VLOOKUP(E8,Res,25,0)+VLOOKUP(F8,Res,25,0) -> 11 | Z8: =VLOOKUP(E8,Res,26,0) -> 6 | AA8: =VLOOKUP(B8,Res,27,0)+VLOOKUP(D8,Res,27,0)+VLOOKUP(F8,Res,27,0)+VLOOKUP(I8,Res,27,0) -> -1 | AB8: =VLOOKUP(B8,Res,28,0)+VLOOKUP(C8,Res,28,0)+VLOOKUP(D8,Res,28,0)+VLOOKUP(E8,Res,28,0)+VLOOKUP(F8,Res,28,0)+VLOOKUP(G8,Res,28,0)+VLOOKUP(I8,Res,28,0)+VLOOKUP(J8,Res,28,0) -> 80 | AC8: =VLOOKUP(I8,Res,31,0)*AD8+AE8 -> 298.6 | AD8: =VLOOKUP(B8,Res,30,0)+VLOOKUP(C8,Res,30,0)+VLOOKUP(D8,Res,30,0)+VLOOKUP(F8,Res,30,0)+VLOOKUP(G8,Res,30,0)+VLOOKUP(I8,Res,30,0)+VLOOKUP(J8,Res,30,0) -> 8.2 | AE8: =(VLOOKUP(C8,Res,32,0)+VLOOKUP(I8,Res,32,0))*(VLOOKUP(B8,Res,34,0)+VLOOKUP(C8,Res,34,0)+VLOOKUP(D8,Res,34,0)+VLOOKUP(E8,Res,34,0)+VLOOKUP(G8,Res,34,0))+VLOOKUP(B8,Res,35,0)+VLOOKUP(C8,Res,35,0)+VLOOKUP(D8,Res,35,0) -> 265.8 | AF8: =VLOOKUP(AB8,verftab,2,1) -> 6
A9: Schapschu | B9: Drow | C9: Gewehr | D9: Karabiner | E9: Klapplauf | F9: Schlagbolzen | G9: Gezogen | H9: Messing Patrone | I9: Massenfabrikation | J9: Von der Stange | K9: =VLOOKUP(B9,Res,11,0)+VLOOKUP(C9,Res,11,0)+VLOOKUP(D9,Res,11,0)+VLOOKUP(E9,Res,11,0)+VLOOKUP(G9,Res,11,0) -> 4.15 | L9: =VLOOKUP(B9,Res,12,0)+VLOOKUP(C9,Res,12,0)+VLOOKUP(D9,Res,12,0)+VLOOKUP(J9,Res,12,0) -> 10 | M9: =VLOOKUP(VLOOKUP(B9,Res,13,0)+VLOOKUP(C9,Res,13,0)+VLOOKUP(D9,Res,13,0),wtab,2,0) -> W12 | N9: =VLOOKUP(VLOOKUP(B9,Res,14,0)+VLOOKUP(C9,Res,14,0)+VLOOKUP(D9,Res,14,0),wtab,2,0) -> W10 | O9: =VLOOKUP(B9,Res,15,0)+VLOOKUP(C9,Res,15,0)+VLOOKUP(D9,Res,15,0) -> 1 | P9: =VLOOKUP(B9,Res,16,0)+VLOOKUP(C9,Res,16,0)+VLOOKUP(D9,Res,16,0)+VLOOKUP(E9,Res,16,0) -> 17 | Q9: =VLOOKUP(B9,Res,17,0)+VLOOKUP(C9,Res,17,0)+VLOOKUP(D9,Res,17,0)+VLOOKUP(E9,Res,17,0) -> 12 | R9: =VLOOKUP(B9,Res,18,0)+VLOOKUP(C9,Res,18,0)+VLOOKUP(D9,Res,18,0)+VLOOKUP(F9,Res,18,0)+VLOOKUP(G9,Res,18,0)+VLOOKUP(I9,Res,18,0)+VLOOKUP(J9,Res,18,0) -> 11 | S9: =VLOOKUP(B9,Res,19,0)+VLOOKUP(C9,Res,19,0)+VLOOKUP(D9,Res,19,0)+VLOOKUP(F9,Res,19,0)+VLOOKUP(G9,Res,19,0)+VLOOKUP(I9,Res,19,0)+VLOOKUP(J9,Res,19,0) -> 4 | T9: =VLOOKUP(B9,Res,20,0)+VLOOKUP(C9,Res,20,0)+VLOOKUP(D9,Res,20,0)+VLOOKUP(F9,Res,20,0)+VLOOKUP(G9,Res,20,0)+VLOOKUP(I9,Res,20,0)+VLOOKUP(J9,Res,20,0) -> -4 | U9: =VLOOKUP(B9,Res,21,0)+VLOOKUP(C9,Res,21,0)+VLOOKUP(D9,Res,21,0)+VLOOKUP(F9,Res,21,0)+VLOOKUP(G9,Res,21,0)+VLOOKUP(I9,Res,21,0)+VLOOKUP(J9,Res,21,0) -> -13 | V9: =VLOOKUP(B9,Res,22,0)+VLOOKUP(C9,Res,22,0)+VLOOKUP(D9,Res,22,0)+VLOOKUP(F9,Res,22,0)+VLOOKUP(G9,Res,22,0)+VLOOKUP(I9,Res,22,0)+VLOOKUP(J9,Res,22,0) -> -24 | W9: =VLOOKUP(B9,Res,23,0)+VLOOKUP(C9,Res,23,0)+VLOOKUP(D9,Res,23,0)+VLOOKUP(F9,Res,23,0)+VLOOKUP(G9,Res,23,0)+VLOOKUP(I9,Res,23,0)+VLOOKUP(J9,Res,23,0) -> -35 | X9: =VLOOKUP(B9,Res,24,0)+VLOOKUP(C9,Res,24,0)+VLOOKUP(D9,Res,24,0)+VLOOKUP(G9,Res,24,0) -> 60 | Y9: =VLOOKUP(D9,Res,25,0)+VLOOKUP(E9,Res,25,0)+VLOOKUP(F9,Res,25,0) -> 9 | Z9: =VLOOKUP(E9,Res,26,0) -> 6 | AA9: =VLOOKUP(B9,Res,27,0)+VLOOKUP(D9,Res,27,0)+VLOOKUP(F9,Res,27,0)+VLOOKUP(I9,Res,27,0) -> -2 | AB9: =VLOOKUP(B9,Res,28,0)+VLOOKUP(C9,Res,28,0)+VLOOKUP(D9,Res,28,0)+VLOOKUP(E9,Res,28,0)+VLOOKUP(F9,Res,28,0)+VLOOKUP(G9,Res,28,0)+VLOOKUP(I9,Res,28,0)+VLOOKUP(J9,Res,28,0) -> 50 | AC9: =VLOOKUP(I9,Res,31,0)*AD9+AE9 -> 326.6 | AD9: =VLOOKUP(B9,Res,30,0)+VLOOKUP(C9,Res,30,0)+VLOOKUP(D9,Res,30,0)+VLOOKUP(F9,Res,30,0)+VLOOKUP(G9,Res,30,0)+VLOOKUP(I9,Res,30,0)+VLOOKUP(J9,Res,30,0) -> 10.7 | AE9: =(VLOOKUP(C9,Res,32,0)+VLOOKUP(I9,Res,32,0))*(VLOOKUP(B9,Res,34,0)+VLOOKUP(C9,Res,34,0)+VLOOKUP(D9,Res,34,0)+VLOOKUP(E9,Res,34,0)+VLOOKUP(G9,Res,34,0))+VLOOKUP(B9,Res,35,0)+VLOOKUP(C9,Res,35,0)+VLOOKUP(D9,Res,35,0) -> 283.8 | AF9: =VLOOKUP(AB9,verftab,2,1) -> 7
A10: Ssussun | B10: Drow | C10: Gewehr | D10: Normal | E10: Vorderlader | F10: Steinschloss | G10: Glattlauf | H10: Blei | I10: Massenfabrikation | J10: Von der Stange | K10: =VLOOKUP(B10,Res,11,0)+VLOOKUP(C10,Res,11,0)+VLOOKUP(D10,Res,11,0)+VLOOKUP(E10,Res,11,0)+VLOOKUP(G10,Res,11,0) -> 4.8 | L10: =VLOOKUP(B10,Res,12,0)+VLOOKUP(C10,Res,12,0)+VLOOKUP(D10,Res,12,0)+VLOOKUP(J10,Res,12,0) -> 11 | M10: =VLOOKUP(VLOOKUP(B10,Res,13,0)+VLOOKUP(C10,Res,13,0)+VLOOKUP(D10,Res,13,0),wtab,2,0) -> W12 | N10: =VLOOKUP(VLOOKUP(B10,Res,14,0)+VLOOKUP(C10,Res,14,0)+VLOOKUP(D10,Res,14,0),wtab,2,0) -> W10 | O10: =VLOOKUP(B10,Res,15,0)+VLOOKUP(C10,Res,15,0)+VLOOKUP(D10,Res,15,0) -> 1 | P10: =VLOOKUP(B10,Res,16,0)+VLOOKUP(C10,Res,16,0)+VLOOKUP(D10,Res,16,0)+VLOOKUP(E10,Res,16,0) -> 11 | Q10: =VLOOKUP(B10,Res,17,0)+VLOOKUP(C10,Res,17,0)+VLOOKUP(D10,Res,17,0)+VLOOKUP(E10,Res,17,0) -> 18 | R10: =VLOOKUP(B10,Res,18,0)+VLOOKUP(C10,Res,18,0)+VLOOKUP(D10,Res,18,0)+VLOOKUP(F10,Res,18,0)+VLOOKUP(G10,Res,18,0)+VLOOKUP(I10,Res,18,0)+VLOOKUP(J10,Res,18,0) -> 5 | S10: =VLOOKUP(B10,Res,19,0)+VLOOKUP(C10,Res,19,0)+VLOOKUP(D10,Res,19,0)+VLOOKUP(F10,Res,19,0)+VLOOKUP(G10,Res,19,0)+VLOOKUP(I10,Res,19,0)+VLOOKUP(J10,Res,19,0) -> -1 | T10: =VLOOKUP(B10,Res,20,0)+VLOOKUP(C10,Res,20,0)+VLOOKUP(D10,Res,20,0)+VLOOKUP(F10,Res,20,0)+VLOOKUP(G10,Res,20,0)+VLOOKUP(I10,Res,20,0)+VLOOKUP(J10,Res,20,0) -> -7 | U10: =VLOOKUP(B10,Res,21,0)+VLOOKUP(C10,Res,21,0)+VLOOKUP(D10,Res,21,0)+VLOOKUP(F10,Res,21,0)+VLOOKUP(G10,Res,21,0)+VLOOKUP(I10,Res,21,0)+VLOOKUP(J10,Res,21,0) -> -13 | V10: =VLOOKUP(B10,Res,22,0)+VLOOKUP(C10,Res,22,0)+VLOOKUP(D10,Res,22,0)+VLOOKUP(F10,Res,22,0)+VLOOKUP(G10,Res,22,0)+VLOOKUP(I10,Res,22,0)+VLOOKUP(J10,Res,22,0) -> -21 | W10: =VLOOKUP(B10,Res,23,0)+VLOOKUP(C10,Res,23,0)+VLOOKUP(D10,Res,23,0)+VLOOKUP(F10,Res,23,0)+VLOOKUP(G10,Res,23,0)+VLOOKUP(I10,Res,23,0)+VLOOKUP(J10,Res,23,0) -> -30 | X10: =VLOOKUP(B10,Res,24,0)+VLOOKUP(C10,Res,24,0)+VLOOKUP(D10,Res,24,0)+VLOOKUP(G10,Res,24,0) -> 40 | Y10: =VLOOKUP(D10,Res,25,0)+VLOOKUP(E10,Res,25,0)+VLOOKUP(F10,Res,25,0) -> 30 | Z10: =VLOOKUP(E10,Res,26,0) -> 3 | AA10: =VLOOKUP(B10,Res,27,0)+VLOOKUP(D10,Res,27,0)+VLOOKUP(F10,Res,27,0)+VLOOKUP(I10,Res,27,0) -> 1 | AB10: =VLOOKUP(B10,Res,28,0)+VLOOKUP(C10,Res,28,0)+VLOOKUP(D10,Res,28,0)+VLOOKUP(E10,Res,28,0)+VLOOKUP(F10,Res,28,0)+VLOOKUP(G10,Res,28,0)+VLOOKUP(I10,Res,28,0)+VLOOKUP(J10,Res,28,0) -> 120 | AC10: =VLOOKUP(I10,Res,31,0)*AD10+AE10 -> 374.7 | AD10: =VLOOKUP(B10,Res,30,0)+VLOOKUP(C10,Res,30,0)+VLOOKUP(D10,Res,30,0)+VLOOKUP(F10,Res,30,0)+VLOOKUP(G10,Res,30,0)+VLOOKUP(I10,Res,30,0)+VLOOKUP(J10,Res,30,0) -> 6.2 | AE10: =(VLOOKUP(C10,Res,32,0)+VLOOKUP(I10,Res,32,0))*(VLOOKUP(B10,Res,34,0)+VLOOKUP(C10,Res,34,0)+VLOOKUP(D10,Res,34,0)+VLOOKUP(E10,Res,34,0)+VLOOKUP(G10,Res,34,0))+VLOOKUP(B10,Res,35,0)+VLOOKUP(C10,Res,35,0)+VLOOKUP(D10,Res,35,0) -> 349.9 | AF10: =VLOOKUP(AB10,verftab,2,1) -> 4
A11: Wissperr | B11: Drow | C11: Gewehr | D11: Normal | E11: Hinterlader | F11: Nadelzündung | G11: Glattlauf | H11: Papier Patrone | I11: Massenfabrikation | J11: Von der Stange | K11: =VLOOKUP(B11,Res,11,0)+VLOOKUP(C11,Res,11,0)+VLOOKUP(D11,Res,11,0)+VLOOKUP(E11,Res,11,0)+VLOOKUP(G11,Res,11,0) -> 4.9 | L11: =VLOOKUP(B11,Res,12,0)+VLOOKUP(C11,Res,12,0)+VLOOKUP(D11,Res,12,0)+VLOOKUP(J11,Res,12,0) -> 11 | M11: =VLOOKUP(VLOOKUP(B11,Res,13,0)+VLOOKUP(C11,Res,13,0)+VLOOKUP(D11,Res,13,0),wtab,2,0) -> W12 | N11: =VLOOKUP(VLOOKUP(B11,Res,14,0)+VLOOKUP(C11,Res,14,0)+VLOOKUP(D11,Res,14,0),wtab,2,0) -> W10 | O11: =VLOOKUP(B11,Res,15,0)+VLOOKUP(C11,Res,15,0)+VLOOKUP(D11,Res,15,0) -> 1 | P11: =VLOOKUP(B11,Res,16,0)+VLOOKUP(C11,Res,16,0)+VLOOKUP(D11,Res,16,0)+VLOOKUP(E11,Res,16,0) -> 11 | Q11: =VLOOKUP(B11,Res,17,0)+VLOOKUP(C11,Res,17,0)+VLOOKUP(D11,Res,17,0)+VLOOKUP(E11,Res,17,0) -> 18 | R11: =VLOOKUP(B11,Res,18,0)+VLOOKUP(C11,Res,18,0)+VLOOKUP(D11,Res,18,0)+VLOOKUP(F11,Res,18,0)+VLOOKUP(G11,Res,18,0)+VLOOKUP(I11,Res,18,0)+VLOOKUP(J11,Res,18,0) -> 7 | S11: =VLOOKUP(B11,Res,19,0)+VLOOKUP(C11,Res,19,0)+VLOOKUP(D11,Res,19,0)+VLOOKUP(F11,Res,19,0)+VLOOKUP(G11,Res,19,0)+VLOOKUP(I11,Res,19,0)+VLOOKUP(J11,Res,19,0) -> 1 | T11: =VLOOKUP(B11,Res,20,0)+VLOOKUP(C11,Res,20,0)+VLOOKUP(D11,Res,20,0)+VLOOKUP(F11,Res,20,0)+VLOOKUP(G11,Res,20,0)+VLOOKUP(I11,Res,20,0)+VLOOKUP(J11,Res,20,0) -> -5 | U11: =VLOOKUP(B11,Res,21,0)+VLOOKUP(C11,Res,21,0)+VLOOKUP(D11,Res,21,0)+VLOOKUP(F11,Res,21,0)+VLOOKUP(G11,Res,21,0)+VLOOKUP(I11,Res,21,0)+VLOOKUP(J11,Res,21,0) -> -11 | V11: =VLOOKUP(B11,Res,22,0)+VLOOKUP(C11,Res,22,0)+VLOOKUP(D11,Res,22,0)+VLOOKUP(F11,Res,22,0)+VLOOKUP(G11,Res,22,0)+VLOOKUP(I11,Res,22,0)+VLOOKUP(J11,Res,22,0) -> -19 | W11: =VLOOKUP(B11,Res,23,0)+VLOOKUP(C11,Res,23,0)+VLOOKUP(D11,Res,23,0)+VLOOKUP(F11,Res,23,0)+VLOOKUP(G11,Res,23,0)+VLOOKUP(I11,Res,23,0)+VLOOKUP(J11,Res,23,0) -> -28 | X11: =VLOOKUP(B11,Res,24,0)+VLOOKUP(C11,Res,24,0)+VLOOKUP(D11,Res,24,0)+VLOOKUP(G11,Res,24,0) -> 40 | Y11: =VLOOKUP(D11,Res,25,0)+VLOOKUP(E11,Res,25,0)+VLOOKUP(F11,Res,25,0) -> 11 | Z11: =VLOOKUP(E11,Res,26,0) -> 6 | AA11: =VLOOKUP(B11,Res,27,0)+VLOOKUP(D11,Res,27,0)+VLOOKUP(F11,Res,27,0)+VLOOKUP(I11,Res,27,0) -> -1 | AB11: =VLOOKUP(B11,Res,28,0)+VLOOKUP(C11,Res,28,0)+VLOOKUP(D11,Res,28,0)+VLOOKUP(E11,Res,28,0)+VLOOKUP(F11,Res,28,0)+VLOOKUP(G11,Res,28,0)+VLOOKUP(I11,Res,28,0)+VLOOKUP(J11,Res,28,0) -> 100 | AC11: =VLOOKUP(I11,Res,31,0)*AD11+AE11 -> 394.7 | AD11: =VLOOKUP(B11,Res,30,0)+VLOOKUP(C11,Res,30,0)+VLOOKUP(D11,Res,30,0)+VLOOKUP(F11,Res,30,0)+VLOOKUP(G11,Res,30,0)+VLOOKUP(I11,Res,30,0)+VLOOKUP(J11,Res,30,0) -> 8.2 | AE11: =(VLOOKUP(C11,Res,32,0)+VLOOKUP(I11,Res,32,0))*(VLOOKUP(B11,Res,34,0)+VLOOKUP(C11,Res,34,0)+VLOOKUP(D11,Res,34,0)+VLOOKUP(E11,Res,34,0)+VLOOKUP(G11,Res,34,0))+VLOOKUP(B11,Res,35,0)+VLOOKUP(C11,Res,35,0)+VLOOKUP(D11,Res,35,0) -> 361.9 | AF11: =VLOOKUP(AB11,verftab,2,1) -> 5
A12: Dunar | B12: Drow | C12: Pistole | D12: Normal P | E12: Klapplauf | F12: Schlagbolzen | G12: Gezogen | H12: Messing Patrone | I12: Massenfabrikation | J12: Von der Stange | K12: =VLOOKUP(B12,Res,11,0)+VLOOKUP(C12,Res,11,0)+VLOOKUP(D12,Res,11,0)+VLOOKUP(E12,Res,11,0)+VLOOKUP(G12,Res,11,0) -> 2.8 | L12: =VLOOKUP(B12,Res,12,0)+VLOOKUP(C12,Res,12,0)+VLOOKUP(D12,Res,12,0)+VLOOKUP(J12,Res,12,0) -> 8 | M12: =VLOOKUP(VLOOKUP(B12,Res,13,0)+VLOOKUP(C12,Res,13,0)+VLOOKUP(D12,Res,13,0),wtab,2,0) -> W12 | N12: =VLOOKUP(VLOOKUP(B12,Res,14,0)+VLOOKUP(C12,Res,14,0)+VLOOKUP(D12,Res,14,0),wtab,2,0) -> W10 | O12: =VLOOKUP(B12,Res,15,0)+VLOOKUP(C12,Res,15,0)+VLOOKUP(D12,Res,15,0) -> 0 | P12: =VLOOKUP(B12,Res,16,0)+VLOOKUP(C12,Res,16,0)+VLOOKUP(D12,Res,16,0)+VLOOKUP(E12,Res,16,0) -> 12 | Q12: =VLOOKUP(B12,Res,17,0)+VLOOKUP(C12,Res,17,0)+VLOOKUP(D12,Res,17,0)+VLOOKUP(E12,Res,17,0) -> 9 | R12: =VLOOKUP(B12,Res,18,0)+VLOOKUP(C12,Res,18,0)+VLOOKUP(D12,Res,18,0)+VLOOKUP(F12,Res,18,0)+VLOOKUP(G12,Res,18,0)+VLOOKUP(I12,Res,18,0)+VLOOKUP(J12,Res,18,0) -> 12 | S12: =VLOOKUP(B12,Res,19,0)+VLOOKUP(C12,Res,19,0)+VLOOKUP(D12,Res,19,0)+VLOOKUP(F12,Res,19,0)+VLOOKUP(G12,Res,19,0)+VLOOKUP(I12,Res,19,0)+VLOOKUP(J12,Res,19,0) -> 4 | T12: =VLOOKUP(B12,Res,20,0)+VLOOKUP(C12,Res,20,0)+VLOOKUP(D12,Res,20,0)+VLOOKUP(F12,Res,20,0)+VLOOKUP(G12,Res,20,0)+VLOOKUP(I12,Res,20,0)+VLOOKUP(J12,Res,20,0) -> -7 | U12: =VLOOKUP(B12,Res,21,0)+VLOOKUP(C12,Res,21,0)+VLOOKUP(D12,Res,21,0)+VLOOKUP(F12,Res,21,0)+VLOOKUP(G12,Res,21,0)+VLOOKUP(I12,Res,21,0)+VLOOKUP(J12,Res,21,0) -> -20 | V12: =VLOOKUP(B12,Res,22,0)+VLOOKUP(C12,Res,22,0)+VLOOKUP(D12,Res,22,0)+VLOOKUP(F12,Res,22,0)+VLOOKUP(G12,Res,22,0)+VLOOKUP(I12,Res,22,0)+VLOOKUP(J12,Res,22,0) -> -36 | W12: =VLOOKUP(B12,Res,23,0)+VLOOKUP(C12,Res,23,0)+VLOOKUP(D12,Res,23,0)+VLOOKUP(F12,Res,23,0)+VLOOKUP(G12,Res,23,0)+VLOOKUP(I12,Res,23,0)+VLOOKUP(J12,Res,23,0) -> -53 | X12: =VLOOKUP(B12,Res,24,0)+VLOOKUP(C12,Res,24,0)+VLOOKUP(D12,Res,24,0)+VLOOKUP(G12,Res,24,0) -> 60 | Y12: =VLOOKUP(D12,Res,25,0)+VLOOKUP(E12,Res,25,0)+VLOOKUP(F12,Res,25,0) -> 9 | Z12: =VLOOKUP(E12,Res,26,0) -> 6 | AA12: =VLOOKUP(B12,Res,27,0)+VLOOKUP(D12,Res,27,0)+VLOOKUP(F12,Res,27,0)+VLOOKUP(I12,Res,27,0) -> -2 | AB12: =VLOOKUP(B12,Res,28,0)+VLOOKUP(C12,Res,28,0)+VLOOKUP(D12,Res,28,0)+VLOOKUP(E12,Res,28,0)+VLOOKUP(F12,Res,28,0)+VLOOKUP(G12,Res,28,0)+VLOOKUP(I12,Res,28,0)+VLOOKUP(J12,Res,28,0) -> 70 | AC12: =VLOOKUP(I12,Res,31,0)*AD12+AE12 -> 312.55 | AD12: =VLOOKUP(B12,Res,30,0)+VLOOKUP(C12,Res,30,0)+VLOOKUP(D12,Res,30,0)+VLOOKUP(F12,Res,30,0)+VLOOKUP(G12,Res,30,0)+VLOOKUP(I12,Res,30,0)+VLOOKUP(J12,Res,30,0) -> 10.5 | AE12: =(VLOOKUP(C12,Res,32,0)+VLOOKUP(I12,Res,32,0))*(VLOOKUP(B12,Res,34,0)+VLOOKUP(C12,Res,34,0)+VLOOKUP(D12,Res,34,0)+VLOOKUP(E12,Res,34,0)+VLOOKUP(G12,Res,34,0))+VLOOKUP(B12,Res,35,0)+VLOOKUP(C12,Res,35,0)+VLOOKUP(D12,Res,35,0) -> 270.55 | AF12: =VLOOKUP(AB12,verftab,2,1) -> 6
A13: Schatten | B13: Drow | C13: Pistole | D13: Schwer P | E13: Klapplauf | F13: Schlagbolzen | G13: Gezogen | H13: Messing Patrone | I13: Massenfabrikation | J13: Von der Stange | K13: =VLOOKUP(B13,Res,11,0)+VLOOKUP(C13,Res,11,0)+VLOOKUP(D13,Res,11,0)+VLOOKUP(E13,Res,11,0)+VLOOKUP(G13,Res,11,0) -> 3.3 | L13: =VLOOKUP(B13,Res,12,0)+VLOOKUP(C13,Res,12,0)+VLOOKUP(D13,Res,12,0)+VLOOKUP(J13,Res,12,0) -> 10 | M13: =VLOOKUP(VLOOKUP(B13,Res,13,0)+VLOOKUP(C13,Res,13,0)+VLOOKUP(D13,Res,13,0),wtab,2,0) -> W15 | N13: =VLOOKUP(VLOOKUP(B13,Res,14,0)+VLOOKUP(C13,Res,14,0)+VLOOKUP(D13,Res,14,0),wtab,2,0) -> W12 | O13: =VLOOKUP(B13,Res,15,0)+VLOOKUP(C13,Res,15,0)+VLOOKUP(D13,Res,15,0) -> 1 | P13: =VLOOKUP(B13,Res,16,0)+VLOOKUP(C13,Res,16,0)+VLOOKUP(D13,Res,16,0)+VLOOKUP(E13,Res,16,0) -> 13 | Q13: =VLOOKUP(B13,Res,17,0)+VLOOKUP(C13,Res,17,0)+VLOOKUP(D13,Res,17,0)+VLOOKUP(E13,Res,17,0) -> 10 | R13: =VLOOKUP(B13,Res,18,0)+VLOOKUP(C13,Res,18,0)+VLOOKUP(D13,Res,18,0)+VLOOKUP(F13,Res,18,0)+VLOOKUP(G13,Res,18,0)+VLOOKUP(I13,Res,18,0)+VLOOKUP(J13,Res,18,0) -> 10 | S13: =VLOOKUP(B13,Res,19,0)+VLOOKUP(C13,Res,19,0)+VLOOKUP(D13,Res,19,0)+VLOOKUP(F13,Res,19,0)+VLOOKUP(G13,Res,19,0)+VLOOKUP(I13,Res,19,0)+VLOOKUP(J13,Res,19,0) -> 3 | T13: =VLOOKUP(B13,Res,20,0)+VLOOKUP(C13,Res,20,0)+VLOOKUP(D13,Res,20,0)+VLOOKUP(F13,Res,20,0)+VLOOKUP(G13,Res,20,0)+VLOOKUP(I13,Res,20,0)+VLOOKUP(J13,Res,20,0) -> -7 | U13: =VLOOKUP(B13,Res,21,0)+VLOOKUP(C13,Res,21,0)+VLOOKUP(D13,Res,21,0)+VLOOKUP(F13,Res,21,0)+VLOOKUP(G13,Res,21,0)+VLOOKUP(I13,Res,21,0)+VLOOKUP(J13,Res,21,0) -> -20 | V13: =VLOOKUP(B13,Res,22,0)+VLOOKUP(C13,Res,22,0)+VLOOKUP(D13,Res,22,0)+VLOOKUP(F13,Res,22,0)+VLOOKUP(G13,Res,22,0)+VLOOKUP(I13,Res,22,0)+VLOOKUP(J13,Res,22,0) -> -36 | W13: =VLOOKUP(B13,Res,23,0)+VLOOKUP(C13,Res,23,0)+VLOOKUP(D13,Res,23,0)+VLOOKUP(F13,Res,23,0)+VLOOKUP(G13,Res,23,0)+VLOOKUP(I13,Res,23,0)+VLOOKUP(J13,Res,23,0) -> -53 | X13: =VLOOKUP(B13,Res,24,0)+VLOOKUP(C13,Res,24,0)+VLOOKUP(D13,Res,24,0)+VLOOKUP(G13,Res,24,0) -> 80 | Y13: =VLOOKUP(D13,Res,25,0)+VLOOKUP(E13,Res,25,0)+VLOOKUP(F13,Res,25,0) -> 11 | Z13: =VLOOKUP(E13,Res,26,0) -> 6 | AA13: =VLOOKUP(B13,Res,27,0)+VLOOKUP(D13,Res,27,0)+VLOOKUP(F13,Res,27,0)+VLOOKUP(I13,Res,27,0) -> -2 | AB13: =VLOOKUP(B13,Res,28,0)+VLOOKUP(C13,Res,28,0)+VLOOKUP(D13,Res,28,0)+VLOOKUP(E13,Res,28,0)+VLOOKUP(F13,Res,28,0)+VLOOKUP(G13,Res,28,0)+VLOOKUP(I13,Res,28,0)+VLOOKUP(J13,Res,28,0) -> 60 | AC13: =VLOOKUP(I13,Res,31,0)*AD13+AE13 -> 374.55 | AD13: =VLOOKUP(B13,Res,30,0)+VLOOKUP(C13,Res,30,0)+VLOOKUP(D13,Res,30,0)+VLOOKUP(F13,Res,30,0)+VLOOKUP(G13,Res,30,0)+VLOOKUP(I13,Res,30,0)+VLOOKUP(J13,Res,30,0) -> 11 | AE13: =(VLOOKUP(C13,Res,32,0)+VLOOKUP(I13,Res,32,0))*(VLOOKUP(B13,Res,34,0)+VLOOKUP(C13,Res,34,0)+VLOOKUP(D13,Res,34,0)+VLOOKUP(E13,Res,34,0)+VLOOKUP(G13,Res,34,0))+VLOOKUP(B13,Res,35,0)+VLOOKUP(C13,Res,35,0)+VLOOKUP(D13,Res,35,0) -> 330.55 | AF13: =VLOOKUP(AB13,verftab,2,1) -> 7
... A87: Wyrm | B87: Zwergisch | C87: Pistole | D87: Normal P | E87: Vorderlader | F87: Steinschloss | G87: Glattlauf | H87: Blei | I87: Massenfabrikation | J87: Von der Stange | K87: =VLOOKUP(B87,Res,11,0)+VLOOKUP(C87,Res,11,0)+VLOOKUP(D87,Res,11,0)+VLOOKUP(E87,Res,11,0)+VLOOKUP(G87,Res,11,0) -> 2.55 | L87: =VLOOKUP(B87,Res,12,0)+VLOOKUP(C87,Res,12,0)+VLOOKUP(D87,Res,12,0)+VLOOKUP(J87,Res,12,0) -> 8 | M87: =VLOOKUP(VLOOKUP(B87,Res,13,0)+VLOOKUP(C87,Res,13,0)+VLOOKUP(D87,Res,13,0),wtab,2,0) -> W10 | N87: =VLOOKUP(VLOOKUP(B87,Res,14,0)+VLOOKUP(C87,Res,14,0)+VLOOKUP(D87,Res,14,0),wtab,2,0) -> W10 | O87: =VLOOKUP(B87,Res,15,0)+VLOOKUP(C87,Res,15,0)+VLOOKUP(D87,Res,15,0) -> 0 | P87: =VLOOKUP(B87,Res,16,0)+VLOOKUP(C87,Res,16,0)+VLOOKUP(D87,Res,16,0)+VLOOKUP(E87,Res,16,0) -> 8 | Q87: =VLOOKUP(B87,Res,17,0)+VLOOKUP(C87,Res,17,0)+VLOOKUP(D87,Res,17,0)+VLOOKUP(E87,Res,17,0) -> 14 | R87: =VLOOKUP(B87,Res,18,0)+VLOOKUP(C87,Res,18,0)+VLOOKUP(D87,Res,18,0)+VLOOKUP(F87,Res,18,0)+VLOOKUP(G87,Res,18,0)+VLOOKUP(I87,Res,18,0)+VLOOKUP(J87,Res,18,0) -> 7 | S87: =VLOOKUP(B87,Res,19,0)+VLOOKUP(C87,Res,19,0)+VLOOKUP(D87,Res,19,0)+VLOOKUP(F87,Res,19,0)+VLOOKUP(G87,Res,19,0)+VLOOKUP(I87,Res,19,0)+VLOOKUP(J87,Res,19,0) -> -1 | T87: =VLOOKUP(B87,Res,20,0)+VLOOKUP(C87,Res,20,0)+VLOOKUP(D87,Res,20,0)+VLOOKUP(F87,Res,20,0)+VLOOKUP(G87,Res,20,0)+VLOOKUP(I87,Res,20,0)+VLOOKUP(J87,Res,20,0) -> -11 | U87: =VLOOKUP(B87,Res,21,0)+VLOOKUP(C87,Res,21,0)+VLOOKUP(D87,Res,21,0)+VLOOKUP(F87,Res,21,0)+VLOOKUP(G87,Res,21,0)+VLOOKUP(I87,Res,21,0)+VLOOKUP(J87,Res,21,0) -> -23 | V87: =VLOOKUP(B87,Res,22,0)+VLOOKUP(C87,Res,22,0)+VLOOKUP(D87,Res,22,0)+VLOOKUP(F87,Res,22,0)+VLOOKUP(G87,Res,22,0)+VLOOKUP(I87,Res,22,0)+VLOOKUP(J87,Res,22,0) -> -37 | W87: =VLOOKUP(B87,Res,23,0)+VLOOKUP(C87,Res,23,0)+VLOOKUP(D87,Res,23,0)+VLOOKUP(F87,Res,23,0)+VLOOKUP(G87,Res,23,0)+VLOOKUP(I87,Res,23,0)+VLOOKUP(J87,Res,23,0) -> -53 | X87: =VLOOKUP(B87,Res,24,0)+VLOOKUP(C87,Res,24,0)+VLOOKUP(D87,Res,24,0)+VLOOKUP(G87,Res,24,0) -> 30 | Y87: =VLOOKUP(D87,Res,25,0)+VLOOKUP(E87,Res,25,0)+VLOOKUP(F87,Res,25,0) -> 30 | Z87: =VLOOKUP(E87,Res,26,0) -> 3 | AA87: =VLOOKUP(B87,Res,27,0)+VLOOKUP(D87,Res,27,0)+VLOOKUP(F87,Res,27,0)+VLOOKUP(I87,Res,27,0) -> -2 | AB87: =VLOOKUP(B87,Res,28,0)+VLOOKUP(C87,Res,28,0)+VLOOKUP(D87,Res,28,0)+VLOOKUP(E87,Res,28,0)+VLOOKUP(F87,Res,28,0)+VLOOKUP(G87,Res,28,0)+VLOOKUP(I87,Res,28,0)+VLOOKUP(J87,Res,28,0) -> 140 | AC87: =VLOOKUP(I87,Res,31,0)*AD87+AE87 -> 268.55 | AD87: =VLOOKUP(B87,Res,30,0)+VLOOKUP(C87,Res,30,0)+VLOOKUP(D87,Res,30,0)+VLOOKUP(F87,Res,30,0)+VLOOKUP(G87,Res,30,0)+VLOOKUP(I87,Res,30,0)+VLOOKUP(J87,Res,30,0) -> 7 | AE87: =(VLOOKUP(C87,Res,32,0)+VLOOKUP(I87,Res,32,0))*(VLOOKUP(B87,Res,34,0)+VLOOKUP(C87,Res,34,0)+VLOOKUP(D87,Res,34,0)+VLOOKUP(E87,Res,34,0)+VLOOKUP(G87,Res,34,0))+VLOOKUP(B87,Res,35,0)+VLOOKUP(C87,Res,35,0)+VLOOKUP(D87,Res,35,0) -> 240.55 | AF87: =VLOOKUP(AB87,verftab,2,1) -> 3

Sheet Munition
A1: Geeignet für | B1: Art | C1: Kaliber | D1: Preis (1Schuss) | E1: Preis (10 Schuss) | F1: Preis (50 Schuss) | G1: Preis (100 Schuss) | H1: Preis (500 Schuss) | I1: Preis (1.000 Schuss) | J1: Besonderheiten
A2: Vorderlader | B2: S.P.&Blei | C2: 12 | D2: ='Ressourcen-Munition'!D23 -> 0.366912 | E2: ='Ressourcen-Munition'!E23 -> 3.66912 | F2: ='Ressourcen-Munition'!F23 -> 18.3456 | G2: ='Ressourcen-Munition'!G23 -> 36.6912 | H2: ='Ressourcen-Munition'!H23 -> 183.456 | I2: ='Ressourcen-Munition'!I23 -> 366.912
A3: Vorderlader | B3: S.P.&Blei | C3: 13 | D3: ='Ressourcen-Munition'!D24 -> 0.374556 | E3: ='Ressourcen-Munition'!E24 -> 3.74556 | F3: ='Ressourcen-Munition'!F24 -> 18.7278 | G3: ='Ressourcen-Munition'!G24 -> 37.4556 | H3: ='Ressourcen-Munition'!H24 -> 187.278 | I3: ='Ressourcen-Munition'!I24 -> 374.556
A4: Vorderlader | B4: S.P.&Blei | C4: 14 | D4: ='Ressourcen-Munition'!D25 -> 0.3822 | E4: ='Ressourcen-Munition'!E25 -> 3.822 | F4: ='Ressourcen-Munition'!F25 -> 19.11 | G4: ='Ressourcen-Munition'!G25 -> 38.22 | H4: ='Ressourcen-Munition'!H25 -> 191.1 | I4: ='Ressourcen-Munition'!I25 -> 382.2
A5: Vorderlader | B5: S.P.&Blei | C5: 15 | D5: ='Ressourcen-Munition'!D26 -> 0.389844 | E5: ='Ressourcen-Munition'!E26 -> 3.89844 | F5: ='Ressourcen-Munition'!F26 -> 19.4922 | G5: ='Ressourcen-Munition'!G26 -> 38.9844 | H5: ='Ressourcen-Munition'!H26 -> 194.922 | I5: ='Ressourcen-Munition'!I26 -> 389.844
A6: Vorderlader | B6: S.P.&Blei | C6: 16 | D6: ='Ressourcen-Munition'!D27 -> 0.397488 | E6: ='Ressourcen-Munition'!E27 -> 3.97488 | F6: ='Ressourcen-Munition'!F27 -> 19.8744 | G6: ='Ressourcen-Munition'!G27 -> 39.7488 | H6: ='Ressourcen-Munition'!H27 -> 198.744 | I6: ='Ressourcen-Munition'!I27 -> 397.488
A7: Vorderlader | B7: S.P.&Blei | C7: 17 | D7: ='Ressourcen-Munition'!D28 -> 0.405132 | E7: ='Ressourcen-Munition'!E28 -> 4.05132 | F7: ='Ressourcen-Munition'!F28 -> 20.2566 | G7: ='Ressourcen-Munition'!G28 -> 40.5132 | H7: ='Ressourcen-Munition'!H28 -> 202.566 | I7: ='Ressourcen-Munition'!I28 -> 405.132
A8: Vorderlader | B8: S.P.&Blei | C8: 18 | D8: ='Ressourcen-Munition'!D29 -> 0.412776 | E8: ='Ressourcen-Munition'!E29 -> 4.12776 | F8: ='Ressourcen-Munition'!F29 -> 20.6388 | G8: ='Ressourcen-Munition'!G29 -> 41.2776 | H8: ='Ressourcen-Munition'!H29 -> 206.388 | I8: ='Ressourcen-Munition'!I29 -> 412.776
A9: Vorderlader | B9: S.P.&Blei | C9: 19 | D9: ='Ressourcen-Munition'!D30 -> 0.42042 | E9: ='Ressourcen-Munition'!E30 -> 4.2042 | F9: ='Ressourcen-Munition'!F30 -> 21.021 | G9: ='Ressourcen-Munition'!G30 -> 42.042 | H9: ='Ressourcen-Munition'!H30 -> 210.21 | I9: ='Ressourcen-Munition'!I30 -> 420.42
A10: Vorderlader | B10: S.P.&Blei | C10: 20 | D10: ='Ressourcen-Munition'!D31 -> 0.428064 | E10: ='Ressourcen-Munition'!E31 -> 4.28064 | F10: ='Ressourcen-Munition'!F31 -> 21.4032 | G10: ='Ressourcen-Munition'!G31 -> 42.8064 | H10: ='Ressourcen-Munition'!H31 -> 214.032 | I10: ='Ressourcen-Munition'!I31 -> 428.064
A11: Vorderlader | B11: S.P.&Blei | C11: 21 | D11: ='Ressourcen-Munition'!D32 -> 0.435708 | E11: ='Ressourcen-Munition'!E32 -> 4.35708 | F11: ='Ressourcen-Munition'!F32 -> 21.7854 | G11: ='Ressourcen-Munition'!G32 -> 43.5708 | H11: ='Ressourcen-Munition'!H32 -> 217.854 | I11: ='Ressourcen-Munition'!I32 -> 435.708
A12: Vorderlader | B12: S.P.&Blei | C12: 22 | D12: ='Ressourcen-Munition'!D33 -> 0.443352 | E12: ='Ressourcen-Munition'!E33 -> 4.43352 | F12: ='Ressourcen-Munition'!F33 -> 22.1676 | G12: ='Ressourcen-Munition'!G33 -> 44.3352 | H12: ='Ressourcen-Munition'!H33 -> 221.676 | I12: ='Ressourcen-Munition'!I33 -> 443.352
A13: Vorderlader | B13: S.P.&Blei | C13: 23 | D13: ='Ressourcen-Munition'!D34 -> 0.450996 | E13: ='Ressourcen-Munition'!E34 -> 4.50996 | F13: ='Ressourcen-Munition'!F34 -> 22.5498 | G13: ='Ressourcen-Munition'!G34 -> 45.0996 | H13: ='Ressourcen-Munition'!H34 -> 225.498 | I13: ='Ressourcen-Munition'!I34 -> 450.996
A14: Vorderlader | B14: VL. Papierpatrone | C14: 12 | D14: ='Ressourcen-Munition'!D35 -> 0.408855 | E14: ='Ressourcen-Munition'!E35 -> 4.08855 | F14: ='Ressourcen-Munition'!F35 -> 20.44275 | G14: ='Ressourcen-Munition'!G35 -> 40.8855 | H14: ='Ressourcen-Munition'!H35 -> 204.4275 | I14: ='Ressourcen-Munition'!I35 -> 408.855 | J14: Reduziert die Nachladezeit um 5 Sekunden
A15: Vorderlader | B15: VL. Papierpatrone | C15: 13 | D15: ='Ressourcen-Munition'!D36 -> 0.4151775 | E15: ='Ressourcen-Munition'!E36 -> 4.151775 | F15: ='Ressourcen-Munition'!F36 -> 20.758875 | G15: ='Ressourcen-Munition'!G36 -> 41.51775 | H15: ='Ressourcen-Munition'!H36 -> 207.58875 | I15: ='Ressourcen-Munition'!I36 -> 415.1775 | J15: Reduziert die Nachladezeit um 5 Sekunden
A16: Vorderlader | B16: VL. Papierpatrone | C16: 14 | D16: ='Ressourcen-Munition'!D37 -> 0.4215 | E16: ='Ressourcen-Munition'!E37 -> 4.215 | F16: ='Ressourcen-Munition'!F37 -> 21.075 | G16: ='Ressourcen-Munition'!G37 -> 42.15 | H16: ='Ressourcen-Munition'!H37 -> 210.75 | I16: ='Ressourcen-Munition'!I37 -> 421.5 | J16: Reduziert die Nachladezeit um 5 Sekunden
A17: Vorderlader | B17: VL. Papierpatrone | C17: 15 | D17: ='Ressourcen-Munition'!D38 -> 0.4278225 | E17: ='Ressourcen-Munition'!E38 -> 4.278225 | F17: ='Ressourcen-Munition'!F38 -> 21.391125 | G17: ='Ressourcen-Munition'!G38 -> 42.78225 | H17: ='Ressourcen-Munition'!H38 -> 213.91125 | I17: ='Ressourcen-Munition'!I38 -> 427.8225 | J17: Reduziert die Nachladezeit um 5 Sekunden
A18: Vorderlader | B18: VL. Papierpatrone | C18: 16 | D18: ='Ressourcen-Munition'!D39 -> 0.434145 | E18: ='Ressourcen-Munition'!E39 -> 4.34145 | F18: ='Ressourcen-Munition'!F39 -> 21.70725 | G18: ='Ressourcen-Munition'!G39 -> 43.4145 | H18: ='Ressourcen-Munition'!H39 -> 217.0725 | I18: ='Ressourcen-Munition'!I39 -> 434.145 | J18: Reduziert die Nachladezeit um 5 Sekunden
A19: Vorderlader | B19: VL. Papierpatrone | C19: 17 | D19: ='Ressourcen-Munition'!D40 -> 0.4404675 | E19: ='Ressourcen-Munition'!E40 -> 4.404675 | F19: ='Ressourcen-Munition'!F40 -> 22.023375 | G19: ='Ressourcen-Munition'!G40 -> 44.04675 | H19: ='Ressourcen-Munition'!H40 -> 220.23375 | I19: ='Ressourcen-Munition'!I40 -> 440.4675 | J19: Reduziert die Nachladezeit um 5 Sekunden
A20: Vorderlader | B20: VL. Papierpatrone | C20: 18 | D20: ='Ressourcen-Munition'!D41 -> 0.44679 | E20: ='Ressourcen-Munition'!E41 -> 4.4679 | F20: ='Ressourcen-Munition'!F41 -> 22.3395 | G20: ='Ressourcen-Munition'!G41 -> 44.679 | H20: ='Ressourcen-Munition'!H41 -> 223.395 | I20: ='Ressourcen-Munition'!I41 -> 446.79 | J20: Reduziert die Nachladezeit um 5 Sekunden
A21: Vorderlader | B21: VL. Papierpatrone | C21: 19 | D21: ='Ressourcen-Munition'!D42 -> 0.4531125 | E21: ='Ressourcen-Munition'!E42 -> 4.531125 | F21: ='Ressourcen-Munition'!F42 -> 22.655625 | G21: ='Ressourcen-Munition'!G42 -> 45.31125 | H21: ='Ressourcen-Munition'!H42 -> 226.55625 | I21: ='Ressourcen-Munition'!I42 -> 453.1125 | J21: Reduziert die Nachladezeit um 5 Sekunden
A22: Vorderlader | B22: VL. Papierpatrone | C22: 20 | D22: ='Ressourcen-Munition'!D43 -> 0.459435 | E22: ='Ressourcen-Munition'!E43 -> 4.59435 | F22: ='Ressourcen-Munition'!F43 -> 22.97175 | G22: ='Ressourcen-Munition'!G43 -> 45.9435 | H22: ='Ressourcen-Munition'!H43 -> 229.7175 | I22: ='Ressourcen-Munition'!I43 -> 459.435 | J22: Reduziert die Nachladezeit um 5 Sekunden
A23: Vorderlader | B23: VL. Papierpatrone | C23: 21 | D23: ='Ressourcen-Munition'!D44 -> 0.4657575 | E23: ='Ressourcen-Munition'!E44 -> 4.657575 | F23: ='Ressourcen-Munition'!F44 -> 23.287875 | G23: ='Ressourcen-Munition'!G44 -> 46.57575 | H23: ='Ressourcen-Munition'!H44 -> 232.87875 | I23: ='Ressourcen-Munition'!I44 -> 465.7575 | J23: Reduziert die Nachladezeit um 5 Sekunden
A24: Vorderlader | B24: VL. Papierpatrone | C24: 22 | D24: ='Ressourcen-Munition'!D45 -> 0.47208 | E24: ='Ressourcen-Munition'!E45 -> 4.7208 | F24: ='Ressourcen-Munition'!F45 -> 23.604 | G24: ='Ressourcen-Munition'!G45 -> 47.208 | H24: ='Ressourcen-Munition'!H45 -> 236.04 | I24: ='Ressourcen-Munition'!I45 -> 472.08 | J24: Reduziert die Nachladezeit um 5 Sekunden
A25: Vorderlader | B25: VL. Papierpatrone | C25: 23 | D25: ='Ressourcen-Munition'!D46 -> 0.4784025 | E25: ='Ressourcen-Munition'!E46 -> 4.784025 | F25: ='Ressourcen-Munition'!F46 -> 23.920125 | G25: ='Ressourcen-Munition'!G46 -> 47.84025 | H25: ='Ressourcen-Munition'!H46 -> 239.20125 | I25: ='Ressourcen-Munition'!I46 -> 478.4025 | J25: Reduziert die Nachladezeit um 5 Sekunden
A26: Hinterlader | B26: Papierpatrone | C26: 16 | D26: ='Ressourcen-Munition'!D47 -> 0.68066667 | E26: ='Ressourcen-Munition'!E47 -> 6.8066667 | F26: ='Ressourcen-Munition'!F47 -> 34.033333 | G26: ='Ressourcen-Munition'!G47 -> 68.066667 | H26: ='Ressourcen-Munition'!H47 -> 340.33333 | I26: ='Ressourcen-Munition'!I47 -> 680.66667
A27: Hinterlader | B27: Papierpatrone | C27: 17 | D27: ='Ressourcen-Munition'!D48 -> 0.70108667 | E27: ='Ressourcen-Munition'!E48 -> 7.0108667 | F27: ='Ressourcen-Munition'!F48 -> 35.054333 | G27: ='Ressourcen-Munition'!G48 -> 70.108667 | H27: ='Ressourcen-Munition'!H48 -> 350.54333 | I27: ='Ressourcen-Munition'!I48 -> 701.08667
A28: Hinterlader | B28: Papierpatrone | C28: 18 | D28: ='Ressourcen-Munition'!D49 -> 0.72150667 | E28: ='Ressourcen-Munition'!E49 -> 7.2150667 | F28: ='Ressourcen-Munition'!F49 -> 36.075333 | G28: ='Ressourcen-Munition'!G49 -> 72.150667 | H28: ='Ressourcen-Munition'!H49 -> 360.75333 | I28: ='Ressourcen-Munition'!I49 -> 721.50667
A29: Hinterlader | B29: Papierpatrone | C29: 19 | D29: ='Ressourcen-Munition'!D50 -> 0.74192667 | E29: ='Ressourcen-Munition'!E50 -> 7.4192667 | F29: ='Ressourcen-Munition'!F50 -> 37.096333 | G29: ='Ressourcen-Munition'!G50 -> 74.192667 | H29: ='Ressourcen-Munition'!H50 -> 370.96333 | I29: ='Ressourcen-Munition'!I50 -> 741.92667
A30: Patronenwaffen | B30: Messingpatrone | C30: 7 | D30: ='Ressourcen-Munition'!D51 -> 0.7814 | E30: ='Ressourcen-Munition'!E51 -> 7.814 | F30: ='Ressourcen-Munition'!F51 -> 39.07 | G30: ='Ressourcen-Munition'!G51 -> 78.14 | H30: ='Ressourcen-Munition'!H51 -> 390.7 | I30: ='Ressourcen-Munition'!I51 -> 781.4
A31: Patronenwaffen | B31: Messingpatrone | C31: 8 | D31: ='Ressourcen-Munition'!D52 -> 0.8251584 | E31: ='Ressourcen-Munition'!E52 -> 8.251584 | F31: ='Ressourcen-Munition'!F52 -> 41.25792 | G31: ='Ressourcen-Munition'!G52 -> 82.51584 | H31: ='Ressourcen-Munition'!H52 -> 412.5792 | I31: ='Ressourcen-Munition'!I52 -> 825.1584
A32: Patronenwaffen | B32: Messingpatrone | C32: 9 | D32: ='Ressourcen-Munition'!D53 -> 0.8689168 | E32: ='Ressourcen-Munition'!E53 -> 8.689168 | F32: ='Ressourcen-Munition'!F53 -> 43.44584 | G32: ='Ressourcen-Munition'!G53 -> 86.89168 | H32: ='Ressourcen-Munition'!H53 -> 434.4584 | I32: ='Ressourcen-Munition'!I53 -> 868.9168
A33: Patronenwaffen | B33: Messingpatrone | C33: 10 | D33: ='Ressourcen-Munition'!D54 -> 0.9126752 | E33: ='Ressourcen-Munition'!E54 -> 9.126752 | F33: ='Ressourcen-Munition'!F54 -> 45.63376 | G33: ='Ressourcen-Munition'!G54 -> 91.26752 | H33: ='Ressourcen-Munition'!H54 -> 456.3376 | I33: ='Ressourcen-Munition'!I54 -> 912.6752
A34: Patronenwaffen | B34: Messingpatrone | C34: 11 | D34: ='Ressourcen-Munition'!D55 -> 0.9564336 | E34: ='Ressourcen-Munition'!E55 -> 9.564336 | F34: ='Ressourcen-Munition'!F55 -> 47.82168 | G34: ='Ressourcen-Munition'!G55 -> 95.64336 | H34: ='Ressourcen-Munition'!H55 -> 478.2168 | I34: ='Ressourcen-Munition'!I55 -> 956.4336
A35: Patronenwaffen | B35: Messingpatrone | C35: 12 | D35: ='Ressourcen-Munition'!D56 -> 1.000192 | E35: ='Ressourcen-Munition'!E56 -> 10.00192 | F35: ='Ressourcen-Munition'!F56 -> 50.0096 | G35: ='Ressourcen-Munition'!G56 -> 100.0192 | H35: ='Ressourcen-Munition'!H56 -> 500.096 | I35: ='Ressourcen-Munition'!I56 -> 1000.192

Sheet Legende
A1: Name
B2: Der Name, unter dem die Feuerwaffe bei ihrem Urspungsvolk bekannt geworden ist.
A3: Typ
B4: Grobe Bauform der Waffe
B5: Pistole: | C5: Die Pistole (Faustfeuerwaffe) ist eine Schusswaffe, die zur Kategorie der Handfeuerwaffen gehört. Sie zeichnet sich dadurch aus, dass man sie problemlos einhändig führen kann. Pistolen sind meistens nur für kurze Reichweiten geeignet.
B6: Gewehr: | C6: Das Gewehr ist nach zwergischen Sprachgebrauch - mit Ausnahme des Luftgewehrs - eine zu den Handfeuerwaffen zählende Schusswaffe, die als Schulterwaffe (von der Schulter geschossen) mit zwei Händen zu bedienen ist. Durch ihre Länge sind Gewehre im Allgemeinen nicht so gut geeignet für den Nahkampf. Dafür sind sie auf größeren Reichweiten den Pistolen haushoch überlegen.
A7: Bauart
B8: Legt die spezifische Bauform fest.
B9: Normal: | C9: Eine Standardwaffe ohne Besonderheiten.
B10: Billig: | C10: Diese Waffe ist für sehr wenig Gold zu haben. Allerdings ist sie deshalb auch alles andere als zuverlässig und genau.
B11: Böller: | C11: Sehr großkalibrige, kurzläufige Pistole, die für Kurzreichweiten entworfen wurde.
B12: Donnerbüchse: | C12: Sehr großkalibriges, kurzläufiges Gewehr, das für Kurzreichweiten entworfen wurde.
B13: Doppelläufig: | C13: Eine Waffe mit 2 Rohren/Läufen, die beide zugleich oder einzeln abgefeuert werden können. Es gibt also 2 Möglickeiten eine solche Waffe abzufeuern. 1) Beide Rohre direkt hintereinander innerhalb einer Sekunde (Kampfrunde) 2) Nur ein Rohr (nur einen Schuss). Der zweite Schuss innerhalb einer Sekunde (Kampfrunde) ist um den Rückstoß der Waffe erschwert.
B14: Hakenbüchse: | C14: Ein sehr schweres Gewehr, das auf ungehemmte Feuerkraft setzt, dabei aber sehr unhandlich und schwer ist.
B15: Harpunengewehr: | C15: ???
B16: Jagd: | C16: Eine für die Jagd konzipierte Waffe.
B17: Langlauf: | C17: Eine Pistole mit verlängertem Lauf/Rohr. Damit sind Schüsse auf größere Distanz als mit normalen Pistolen möglich. Allerdings geht der längere Lauf zu Ungunsten des Handlings, wodurch die Pistole auf Nahreichweiten unhandlicher wird.
B18: Präzisionsgewehr: | C18: Ein Präzisionsgewehr ist ein langläufiges Gewehr mit gezogenem Lauf (Büchse), das dazu konzipiert wurde, Ziele in sehr großer Entfernung zu treffen.
B19: Schwer: | C19: Ein/e großkalibrige/s Gewehr/Pistole.
B20: Schwere Hakenbüchse: | C20: Eine riesige und extrem schwere Muskete. Eigentlich schon fast eine kleine Kanone. Sie eignet sich aufgrund ihrer Schwerfälligkeit ausschließlich als Verteidigungswaffe, wobei sie vorwiegend von Burgmauern herab eingesetzt wird.
... B23: Karabiner: | C23: Karabiner sind kurzläufige Gewehre. Ursprünglich wurden leichte Militärgewehre mit im Verhältnis zum Infanteriegewehr kürzerem Lauf, und manchmal für schwächere Patronen konzipiert, Karabiner genannt, welche bei der Kavallerie und anderen berittenen Truppenteilen eingesetzt wurden.
A24: Lademechanik
B25: Gibt an, auf welche Weise die Waffe geladen wird.
B27: Block-/Scharnierverschluss: | C27: Der Eisenbeißer der Zwerge war das erste Patronengewehr mit Block-/Schanierverschluss. Es ist ein Einzellader mit einem nach oben zu öffnenden Block- oder Scharnierverschluss. Wie alle seine Vorgänger hat das Gewehr ein vorne liegendes Seitenschloss und einen außen liegendem Hahn.
B28: Hinterlader: | C28: Hinterlader sind Schusswaffen, deren Lauf an beiden Enden offen ist und bei denen das Projektil und die Treibladung durch die hintere Öffnung in die Kammer gebracht werden. Meist wird dazu eine Papier-Patrone verwendet. Die Ladeseite des Laufs wird durch den Verschluss der Waffe abgedichtet, der typischerweise auch die Auslösevorrichtung enthält.
B29: Klapplauf: | C29: Bei Klapplaufwaffen lässt sich das Rohr durch ein Scharnier am hinteren Ende abklappen und ermöglicht so das Laden der Waffe mit Patronen.
B30: Vorderlader: | C30: Der Vorderlader ist die ursprüngliche Form der Feuerwaffe. Die Waffe wird mit Treibladung und Projektil durch die Mündung geladen. Das hintere Ende des Laufes ist fest verschlossen und verfügt nur über ein kleines Zündloch, durch das ein mittels Lunte (Luntenschloss), Feuerstein (Steinschloss), Radschloss oder Zündhütchen (Perkussionswaffe) erzeugter Funke oder Feuerstrahl die Treibladung zündet. Vorderladerwaffen werden klassisch mit Schwarzpulver und einem Bleigeschoss geladen. Dazu kommt oft noch ein Schusspflaster zur Abdichtung.
A31: Schloss
B32: Das Schloss ist der Mechanismus zur Zündung der Ladung einer Feuerwaffe.
B34: Luntenschloss: | C34: Ein Hebel bewegt die brennende Lunte an das Zündloch.
B35: Radschloss: | C35: Ein Reibrad-Uhrwerk und Schwefelkies erzeugen Funken.
B36: Steinschloss: | C36: Ein Feuerstein schlägt auf Metall und erzeugt Funken
B37: Perkussionsschloss: | C37: Ein Hahn schlägt auf ein schlagempfindliches Anzündhütchen.
B38: Nadelzündung: | C38: Die Nadelzündung (auch Zündnadelzündung) ist ein Verfahren der Schussauslösung bei Schusswaffen, bei welchem die Entzündung der Treibladung durch eine spitze Nadel bewirkt wird. Diese Nadel wird durch eine gespannte Feder in das in der Patrone befindliche Zündelement eingestoßen. Der dazugehörige Mechanismus wird Zündnadelschloss genannt. Bei der Zündnadelpatrone von Zworg wurden die Komponenten Geschoss, Treibladung und Zündelement erstmals zusammen als Einheits-Papierpatrone hergestellt. Erste Waffen mit Zündnadelzündung waren Vorderlader, der Durchbruch stellte sich erst als Hinterlader ein, diese wurden von Johann Emanuel von Zworg entwickelt. Obwohl schon früh in Kartharsis eingeführt, stellte sich ein großes internationales Interesse erst spät ein, als das vom Goblinischen Ingenieur Fips Goldfluss entwickelte Zündnadelgewehr produktionsreif wurde. Wenige Jahre später war das Zündnadelsystem bereits technisch überholt. Die Zündnadelzündung mit Papierpatronen wurde von der Schlagbolzenzündung mit Metallpatronen abgelöst.
B39: Schlagbolzen / Hahnschloss: | C39: Beim Hahnschloss schlägt ein durch den Daumen fassbarer Hahn auf einen Zündstift (Stift, welcher geschlagen wird, um zu zünden), der die Kraft weitergibt und die Patrone zündet. Beim Schlagbolzen ist das anders, die Arbeit macht hier der gespannte gefederte Bolzen, dessen Masse und seine Zündspitze die Patrone zündet (Bolzen, der selber schlägt).
A40: Lauf
B41: Als Lauf wird allgemein das Rohr einer Schusswaffe bezeichnet, das der Führung des Projektils und der Aufnahme der Treibladung oder der Patrone dient. Im strengen Sinne bezeichnet Lauf
B42: nur den Abschnitt des Rohres der Waffe, der beim Schuss vom Projektil durchlaufen wird. Das hintere Ende des Laufs, in das die Patrone geladen wird, wird als Patronenlager bezeichnet.
B43: Die Bohrung des Laufes wird auch als Seele (Laufseele) bezeichnet, deren Längsachse als Seelenachse.
B44: Glattlauf: | C44: Läufe von Pistolen und Gewehren mit glatten Läufen sind völlig glatt, wie der Name schon sagt. Das Geschoss verlässt den Lauf ohne jegliche Stabilisierung und ist daher eher ungenau.
...

Sheet Ressourcen-Waffen
A1: Name | B1: Volk | C1: Typ | D1: Bauart | E1: Lademechanik | F1: Schloss | G1: Lauf | H1: Munition | I1: Verarbeitung | J1: Anpassung | K1: Gewicht | L1: Mindeststärke | M1: 1.Würfel | N1: 2.Würfel | O1: Fixschaden | P1: RB | Q1: Kaliber | R1: 10m | S1: 30m | T1: 60m | U1: 100m | V1: 150m | W1: 210m | X1: RW | Y1: Nachladezeit | Z1: Nachladen TaW-Teiler | AA1: Patzermodifikator | AB1: Verfügbarkeit | AC1: Preis | AD1: Herstellungszeit | AE1: Lohn/d | AF1: Stahl/kg in D | AG1: Holz/kg in D | AH1: Gewicht Stahl in kg | AI1: Gewicht Holz in kg
A2: Karabiner | C2: Gewehr | D2: Bauart | K2: =AH2+AI2 -> -0.9 | L2: -1 | R2: 2 | T2: -2 | U2: -4 | V2: -6 | W2: -8 | X2: -10 | AB2: -20 | AH2: -0.8 | AI2: -0.1 | AJ2: Würfeltabelle | AL2: Goblins | AM2: Alle anderen | AO2: Verftabelle
A3: Karabiner VL | C3: Gewehr | D3: Bauart | K3: =AH3+AI3 -> -0.9 | L3: -1 | R3: 2 | T3: -2 | U3: -4 | V3: -6 | W3: -8 | X3: -10 | Y3: -1 | AB3: -10 | AH3: -0.8 | AI3: -0.1 | AJ3: -4 | AK3: W2 | AL3: Ausschuss | AM3: Ausschuss | AO3: -9999 | AP3: 7
A4: Goblinisch | B4: Volk | K4: =AH4+AI4 -> -0.7 | L4: -3 | P4: 3 | Q4: -1 | R4: -1 | S4: -1 | T4: -1 | U4: -2 | V4: -2 | W4: -2 | AA4: 2 | AB4: 40 | AD4: -3 | AH4: -0.5 | AI4: -0.2 | AJ4: -3 | AK4: W3 | AL4: Gob. Massenfabrikation | AM4: Massenfabrikation | AO4: 70 | AP4: 6
A5: Pocket Pistol | C5: Pistole | D5: Bauart | K5: =AH5+AI5 -> -0.7 | L5: -2 | M5: -2 | N5: -2 | P5: 3 | Q5: -2 | R5: 4 | S5: -5 | T5: -10 | U5: -20 | V5: -40 | W5: -80 | X5: -10 | Y5: -1 | AA5: -2 | AB5: -15 | AD5: 4 | AH5: -0.5 | AI5: -0.2 | AJ5: -2 | AK5: W4 | AL5: Massenfabrikation | AM5: Gesellenarbeit | AO5: 90 | AP5: 5
A6: Billig | C6: Gewehr | D6: Bauart | K6: =AH6+AI6 -> -0.5 | L6: -1 | R6: -1 | S6: -1 | T6: -2 | U6: -2 | V6: -3 | W6: -3 | X6: -10 | AA6: 1 | AB6: 10 | AD6: -0.5 | AH6: -0.5 | AJ6: -1 | AK6: W6 | AL6: Gesellenarbeit | AM6: Meisterarbeit | AO6: 110 | AP6: 4
A7: Billig P | C7: Pistole | D7: Bauart | K7: =AH7+AI7 -> -0.5 | L7: -1 | R7: -1 | S7: -1 | T7: -2 | U7: -2 | V7: -3 | W7: -3 | X7: -10 | AA7: 1 | AB7: 10 | AD7: -0.5 | AH7: -0.5 | AJ7: 0 | AK7: W8 | AL7: Meisterarbeit | AM7: Großmeisterarbeit | AO7: 130 | AP7: 3
A8: Block- oder Scharnierverschluss | E8: Lademechanismus | K8: =AH8+AI8 -> 0.1 | P8: 6 | Q8: -6 | Y8: 8 | Z8: 6 | AB8: -30 | AH8: 0.1 | AJ8: 1 | AK8: W10 | AL8: Großmeisterarbeit | AM8: Einzelstück | AO8: 150 | AP8: 2
A9: Hinterlader | E9: Lademechanismus | K9: =AH9+AI9 -> 0.1 | Y9: 11 | Z9: 6 | AB9: -5 | AH9: 0.1 | AJ9: 2 | AK9: W12 | AL9: Einzelstück | AO9: 170 | AP9: 1
A10: Klapplauf | E10: Lademechanismus | K10: =AH10+AI10 -> 0.1 | P10: 6 | Q10: -6 | Y10: 9 | Z10: 6 | AB10: -20 | AH10: 0.1 | AJ10: 3 | AK10: W15
A11: Gezogen | C11: Pistole | G11: Lauf | K11: =AH11+AI11 -> 0.15 | R11: 2 | S11: 3 | T11: 3 | U11: 2 | V11: 1 | W11: 1 | X11: 30 | AB11: -10 | AD11: 1.5 | AH11: 0.15 | AJ11: 4 | AK11: W20
A12: Böller | C12: Pistole | D12: Bauart | K12: =AH12+AI12 -> 0.3 | L12: 2 | M12: 1 | N12: 1 | O12: 3 | P12: -3 | Q12: 3 | S12: -5 | T12: -10 | U12: -15 | V12: -20 | W12: -25 | X12: -10 | Y12: 2 | AB12: -10 | AD12: 1 | AH12: 0.3 | AJ12: 5 | AK12: W30
A13: Langlauf | C13: Pistole | D13: Bauart | K13: =AH13+AI13 -> 0.3 | N13: 1 | O13: 1 | R13: -1 | S13: 2 | T13: 1 | U13: 1 | V13: 1 | W13: 1 | X13: 10 | AB13: -15 | AD13: 0.5 | AH13: 0.3
A14: Gezogen | C14: Gewehr | G14: Lauf | K14: =AH14+AI14 -> 0.3 | R14: 1 | S14: 3 | T14: 4 | U14: 4 | V14: 5 | W14: 5 | X14: 60 | AB14: -10 | AD14: 2 | AH14: 0.3
