Workbook
Name test1: #REF!
Name test2: #REF!

Sheet Werte
A1: Referenz | B1: Kategorie | C1: Beschreibung | D1: Abkürzung | E1: Info | F1: Parent | G1: Art | H1: Formel | I1: Pool | J1: Flag | K1: Grad | L1: Kosten | M1: Verfuegbarkeit | O1: Mindest-TaW | P1: Eig-Bonus | Q1: Wirkung
A2: #spruchmagie_erdbeschwoerung_1_splitterwand | B2: Spruchmagie | C2: Splitterwand | F2: Erdbeschwörung | G2: Wert | J2: ACHTUNG: In der Quelle (NN_Spruchmagie_0.57) gibt es mehrere Zeilen mit gleichem Schule+Grad+Name aber abweichendem Wirkungstext (vermutlich alte+neue Version nebeneinander stehen geblieben) - hier wurde die letzte Version uebernommen, bitte pruefen. | K2: 1 | L2: WENN(wert=0;0;10+(wert-1)*grad) | P2: eig_bonus_k_staerke | Q2: Der Magier erschafft eine Wand aus Erde. Die Wahrnehmung durch diese Wand ist stark erschwert bis unmöglich: Alle FK-Attacken sind um {Aura}*2 erschwert. Wer versucht, die Wand zu durchdringen, erleidet Elementarschaden auf jeder TZ. Während der Effektdauer entfaltet die Wand nur die halbe Wirkung. Schaden: W4+{Magie}, RB 6 auf jede TZ.
A3: #spruchmagie_erdbeschwoerung_2_splitterstrahl | B3: Spruchmagie | C3: Splitterstrahl | F3: Erdbeschwörung | G3: Wert | J3: ACHTUNG: In der Quelle (NN_Spruchmagie_0.57) gibt es mehrere Zeilen mit gleichem Schule+Grad+Name aber abweichendem Wirkungstext (vermutlich alte+neue Version nebeneinander stehen geblieben) - hier wurde die letzte Version uebernommen, bitte pruefen. | K3: 2 | L3: WENN(wert=0;0;10+(wert-1)*grad) | P3: eig_bonus_k_staerke | Q3: Aus der Handfläche des Magiers schießt ein {M} cm dicker Strahl aus Erde. Schaden: W10+{Magie}, RB 3, pro sec, Treffer auf eine FK-TZ mit 1 zusätzlichen TZ-Reroll.
A4: #spruchmagie_erdbeschwoerung_3_steinschlag | B4: Spruchmagie | C4: Steinschlag | F4: Erdbeschwörung | G4: Wert | J4: ACHTUNG: In der Quelle (NN_Spruchmagie_0.57) gibt es mehrere Zeilen mit gleichem Schule+Grad+Name aber abweichendem Wirkungstext (vermutlich alte+neue Version nebeneinander stehen geblieben) - hier wurde die letzte Version uebernommen, bitte pruefen. | K4: 3 | L4: WENN(wert=0;0;10+(wert-1)*grad) | P4: eig_bonus_k_staerke | Q4: Der Magus erschafft um das Opfer eine Kugel aus Erde. Treffer auf FK-TZ mit 2 TZ-Rerolls auf die gewünschte Trefferzone. Schaden: 2W6 + {Magie}, RB 6.
A5: #spruchmagie_erdbeschwoerung_4_grosse_splitterwand | B5: Spruchmagie | C5: Große Splitterwand | F5: Erdbeschwörung | G5: Wert | J5: ACHTUNG: In der Quelle (NN_Spruchmagie_0.57) gibt es mehrere Zeilen mit gleichem Schule+Grad+Name aber abweichendem Wirkungstext (vermutlich alte+neue Version nebeneinander stehen geblieben) - hier wurde die letzte Version uebernommen, bitte pruefen. | K5: 4 | L5: WENN(wert=0;0;10+(wert-1)*grad) | P5: eig_bonus_k_staerke | Q5: Der Magier erschafft eine Wand aus Erde. Die Wahrnehmung durch diese Wand ist stark erschwert bis unmöglich: Alle FK-Attacken sind um {Aura}*2 erschwert. Wer versucht, die Wand zu durchdringen, erleidet Elementarschaden auf jeder TZ. Während der Effektdauer entfaltet die Wand nur die halbe Wirkung. Schaden: 2W6 + {Magie}, RB 6. Länge max. {M} m, Breite max. {M}*5cm
A6: #spruchmagie_erdbeschwoerung_5_grosse_splitteraura | B6: Spruchmagie | C6: Große Splitteraura | F6: Erdbeschwörung | G6: Wert | J6: ACHTUNG: In der Quelle (NN_Spruchmagie_0.57) gibt es mehrere Zeilen mit gleichem Schule+Grad+Name aber abweichendem Wirkungstext (vermutlich alte+neue Version nebeneinander stehen geblieben) - hier wurde die letzte Version uebernommen, bitte pruefen. | K6: 5 | L6: WENN(wert=0;0;10+(wert-1)*grad) | P6: eig_bonus_k_staerke | Q6: Der Magus hüllt sich in eine kugelförmige Aura aus Erde. Wer sich in die Aura begibt, erleidet auf jeder TZ innerhalb dieses Gebietes Elementarschaden. Der Magier kann aus der Aura heraus normal zielen, FK-Angriffe sind um {Aura}*2 erschwert. Feindliche Magie ist mit Ziel Aura hiervon nicht betroffen. Schaden: 2W6+{Magie}, RB 6, auf jede TZ.
A7: #spruchmagie_erdbeschwoerung_5_grosser_steinschuss | B7: Spruchmagie | C7: Großer Steinschuss | F7: Erdbeschwörung | G7: Wert | J7: ACHTUNG: In der Quelle (NN_Spruchmagie_0.57) gibt es mehrere Zeilen mit gleichem Schule+Grad+Name aber abweichendem Wirkungstext (vermutlich alte+neue Version nebeneinander stehen geblieben) - hier wurde die letzte Version uebernommen, bitte pruefen. | K7: 5 | L7: WENN(wert=0;0;10+(wert-1)*grad) | P7: eig_bonus_k_staerke | Q7: Der Magus erschafft einen Bolzen aus Erde. Treffer auf FK-TZ. Schaden: 2W10 + {Magie}; RB: 6 + {M}:2
A8: #spruchmagie_erdbeschwoerung_5_splittersturm | B8: Spruchmagie | C8: Splittersturm | F8: Erdbeschwörung | G8: Wert | J8: ACHTUNG: In der Quelle (NN_Spruchmagie_0.57) gibt es mehrere Zeilen mit gleichem Schule+Grad+Name aber abweichendem Wirkungstext (vermutlich alte+neue Version nebeneinander stehen geblieben) - hier wurde die letzte Version uebernommen, bitte pruefen. | K8: 5 | L8: WENN(wert=0;0;10+(wert-1)*grad) | P8: eig_bonus_k_staerke | Q8: Eine vom Magus ausgehende kugelförmige Explosion verursacht Elementarschaden. Es ist unmöglich, dem Schaden zu entgehen. Jede TZ wird getroffen. Schaden: W8 + {Magie}, RB 3.
A9: #spruchmagie_erdbeschwoerung_6_grosser_splitterstrahl | B9: Spruchmagie | C9: Großer Splitterstrahl | F9: Erdbeschwörung | G9: Wert | J9: ACHTUNG: In der Quelle (NN_Spruchmagie_0.57) gibt es mehrere Zeilen mit gleichem Schule+Grad+Name aber abweichendem Wirkungstext (vermutlich alte+neue Version nebeneinander stehen geblieben) - hier wurde die letzte Version uebernommen, bitte pruefen. | K9: 6 | L9: WENN(wert=0;0;10+(wert-1)*grad) | P9: eig_bonus_k_staerke | Q9: Aus der Handfläche des Magiers schießt ein {M} cm dicker Strahl aus Erde. Schaden: 2W10 + {Magie}, RB 6, pro sec, Treffer auf eine FK-TZ mit 1 zusätzlichen TZ-Reroll.
A10: #spruchmagie_erdbeschwoerung_6_grosser_steinschlag | B10: Spruchmagie | C10: Großer Steinschlag | F10: Erdbeschwörung | G10: Wert | J10: ACHTUNG: In der Quelle (NN_Spruchmagie_0.57) gibt es mehrere Zeilen mit gleichem Schule+Grad+Name aber abweichendem Wirkungstext (vermutlich alte+neue Version nebeneinander stehen geblieben) - hier wurde die letzte Version uebernommen, bitte pruefen. | K10: 6 | L10: WENN(wert=0;0;10+(wert-1)*grad) | P10: eig_bonus_k_staerke | Q10: Der Magus erschafft um das Opfer eine Kugel aus Erde. Treffer auf FK-TZ mit 2 TZ-Rerolls auf die gewünschte Trefferzone. Schaden: 2W12 + {Magie}, RB 9.
A11: #spruchmagie_erdbeschwoerung_7_grosser_splittersturm | B11: Spruchmagie | C11: Großer Splittersturm | F11: Erdbeschwörung | G11: Wert | J11: ACHTUNG: In der Quelle (NN_Spruchmagie_0.57) gibt es mehrere Zeilen mit gleichem Schule+Grad+Name aber abweichendem Wirkungstext (vermutlich alte+neue Version nebeneinander stehen geblieben) - hier wurde die letzte Version uebernommen, bitte pruefen. | K11: 7 | L11: WENN(wert=0;0;10+(wert-1)*grad) | P11: eig_bonus_k_staerke | Q11: Eine vom Magus ausgehende kugelförmige Explosion verursacht Elementarschaden. Es ist unmöglich, dem Schaden zu entgehen. Jede TZ wird getroffen. Schaden: 2W15 + {Magie}, RB 15.
A12: #spruchmagie_feuerbeschwoerung_1_flammenwand | B12: Spruchmagie | C12: Flammenwand | F12: Feuerbeschwörung | G12: Wert | J12: ACHTUNG: In der Quelle (NN_Spruchmagie_0.57) gibt es mehrere Zeilen mit gleichem Schule+Grad+Name aber abweichendem Wirkungstext (vermutlich alte+neue Version nebeneinander stehen geblieben) - hier wurde die letzte Version uebernommen, bitte pruefen. | K12: 1 | L12: WENN(wert=0;0;10+(wert-1)*grad) | P12: eig_bonus_g_mut | Q12: Der Magier erschafft eine Wand aus Feuer. Die Wahrnehmung durch diese Wand ist stark erschwert bis unmöglich: Alle FK-Attacken sind um {Aura}*2 erschwert. Wer versucht, die Wand zu durchdringen, erleidet Elementarschaden auf jeder TZ. Während der Effektdauer entfaltet die Wand nur die halbe Wirkung. Schaden: W6+{Magie} auf jede TZ.
A13: #spruchmagie_feuerbeschwoerung_2_flammenaura | B13: Spruchmagie | C13: Flammenaura | F13: Feuerbeschwörung | G13: Wert | J13: ACHTUNG: In der Quelle (NN_Spruchmagie_0.57) gibt es mehrere Zeilen mit gleichem Schule+Grad+Name aber abweichendem Wirkungstext (vermutlich alte+neue Version nebeneinander stehen geblieben) - hier wurde die letzte Version uebernommen, bitte pruefen. | K13: 2 | L13: WENN(wert=0;0;10+(wert-1)*grad) | P13: eig_bonus_g_mut | Q13: Der Magus hüllt sich in eine kugelförmige Aura aus Feuer. Wer sich in die Aura begibt, erleidet auf jeder TZ innerhalb dieses Gebietes Elementarschaden. Der Magier kann aus der Aura heraus normal zielen, FK-Angriffe sind um {Aura}*2 erschwert. Feindliche Magie ist mit Ziel Aura hiervon nicht betroffen. Schaden: W6+{Magie} auf jede TZ.
... A71: #spruchmagie_wasserbeschwoerung_7_grosse_frostbolzen_salve | B71: Spruchmagie | C71: Große Frostbolzen-Salve | F71: Wasserbeschwörung | G71: Wert | J71: ACHTUNG: In der Quelle (NN_Spruchmagie_0.57) gibt es mehrere Zeilen mit gleichem Schule+Grad+Name aber abweichendem Wirkungstext (vermutlich alte+neue Version nebeneinander stehen geblieben) - hier wurde die letzte Version uebernommen, bitte pruefen. | Referenz enthielt Bindestrich (mehrdeutig mit Subtraktion) - zu Unterstrich normalisiert. | K71: 7 | L71: WENN(wert=0;0;10+(wert-1)*grad) | P71: eig_bonus_k_athletik | Q71: Der Magus erschafft {Magie} : 2 Bolzen aus Wasser. Jeweils Treffer auf FK-TZ. Schaden: 2W10 + {Magie}; RB: {M}:2. Pro 5 TP erleidet das Opfer zusätzliche BE 1, nur die höchste so erzielte BE zählt.
A72: ep_abenteuer | B72: Charakterwerte | C72: EP zum Abenteuerende | E72: S.1 | G72: Formel | H72: ep_gesamt-ep_start
A73: le_leberschutz | B73: Kampf | C73: Leberschutz | E73: S.3 | G73: Pool
A74: ep_gesamt | B74: Charakterwerte | C74: Gesamte Erfahrungspunke | E74: S.1 | G74: Wert
A75: ep_start | B75: Charakterwerte | C75: EP bei Abenteuerbeginn | E75: S.1 | G75: Wert
A76: bewegung_f_schnell_schwimmen | B76: Bewegung | C76: Schnell Schwimmen | E76: Meisterscreen S.3 | G76: Formel | H76: (eig_k_konstitution+eig_k_athletik+gr_schwimmen)/30
A77: bewegung_f_sprinten | B77: Bewegung | C77: Sprinten | E77: Meisterscreen S.3 | G77: Formel | H77: (eig_k_athletik+eig_k_schnelligkeit+gr_laufen)/7+4
A78: #spruchmagie_beherrschung_4_einschlaefern | B78: Spruchmagie | C78: Einschläfern | F78: Beherrschung | G78: Wert | K78: 4 | L78: WENN(wert=0;0;10+(wert-1)*grad) | P78: eig_bonus_g_ausstrahlung | Q78: Das Opfer schläft ein. Der Schlaf ist, wenn auch unnatürlich tief, wie normaler schlaf zu Behandeln. Sollte das Opfer also gerade stehen, so fällt es um und wacht durch den Sturz natürlich wieder auf. Auch das abfeuern einer Feuerwaffe in seiner nähe wird wohl, ohne Probe, zum Aufwachen führen. Gewohnte Geräusche gehören natürlich nicht dazu. Ein Heizer einer Dampfmaschine wird durch eben jene nicht Aufwachen.
A79: #spruchmagie_beherrschung_7_maechtige_f_daemonen_herrschaft | B79: Spruchmagie | C79: Mächtige f.Dämonen Herrschaft | F79: Beherrschung | G79: Wert | K79: 7 | L79: WENN(wert=0;0;10+(wert-1)*grad) | P79: eig_bonus_g_ausstrahlung | Q79: Ein freier (nicht von einem anderen Magus beherrschter) Dämon hat eine Willenskraft-Probe erschwert um die Differenz von der {M} des Margus (Macht x2) und des Opfers (Macht x1). Und alle 24 Stunden eine weitere. Wenn sie gelingt fällt der Zauber.1 und 29 sind immer ein Erfolg. Ansonsten wird der Dämon zu einem Willenskraftenlosen Sklaven des Magus. Es wird aufs Wort hören, ganz so als währe es ein Absolut untertäniger Diner. Der Dämon weis zwar immer genau was der Magus von ihm Willenskraft ist aber nicht Intelligenzelligenter als vorher oder verfügt nicht über neue Fertigkeiten. Eine Stroh dummer Dämon wird es wohl nicht schaffen den Banksafe ohne Gewalt zu öffnen.
A80: #spruchmagie_beherrschung_5_massen_besaenftigung | B80: Spruchmagie | C80: Massen Besänftigung | F80: Beherrschung | G80: Wert | K80: 5 | L80: WENN(wert=0;0;10+(wert-1)*grad) | P80: eig_bonus_g_ausstrahlung | Q80: Die Opfer werden ruhig und gelassen, sie verlieren jeglichen drang zu Töten (außer Einer ist ein Sadist und macht es aus Spaß). Sie wissen zwar noch alles, es ist aber nicht mehr so Dramatisch für Sie. Nach dem der Zauber vorbei ist, sind die Opfer immer noch ruhig, es hält Sie aber nichts davon ab wieder Wütend zu werden. Was natürlich auch sofort geschehen kann aber nicht muss, wenn sie sich daran erinnern dass man gerade ihr Dorf nieder gebrannt hat.
A81: #spruchmagie_beherrschung_3_schmerzt_unterdruecken | B81: Spruchmagie | C81: Schmerzt unterdrücken | F81: Beherrschung | G81: Wert | K81: 3 | L81: WENN(wert=0;0;10+(wert-1)*grad) | P81: eig_bonus_g_willenskraft | Q81: Die Gefühle und Schmerzen des Opfers werden unterdrückt. Das Opfer fühlt sich so als würde es unter dem Einfluss eines Betäubungsmittels stehen. Es bekommt eine Generelle Behinderung von 1. Seine TS steigt um das 4 fache an und alle Behinderungen die das Opfer durch Kampfschäden bekommt oder bekommen hat sind gleich null.
A82: #spruchmagie_beherrschung_2_zoegern | B82: Spruchmagie | C82: Zögern | F82: Beherrschung | G82: Wert | K82: 2 | L82: WENN(wert=0;0;10+(wert-1)*grad) | P82: eig_bonus_g_intelligenz | Q82: Das Opfer zögert, das zu tun, was es gerade wollte. Es greift nicht mehr an, sondern verteidigt sich nur noch. Sollte gerade keine Kampf Situation sein so bleibt es sehn und hält inne um seinen nächsten schritt noch mal zu überdenken. Das Opfer zögert maximal 1W4+{Magie} Sekunden lang.
A83: vn_angst_magie_10 | B83: Vor- und Nachteile | C83: Nervosität: Magie | E83: Auswahlgruppe angst_magie; maximal 1 Stufe; Angstwert 10; direkte Konfrontation: bei jeder erneuten direkten Konfrontation; bloße Gegenwart: BE -1. | F83: Angst: Magie | G83: Auswahl | J83: EP-Rate für 'magie' aus NN NPC-Rechner 0.75, Sheet 'NPC-Rechner' Formel '=AOxx*-10' (Zeile 52ff). Kosten = Stufenwert(10) * Rate(-10). | EXKLUSIV_ANGST=angst_magie | ANGST_INTERVALL=NEUE_KONFRONTATION | ANGST_DIREKTE_KONFRONTATION=1 | ANGST_BE=-1 | K83: 10 | L83: -100 | M83: S | Q83: Der Charakter reagiert auf alle Magie mit Nervosität und ist nicht in der Lage, irgendeine Form von Magie außer KI zu wirken. Bei direkter Konfrontation mit Magie, insbesondere wenn er gegen einen Magiewirker vorgeht, muss er bei jeder erneuten direkten Konfrontation eine um 10 erschwerte Mut-Probe bestehen, um handlungsfähig zu bleiben. Um Verzauberungen oder magische Heilung zuzulassen, ein Artefakt zu benutzen oder bewusst mit Magie zu interagieren, muss er einmalig eine um 10 erschwerte Willenskraft-Probe bestehen. Ist Magie zwar gegenwärtig, aber weder direkter Gegner noch Gegenstand, Wesen oder sonstiges Ziel, mit dem sich der Charakter aktuell befasst, sind keine Angst-Proben erforderlich; der Charakter erhält BE -1.
A84: vn_angst_magie_15 | B84: Vor- und Nachteile | C84: Furcht: Magie | E84: Auswahlgruppe angst_magie; maximal 1 Stufe; Angstwert 15; direkte Konfrontation: sofort, danach alle 10 KR; bloße Gegenwart: BE -2. | F84: Angst: Magie | G84: Auswahl | J84: EP-Rate für 'magie' aus NN NPC-Rechner 0.75, Sheet 'NPC-Rechner' Formel '=AOxx*-10' (Zeile 52ff). Kosten = Stufenwert(15) * Rate(-10). | EXKLUSIV_ANGST=angst_magie | ANGST_INTERVALL=10_KR | ANGST_DIREKTE_KONFRONTATION=1 | ANGST_BE=-2 | K84: 15 | L84: -150 | M84: S | Q84: Der Charakter reagiert auf alle Magie mit Furcht und ist nicht in der Lage, irgendeine Form von Magie außer KI zu wirken. Bei direkter Konfrontation mit Magie, insbesondere wenn er gegen einen Magiewirker vorgeht, muss er sofort, danach alle 10 KR eine um 15 erschwerte Mut-Probe bestehen, um handlungsfähig zu bleiben. Um Verzauberungen oder magische Heilung zuzulassen, ein Artefakt zu benutzen oder bewusst mit Magie zu interagieren, muss er einmalig eine um 15 erschwerte Willenskraft-Probe bestehen. Ist Magie zwar gegenwärtig, aber weder direkter Gegner noch Gegenstand, Wesen oder sonstiges Ziel, mit dem sich der Charakter aktuell befasst, sind keine Angst-Proben erforderlich; der Charakter erhält BE -2.
A85: vn_angst_magie_20 | B85: Vor- und Nachteile | C85: Angst: Magie | E85: Auswahlgruppe angst_magie; maximal 1 Stufe; Angstwert 20; direkte Konfrontation: sofort, danach alle 5 KR; bloße Gegenwart: BE -3. | F85: Angst: Magie | G85: Auswahl | J85: EP-Rate für 'magie' aus NN NPC-Rechner 0.75, Sheet 'NPC-Rechner' Formel '=AOxx*-10' (Zeile 52ff). Kosten = Stufenwert(20) * Rate(-10). | EXKLUSIV_ANGST=angst_magie | ANGST_INTERVALL=5_KR | ANGST_DIREKTE_KONFRONTATION=1 | ANGST_BE=-3 | K85: 20 | L85: -200 | M85: S | Q85: Der Charakter reagiert auf alle Magie mit Angst und ist nicht in der Lage, irgendeine Form von Magie außer KI zu wirken. Bei direkter Konfrontation mit Magie, insbesondere wenn er gegen einen Magiewirker vorgeht, muss er sofort, danach alle 5 KR eine um 20 erschwerte Mut-Probe bestehen, um handlungsfähig zu bleiben. Um Verzauberungen oder magische Heilung zuzulassen, ein Artefakt zu benutzen oder bewusst mit Magie zu interagieren, muss er einmalig eine um 20 erschwerte Willenskraft-Probe bestehen. Ist Magie zwar gegenwärtig, aber weder direkter Gegner noch Gegenstand, Wesen oder sonstiges Ziel, mit dem sich der Charakter aktuell befasst, sind keine Angst-Proben erforderlich; der Charakter erhält BE -3.
A86: vn_angst_magie_30 | B86: Vor- und Nachteile | C86: Phobie: Magie | E86: Auswahlgruppe angst_magie; maximal 1 Stufe; Angstwert 30; direkte Konfrontation: sofort, danach jede KR; bloße Gegenwart: BE -5. | F86: Angst: Magie | G86: Auswahl | J86: EP-Rate für 'magie' aus NN NPC-Rechner 0.75, Sheet 'NPC-Rechner' Formel '=AOxx*-10' (Zeile 52ff). Kosten = Stufenwert(30) * Rate(-10). | EXKLUSIV_ANGST=angst_magie | ANGST_INTERVALL=1_KR | ANGST_DIREKTE_KONFRONTATION=1 | ANGST_BE=-5 | K86: 30 | L86: -300 | M86: S | Q86: Der Charakter leidet unter einer Phobie gegenüber aller Magie und ist nicht in der Lage, irgendeine Form von Magie außer KI zu wirken. Bei direkter Konfrontation mit Magie, insbesondere wenn er gegen einen Magiewirker vorgeht, muss er sofort, danach jede KR eine um 30 erschwerte Mut-Probe bestehen, um handlungsfähig zu bleiben. Um Verzauberungen oder magische Heilung zuzulassen, ein Artefakt zu benutzen oder bewusst mit Magie zu interagieren, muss er einmalig eine um 30 erschwerte Willenskraft-Probe bestehen. Ist Magie zwar gegenwärtig, aber weder direkter Gegner noch Gegenstand, Wesen oder sonstiges Ziel, mit dem sich der Charakter aktuell befasst, sind keine Angst-Proben erforderlich; der Charakter erhält BE -5.
A87: vn_angst_magie_5 | B87: Vor- und Nachteile | C87: Unbehagen: Magie | E87: Auswahlgruppe angst_magie; maximal 1 Stufe; Angstwert 5; direkte Konfrontation: einmal pro Situation; bloße Gegenwart: BE 0. | F87: Angst: Magie | G87: Auswahl | J87: EP-Rate für 'magie' aus NN NPC-Rechner 0.75, Sheet 'NPC-Rechner' Formel '=AOxx*-10' (Zeile 52ff). Kosten = Stufenwert(5) * Rate(-10). | EXKLUSIV_ANGST=angst_magie | ANGST_INTERVALL=SITUATION | ANGST_DIREKTE_KONFRONTATION=1 | ANGST_BE=0 | K87: 5 | L87: -50 | M87: S | Q87: Der Charakter empfindet Unbehagen gegenüber aller Magie und ist nicht in der Lage, irgendeine Form von Magie außer KI zu wirken. Bei direkter Konfrontation mit Magie, insbesondere wenn er gegen einen Magiewirker vorgeht, muss er einmal pro Situation eine um 5 erschwerte Mut-Probe bestehen, um handlungsfähig zu bleiben. Um Verzauberungen oder magische Heilung zuzulassen, ein Artefakt zu benutzen oder bewusst mit Magie zu interagieren, muss er einmalig eine um 5 erschwerte Willenskraft-Probe bestehen.
A88: vn_schlechte_eigenschaft_ausstrahlung | B88: Vor- und Nachteile | C88: Schlechte Eigenschaft: Ausstrahlung | E88: Max=9 (ab Kreis 3); Erstellungs-Max=7; nicht uebersteigerbar | G88: Auswahl | J88: Ersetzt die normale Voelker-Maxima-Tabelle fuer diese Eigenschaft komplett (nicht MIN() mit dem Volkswert - die Regel ignoriert explizit die Erstellungs-/Kreis-3-Minima/Maxima und setzt eigene feste Werte). | L88: -200 | M88: E | Q88: Dieser Charakter hat eine unterdurchschnittliche Ausstrahlung. Das absolute Maximum dieser Eigenschaft ist 9 (ab Kreis 3, davor darf die Eigenschaft 7 nicht übersteigen). Dieser Nachteil überschreibt die Spezies-Vorgaben. Die Eigenschaft ist grundsätzlich nicht übersteigerbar.
A89: vn_schlechte_eigenschaft_intelligenz | B89: Vor- und Nachteile | C89: Schlechte Eigenschaft: Intelligenz | E89: Max=9 (ab Kreis 3); Erstellungs-Max=7; nicht uebersteigerbar | G89: Auswahl | J89: Ersetzt die normale Voelker-Maxima-Tabelle fuer diese Eigenschaft komplett (nicht MIN() mit dem Volkswert - die Regel ignoriert explizit die Erstellungs-/Kreis-3-Minima/Maxima und setzt eigene feste Werte). | L89: -200 | M89: E | Q89: Dieser Charakter hat eine unterdurchschnittliche Intelligenz. Das absolute Maximum dieser Eigenschaft ist 9 (ab Kreis 3, davor darf die Eigenschaft 7 nicht übersteigen). Dieser Nachteil überschreibt die Spezies-Vorgaben. Die Eigenschaft ist grundsätzlich nicht übersteigerbar.
A90: vn_schlechte_eigenschaft_mut | B90: Vor- und Nachteile | C90: Schlechte Eigenschaft: Mut | E90: Max=9 (ab Kreis 3); Erstellungs-Max=7; nicht uebersteigerbar | G90: Auswahl | J90: Ersetzt die normale Voelker-Maxima-Tabelle fuer diese Eigenschaft komplett (nicht MIN() mit dem Volkswert - die Regel ignoriert explizit die Erstellungs-/Kreis-3-Minima/Maxima und setzt eigene feste Werte). | L90: -200 | M90: E | Q90: Dieser Charakter hat einen unterdurchschnittlichen Mut. Das absolute Maximum dieser Eigenschaft ist 9 (ab Kreis 3, davor darf die Eigenschaft 7 nicht übersteigen). Dieser Nachteil überschreibt die Spezies-Vorgaben. Die Eigenschaft ist grundsätzlich nicht übersteigerbar.
A91: vn_schlechte_eigenschaft_sinnesschaerfe | B91: Vor- und Nachteile | C91: Schlechte Eigenschaft: Sinnesschaerfe | E91: Max=9 (ab Kreis 3); Erstellungs-Max=7; nicht uebersteigerbar | G91: Auswahl | J91: Ersetzt die normale Voelker-Maxima-Tabelle fuer diese Eigenschaft komplett (nicht MIN() mit dem Volkswert - die Regel ignoriert explizit die Erstellungs-/Kreis-3-Minima/Maxima und setzt eigene feste Werte). | L91: -200 | M91: E | Q91: Dieser Charakter hat eine unterdurchschnittliche Sinnesschärfe. Das absolute Maximum dieser Eigenschaft ist 9 (ab Kreis 3, davor darf die Eigenschaft 7 nicht übersteigen). Dieser Nachteil überschreibt die Spezies-Vorgaben. Die Eigenschaft ist grundsätzlich nicht übersteigerbar.
A92: vn_schlechte_eigenschaft_willenskraft | B92: Vor- und Nachteile | C92: Schlechte Eigenschaft: Willenskraft | E92: Max=9 (ab Kreis 3); Erstellungs-Max=7; nicht uebersteigerbar | G92: Auswahl | J92: Ersetzt die normale Voelker-Maxima-Tabelle fuer diese Eigenschaft komplett (nicht MIN() mit dem Volkswert - die Regel ignoriert explizit die Erstellungs-/Kreis-3-Minima/Maxima und setzt eigene feste Werte). | L92: -200 | M92: E | Q92: Dieser Charakter hat eine unterdurchschnittliche Willenskraft. Das absolute Maximum dieser Eigenschaft ist 9 (ab Kreis 3, davor darf die Eigenschaft 7 nicht übersteigen). Dieser Nachteil überschreibt die Spezies-Vorgaben. Die Eigenschaft ist grundsätzlich nicht übersteigerbar.
A93: vn_schlechte_eigenschaft_athletik | B93: Vor- und Nachteile | C93: Schlechte Eigenschaft: Athletik | E93: Max=9 (ab Kreis 3); Erstellungs-Max=7; nicht uebersteigerbar | G93: Auswahl | J93: Ersetzt die normale Voelker-Maxima-Tabelle fuer diese Eigenschaft komplett (nicht MIN() mit dem Volkswert - die Regel ignoriert explizit die Erstellungs-/Kreis-3-Minima/Maxima und setzt eigene feste Werte). | L93: -200 | M93: E | Q93: Dieser Charakter hat eine unterdurchschnittliche Athletik. Das absolute Maximum dieser Eigenschaft ist 9 (ab Kreis 3, davor darf die Eigenschaft 7 nicht übersteigen). Dieser Nachteil überschreibt die Spezies-Vorgaben. Die Eigenschaft ist grundsätzlich nicht übersteigerbar.
A94: vn_schlechte_eigenschaft_geschicklichkeit | B94: Vor- und Nachteile | C94: Schlechte Eigenschaft: Geschicklichkeit | E94: Max=9 (ab Kreis 3); Erstellungs-Max=7; nicht uebersteigerbar | G94: Auswahl | J94: Ersetzt die normale Voelker-Maxima-Tabelle fuer diese Eigenschaft komplett (nicht MIN() mit dem Volkswert - die Regel ignoriert explizit die Erstellungs-/Kreis-3-Minima/Maxima und setzt eigene feste Werte). | L94: -200 | M94: E | Q94: Dieser Charakter hat eine unterdurchschnittliche Geschicklichkeit. Das absolute Maximum dieser Eigenschaft ist 9 (ab Kreis 3, davor darf die Eigenschaft 7 nicht übersteigen). Dieser Nachteil überschreibt die Spezies-Vorgaben. Die Eigenschaft ist grundsätzlich nicht übersteigerbar.
A95: vn_schlechte_eigenschaft_konstitution | B95: Vor- und Nachteile | C95: Schlechte Eigenschaft: Konstitution | E95: Max=9 (ab Kreis 3); Erstellungs-Max=7; nicht uebersteigerbar | G95: Auswahl | J95: Ersetzt die normale Voelker-Maxima-Tabelle fuer diese Eigenschaft komplett (nicht MIN() mit dem Volkswert - die Regel ignoriert explizit die Erstellungs-/Kreis-3-Minima/Maxima und setzt eigene feste Werte). | L95: -200 | M95: E | Q95: Dieser Charakter hat eine unterdurchschnittliche Konstitution. Das absolute Maximum dieser Eigenschaft ist 9 (ab Kreis 3, davor darf die Eigenschaft 7 nicht übersteigen). Dieser Nachteil überschreibt die Spezies-Vorgaben. Die Eigenschaft ist grundsätzlich nicht übersteigerbar.
A96: vn_schlechte_eigenschaft_schnelligkeit | B96: Vor- und Nachteile | C96: Schlechte Eigenschaft: Schnelligkeit | E96: Max=9 (ab Kreis 3); Erstellungs-Max=7; nicht uebersteigerbar | G96: Auswahl | J96: Ersetzt die normale Voelker-Maxima-Tabelle fuer diese Eigenschaft komplett (nicht MIN() mit dem Volkswert - die Regel ignoriert explizit die Erstellungs-/Kreis-3-Minima/Maxima und setzt eigene feste Werte). | L96: -200 | M96: E | Q96: Dieser Charakter hat eine unterdurchschnittliche Schnelligkeit. Das absolute Maximum dieser Eigenschaft ist 9 (ab Kreis 3, davor darf die Eigenschaft 7 nicht übersteigen). Dieser Nachteil überschreibt die Spezies-Vorgaben. Die Eigenschaft ist grundsätzlich nicht übersteigerbar.
A97: vn_schlechte_eigenschaft_staerke | B97: Vor- und Nachteile | C97: Schlechte Eigenschaft: Staerke | E97: Max=9 (ab Kreis 3); Erstellungs-Max=7; nicht uebersteigerbar | G97: Auswahl | J97: Ersetzt die normale Voelker-Maxima-Tabelle fuer diese Eigenschaft komplett (nicht MIN() mit dem Volkswert - die Regel ignoriert explizit die Erstellungs-/Kreis-3-Minima/Maxima und setzt eigene feste Werte). | L97: -200 | M97: E | Q97: Dieser Charakter hat eine unterdurchschnittliche Stärke. Das absolute Maximum dieser Eigenschaft ist 9 (ab Kreis 3, davor darf die Eigenschaft 7 nicht übersteigen). Dieser Nachteil überschreibt die Spezies-Vorgaben. Die Eigenschaft ist grundsätzlich nicht übersteigerbar.
...

Sheet EP-Stufe-Kreis
A1: EP ab | B1: Stufe | C1: Kreis
A2: 0 | B2: 0 | C2: 0
A3: 20 | B3: 1 | C3: 1
A4: 60 | B4: 2 | C4: 1
A5: 120 | B5: 3 | C5: 1
A6: 200 | B6: 4 | C6: 2
A7: 300 | B7: 5 | C7: 2
A8: 400 | B8: 6 | C8: 2
A9: 500 | B9: 7 | C9: 2
A10: 600 | B10: 8 | C10: 2
A11: 700 | B11: 9 | C11: 3
A12: 850 | B12: 10 | C12: 3
A13: 1000 | B13: 11 | C13: 3
... A65: 15150 | B65: 63 | C65: 7

Sheet WHK-Spez-Kosten
A1: Wert | B1: EP-Kosten (Schritt) | C1: Gesamt-EP
A2: 0 | B2: 0 | C2: 0
A3: 1 | B3: 4 | C3: 4
A4: 2 | B4: 1 | C4: 5
A5: 3 | B5: 1 | C5: 6
A6: 4 | B6: 1 | C6: 7
A7: 5 | B7: 2 | C7: 9
A8: 6 | B8: 2 | C8: 11
A9: 7 | B9: 2 | C9: 13
A10: 8 | B10: 3 | C10: 16
A11: 9 | B11: 3 | C11: 19
A12: 10 | B12: 3 | C12: 22
A13: 11 | B13: 4 | C13: 26
... A41: 39 | B41: 13 | C41: 264

Sheet Eigenschaften-Kosten
A1: Wert | B1: Gesamt-EP | C1: EP-Kosten (Schritt)
A2: 0 | B2: 0 | C2: 0
A3: 1 | B3: 30 | C3: 30
A4: 2 | B4: 60 | C4: 30
A5: 3 | B5: 90 | C5: 30
A6: 4 | B6: 120 | C6: 30
A7: 5 | B7: 150 | C7: 30
A8: 6 | B8: 180 | C8: 30
A9: 7 | B9: 210 | C9: 30
A10: 8 | B10: 240 | C10: 30
A11: 9 | B11: 270 | C11: 30
A12: 10 | B12: 300 | C12: 30
A13: 11 | B13: 330 | C13: 30
... A66: 64 | B66: 6213 | C66: 189

Sheet Voelker-Maxima
A1: Volk | B1: Eigenschaft | C1: Erstellungs-Min | D1: Erstellungs-Max | E1: Max (ab Kreis 3)
A2: Dalkini | B2: Ausstrahlung | C2: 9 | D2: 21 | E2: 31
A3: Dalkini | B3: Intelligenz | C3: 9 | D3: 21 | E3: 31
A4: Dalkini | B4: Mut | C4: 10 | D4: 22 | E4: 31
A5: Dalkini | B5: Sinnesschaerfe | C5: 9 | D5: 21 | E5: 31
A6: Dalkini | B6: Willenskraft | C6: 15 | D6: 27 | E6: 31
A7: Dalkini | B7: Athletik | C7: 10 | D7: 22 | E7: 31
A8: Dalkini | B8: Geschicklichkeit | C8: 10 | D8: 22 | E8: 31
A9: Dalkini | B9: Konstitution | C9: 11 | D9: 23 | E9: 31
A10: Dalkini | B10: Schnelligkeit | C10: 10 | D10: 22 | E10: 31
A11: Dalkini | B11: Staerke | C11: 11 | D11: 23 | E11: 31
A12: Draw | B12: Ausstrahlung | C12: 11 | D12: 23 | E12: 31
A13: Draw | B13: Intelligenz | C13: 12 | D13: 24 | E13: 31
... A111: Zwerge | B111: Staerke | C111: 12 | D111: 24 | E111: 31

Sheet PSI-Zauberstufen
A1: Referenz | B1: Stufe | C1: Erschwerung | D1: MbS | E1: Wirkung | F1: Name | G1: Regeltext | H1: Aurabann | I1: Ziel | J1: Eig. | K1: RW | L1: VD | M1: ED | N1: W.dauer | O1: Erholungszeit EZ in KR | P1: MpZ | Q1: Quelle
A2: psi_telekinetisches_geschoss | B2: 1 | C2: 3 | D2: 10 | E2: W4 | F2: Telekinetisches Geschoss | G2: SP verteilt auf 3 TZ, Opfer wird um SP/2m zurückgeworfen. Körperbeherrschung+Athletik-Probe, um nicht zu stürzen. Auch Gegenstände werden zurückgeworfen. | H2: Kein Aurabann | I2: Aura | J2: Will | K2: (M)*2m | L2: ST sec | M2: sofort | N2: permanent | O2: 5 | P2: St | Q2: PSI_Magie_Zaubertabelle_1_421.xlsx
A3: psi_telekinetisches_geschoss | B3: 2 | C3: 6 | D3: 20 | E3: W6 | F3: Telekinetisches Geschoss | G3: SP verteilt auf 3 TZ, Opfer wird um SP/2m zurückgeworfen. Körperbeherrschung+Athletik-Probe, um nicht zu stürzen. Auch Gegenstände werden zurückgeworfen. | H3: Kein Aurabann | I3: Aura | J3: Will | K3: (M)*2m | L3: ST sec | M3: sofort | N3: permanent | O3: 5 | P3: St | Q3: PSI_Magie_Zaubertabelle_1_421.xlsx
A4: psi_telekinetisches_geschoss | B4: 3 | C4: 9 | D4: 30 | E4: W8 | F4: Telekinetisches Geschoss | G4: SP verteilt auf 3 TZ, Opfer wird um SP/2m zurückgeworfen. Körperbeherrschung+Athletik-Probe, um nicht zu stürzen. Auch Gegenstände werden zurückgeworfen. | H4: Kein Aurabann | I4: Aura | J4: Will | K4: (M)*2m | L4: ST sec | M4: sofort | N4: permanent | O4: 5 | P4: St | Q4: PSI_Magie_Zaubertabelle_1_421.xlsx
A5: psi_telekinetisches_geschoss | B5: 4 | C5: 12 | D5: 40 | E5: W10 | F5: Telekinetisches Geschoss | G5: SP verteilt auf 3 TZ, Opfer wird um SP/2m zurückgeworfen. Körperbeherrschung+Athletik-Probe, um nicht zu stürzen. Auch Gegenstände werden zurückgeworfen. | H5: Kein Aurabann | I5: Aura | J5: Will | K5: (M)*2m | L5: ST sec | M5: sofort | N5: permanent | O5: 5 | P5: St | Q5: PSI_Magie_Zaubertabelle_1_421.xlsx
A6: psi_telekinetisches_geschoss | B6: 5 | C6: 15 | D6: 55 | E6: W12 | F6: Telekinetisches Geschoss | G6: SP verteilt auf 3 TZ, Opfer wird um SP/2m zurückgeworfen. Körperbeherrschung+Athletik-Probe, um nicht zu stürzen. Auch Gegenstände werden zurückgeworfen. | H6: Kein Aurabann | I6: Aura | J6: Will | K6: (M)*2m | L6: ST sec | M6: sofort | N6: permanent | O6: 5 | P6: St | Q6: PSI_Magie_Zaubertabelle_1_421.xlsx
A7: psi_telekinetisches_geschoss | B7: 6 | C7: 20 | D7: 75 | E7: W20 | F7: Telekinetisches Geschoss | G7: SP verteilt auf 3 TZ, Opfer wird um SP/2m zurückgeworfen. Körperbeherrschung+Athletik-Probe, um nicht zu stürzen. Auch Gegenstände werden zurückgeworfen. | H7: Kein Aurabann | I7: Aura | J7: Will | K7: (M)*2m | L7: ST sec | M7: sofort | N7: permanent | O7: 5 | P7: St | Q7: PSI_Magie_Zaubertabelle_1_421.xlsx
A8: psi_telekinetisches_geschoss | B8: 7 | C8: 30 | D8: 100 | E8: W30 | F8: Telekinetisches Geschoss | G8: SP verteilt auf 3 TZ, Opfer wird um SP/2m zurückgeworfen. Körperbeherrschung+Athletik-Probe, um nicht zu stürzen. Auch Gegenstände werden zurückgeworfen. | H8: Kein Aurabann | I8: Aura | J8: Will | K8: (M)*2m | L8: ST sec | M8: sofort | N8: permanent | O8: 5 | P8: St | Q8: PSI_Magie_Zaubertabelle_1_421.xlsx
A9: psi_pyrokinese | B9: 1 | C9: 4 | D9: 10 | E9: 200° | Watte | +200°/s | F9: Pyrokinese | G9: Der Zauber erhitzt eine Kugel mit Radius (M) x 2 mm³. Gegenstände innerhalb der Kugel brennen nur weiter, wenn sie auch natürlich brennen würden. | H9: Aurabann | I9: Gegenstand | J9: Int | K9: (M) x m | L9: 1 | M9: ST sec | N9: ST sec | O9: 15 | P9: St | Q9: PSI_Magie_Zaubertabelle_1_421.xlsx
A10: psi_pyrokinese | B10: 2 | C10: 7 | D10: 20 | E10: 400° | Stoff | +200°/s | F10: Pyrokinese | G10: Der Zauber erhitzt eine Kugel mit Radius (M) x 2 mm³. Gegenstände innerhalb der Kugel brennen nur weiter, wenn sie auch natürlich brennen würden. | H10: Aurabann | I10: Gegenstand | J10: Int | K10: (M) x m | L10: 1 | M10: ST sec | N10: ST sec | O10: 15 | P10: St | Q10: PSI_Magie_Zaubertabelle_1_421.xlsx
A11: psi_pyrokinese | B11: 3 | C11: 10 | D11: 30 | E11: 800° | Holz | +266°/s | F11: Pyrokinese | G11: Der Zauber erhitzt eine Kugel mit Radius (M) x 2 mm³. Gegenstände innerhalb der Kugel brennen nur weiter, wenn sie auch natürlich brennen würden. | H11: Aurabann | I11: Gegenstand | J11: Int | K11: (M) x m | L11: 1 | M11: ST sec | N11: ST sec | O11: 15 | P11: St | Q11: PSI_Magie_Zaubertabelle_1_421.xlsx
A12: psi_pyrokinese | B12: 4 | C12: 14 | D12: 45 | E12: 1000° | Leder | +250°/s | F12: Pyrokinese | G12: Der Zauber erhitzt eine Kugel mit Radius (M) x 2 mm³. Gegenstände innerhalb der Kugel brennen nur weiter, wenn sie auch natürlich brennen würden. | H12: Aurabann | I12: Gegenstand | J12: Int | K12: (M) x m | L12: 1 | M12: ST sec | N12: ST sec | O12: 15 | P12: St | Q12: PSI_Magie_Zaubertabelle_1_421.xlsx
A13: psi_pyrokinese | B13: 5 | C13: 18 | D13: 60 | E13: 1200° | Guss | +240°/s | F13: Pyrokinese | G13: Der Zauber erhitzt eine Kugel mit Radius (M) x 2 mm³. Gegenstände innerhalb der Kugel brennen nur weiter, wenn sie auch natürlich brennen würden. | H13: Aurabann | I13: Gegenstand | J13: Int | K13: (M) x m | L13: 1 | M13: ST sec | N13: ST sec | O13: 15 | P13: St | Q13: PSI_Magie_Zaubertabelle_1_421.xlsx
A14: psi_pyrokinese | B14: 6 | C14: 22 | D14: 80 | E14: 2200° | Stahl | +366°/s | F14: Pyrokinese | G14: Der Zauber erhitzt eine Kugel mit Radius (M) x 2 mm³. Gegenstände innerhalb der Kugel brennen nur weiter, wenn sie auch natürlich brennen würden. | H14: Aurabann | I14: Gegenstand | J14: Int | K14: (M) x m | L14: 1 | M14: ST sec | N14: ST sec | O14: 15 | P14: St | Q14: PSI_Magie_Zaubertabelle_1_421.xlsx
A15: psi_pyrokinese | B15: 7 | C15: 29 | D15: 100 | E15: 3390° | Wolfram | +484°/s | F15: Pyrokinese | G15: Der Zauber erhitzt eine Kugel mit Radius (M) x 2 mm³. Gegenstände innerhalb der Kugel brennen nur weiter, wenn sie auch natürlich brennen würden. | H15: Aurabann | I15: Gegenstand | J15: Int | K15: (M) x m | L15: 1 | M15: ST sec | N15: ST sec | O15: 15 | P15: St | Q15: PSI_Magie_Zaubertabelle_1_421.xlsx
A16: psi_kryokinese | B16: 1 | C16: 4 | D16: 10 | E16: -15° | -15°/s | F16: Kryokinese | G16: Der Zauber erhitzt eine Kugel mit Radius (M) x 2 mm³. Gegenstände innerhalb der Kugel bleiben gefroren, tauen aber natürlich auf. | H16: Aurabann | I16: Gegenstand | J16: Int | K16: (M) x m | L16: 1 | M16: ST sec | N16: ST sec | O16: 10 | P16: St | Q16: PSI_Magie_Zaubertabelle_1_421.xlsx
A17: psi_kryokinese | B17: 2 | C17: 7 | D17: 20 | E17: -40° | -20°/s | F17: Kryokinese | G17: Der Zauber erhitzt eine Kugel mit Radius (M) x 2 mm³. Gegenstände innerhalb der Kugel bleiben gefroren, tauen aber natürlich auf. | H17: Aurabann | I17: Gegenstand | J17: Int | K17: (M) x m | L17: 1 | M17: ST sec | N17: ST sec | O17: 10 | P17: St | Q17: PSI_Magie_Zaubertabelle_1_421.xlsx
A18: psi_kryokinese | B18: 3 | C18: 10 | D18: 30 | E18: -60° | -20°/s | F18: Kryokinese | G18: Der Zauber erhitzt eine Kugel mit Radius (M) x 2 mm³. Gegenstände innerhalb der Kugel bleiben gefroren, tauen aber natürlich auf. | H18: Aurabann | I18: Gegenstand | J18: Int | K18: (M) x m | L18: 1 | M18: ST sec | N18: ST sec | O18: 10 | P18: St | Q18: PSI_Magie_Zaubertabelle_1_421.xlsx
A19: psi_kryokinese | B19: 4 | C19: 14 | D19: 45 | E19: -85° | -21°/s | F19: Kryokinese | G19: Der Zauber erhitzt eine Kugel mit Radius (M) x 2 mm³. Gegenstände innerhalb der Kugel bleiben gefroren, tauen aber natürlich auf. | H19: Aurabann | I19: Gegenstand | J19: Int | K19: (M) x m | L19: 1 | M19: ST sec | N19: ST sec | O19: 10 | P19: St | Q19: PSI_Magie_Zaubertabelle_1_421.xlsx
A20: psi_kryokinese | B20: 5 | C20: 18 | D20: 60 | E20: -110° | -22°/s | F20: Kryokinese | G20: Der Zauber erhitzt eine Kugel mit Radius (M) x 2 mm³. Gegenstände innerhalb der Kugel bleiben gefroren, tauen aber natürlich auf. | H20: Aurabann | I20: Gegenstand | J20: Int | K20: (M) x m | L20: 1 | M20: ST sec | N20: ST sec | O20: 10 | P20: St | Q20: PSI_Magie_Zaubertabelle_1_421.xlsx
... A29: psi_destruktion | B29: 7 | C29: 23 | D29: 115 | E29: Diamant | F29: Destruktion | G29: Auf 1 Unbel. Geg/ nur kleinere Dinge, Bei großen =ST+1. Bei Fremdaura FK-TZW | H29: Kein Aurabann | I29: Aura | J29: Will | K29: (M)*m | L29: 1 | M29: sofort | N29: permanent | O29: 20 | P29: St*5 | Q29: PSI_Magie_Zaubertabelle_1_421.xlsx
A30: psi_geschosse_ablenken | B30: 1 | C30: 2 | D30: 7 | F30: Geschosse ablenken | G30: Der Magus kann Geschosse ablenken, die er sieht oder deren Abwurf/Abschuss/Mündungsfeuer er gesehen hat. Die AW oder Glück-Probe ist um ST x 3 erleichtert. | H30: Kein Aurabann | I30: Selbst | J30: Sch | K30: Selbst | L30: 1 | M30: sofort | N30: permanent | O30: 2 | P30: St*5 | Q30: PSI_Magie_Zaubertabelle_1_421.xlsx
A31: psi_geschosse_ablenken | B31: 2 | C31: 5 | D31: 14 | F31: Geschosse ablenken | G31: Der Magus kann Geschosse ablenken, die er sieht oder deren Abwurf/Abschuss/Mündungsfeuer er gesehen hat. Die AW oder Glück-Probe ist um ST x 3 erleichtert. | H31: Kein Aurabann | I31: Selbst | J31: Sch | K31: Selbst | L31: 1 | M31: sofort | N31: permanent | O31: 2 | P31: St*5 | Q31: PSI_Magie_Zaubertabelle_1_421.xlsx
A32: psi_geschosse_ablenken | B32: 3 | C32: 8 | D32: 21 | F32: Geschosse ablenken | G32: Der Magus kann Geschosse ablenken, die er sieht oder deren Abwurf/Abschuss/Mündungsfeuer er gesehen hat. Die AW oder Glück-Probe ist um ST x 3 erleichtert. | H32: Kein Aurabann | I32: Selbst | J32: Sch | K32: Selbst | L32: 1 | M32: sofort | N32: permanent | O32: 2 | P32: St*5 | Q32: PSI_Magie_Zaubertabelle_1_421.xlsx
A33: psi_geschosse_ablenken | B33: 4 | C33: 11 | D33: 28 | F33: Geschosse ablenken | G33: Der Magus kann Geschosse ablenken, die er sieht oder deren Abwurf/Abschuss/Mündungsfeuer er gesehen hat. Die AW oder Glück-Probe ist um ST x 3 erleichtert. | H33: Kein Aurabann | I33: Selbst | J33: Sch | K33: Selbst | L33: 1 | M33: sofort | N33: permanent | O33: 2 | P33: St*5 | Q33: PSI_Magie_Zaubertabelle_1_421.xlsx
A34: psi_geschosse_ablenken | B34: 5 | C34: 14 | D34: 35 | F34: Geschosse ablenken | G34: Der Magus kann Geschosse ablenken, die er sieht oder deren Abwurf/Abschuss/Mündungsfeuer er gesehen hat. Die AW oder Glück-Probe ist um ST x 3 erleichtert. | H34: Kein Aurabann | I34: Selbst | J34: Sch | K34: Selbst | L34: 1 | M34: sofort | N34: permanent | O34: 2 | P34: St*5 | Q34: PSI_Magie_Zaubertabelle_1_421.xlsx
A35: psi_geschosse_ablenken | B35: 6 | C35: 17 | D35: 92 | F35: Geschosse ablenken | G35: Der Magus kann Geschosse ablenken, die er sieht oder deren Abwurf/Abschuss/Mündungsfeuer er gesehen hat. Die AW oder Glück-Probe ist um ST x 3 erleichtert. | H35: Kein Aurabann | I35: Selbst | J35: Sch | K35: Selbst | L35: 1 | M35: sofort | N35: permanent | O35: 2 | P35: St*5 | Q35: PSI_Magie_Zaubertabelle_1_421.xlsx
A36: psi_geschosse_ablenken | B36: 7 | C36: 20 | D36: 145 | F36: Geschosse ablenken | G36: Der Magus kann Geschosse ablenken, die er sieht oder deren Abwurf/Abschuss/Mündungsfeuer er gesehen hat. Die AW oder Glück-Probe ist um ST x 3 erleichtert. | H36: Kein Aurabann | I36: Selbst | J36: Sch | K36: Selbst | L36: 1 | M36: sofort | N36: permanent | O36: 2 | P36: St*5 | Q36: PSI_Magie_Zaubertabelle_1_421.xlsx
A37: psi_empathie | B37: 1 | C37: 1 | D37: 5 | F37: Empathie | G37: Der Zauberer bekommt St*2 Punkte und kann sie frei nach der unten gewählten Tabelle einsetzen: 14 Punkte = 1 gesehene Person Gesinnungsbogen Scannen 1 Punkt = 60° zusätzlicher Sichtwinkel 1 Punkt = Personen vorhanden, ja oder nein 3 Punkte = Personen Vorhanden, ja nein; ungefähre Anzahl 5 Punkte = Personen Vorhanden, ja nein; genaue Anzahl 7 Punkte = Personen Vorhanden, ja nein; genaue Anzahl; ungefähre Position 9 Punkte = Personen Vorhanden, ja nein; genaue Anzahl; genaue Position 11 Punkte = Personen Vorhanden, ja/nein; genaue Anzahl; genaue Position; Tier und Mensch unterscheiden. (genaue Position ist +/- 1m) | H37: Kein Aurabann | I37: Aura | J37: Will | K37: (M)*2m | L37: 1 | M37: sofort | N37: (M) sec | O37: 5 | P37: St | Q37: PSI_Magie_Zaubertabelle_1_421.xlsx
A38: psi_empathie | B38: 2 | C38: 4 | D38: 10 | F38: Empathie | G38: Der Zauberer bekommt St*2 Punkte und kann sie frei nach der unten gewählten Tabelle einsetzen: 14 Punkte = 1 gesehene Person Gesinnungsbogen Scannen 1 Punkt = 60° zusätzlicher Sichtwinkel 1 Punkt = Personen vorhanden, ja oder nein 3 Punkte = Personen Vorhanden, ja nein; ungefähre Anzahl 5 Punkte = Personen Vorhanden, ja nein; genaue Anzahl 7 Punkte = Personen Vorhanden, ja nein; genaue Anzahl; ungefähre Position 9 Punkte = Personen Vorhanden, ja nein; genaue Anzahl; genaue Position 11 Punkte = Personen Vorhanden, ja/nein; genaue Anzahl; genaue Position; Tier und Mensch unterscheiden. (genaue Position ist +/- 1m) | H38: Kein Aurabann | I38: Aura | J38: Will | K38: (M)*2m | L38: 1 | M38: sofort | N38: (M) sec | O38: 5 | P38: St | Q38: PSI_Magie_Zaubertabelle_1_421.xlsx
A39: psi_empathie | B39: 3 | C39: 7 | D39: 20 | F39: Empathie | G39: Der Zauberer bekommt St*2 Punkte und kann sie frei nach der unten gewählten Tabelle einsetzen: 14 Punkte = 1 gesehene Person Gesinnungsbogen Scannen 1 Punkt = 60° zusätzlicher Sichtwinkel 1 Punkt = Personen vorhanden, ja oder nein 3 Punkte = Personen Vorhanden, ja nein; ungefähre Anzahl 5 Punkte = Personen Vorhanden, ja nein; genaue Anzahl 7 Punkte = Personen Vorhanden, ja nein; genaue Anzahl; ungefähre Position 9 Punkte = Personen Vorhanden, ja nein; genaue Anzahl; genaue Position 11 Punkte = Personen Vorhanden, ja/nein; genaue Anzahl; genaue Position; Tier und Mensch unterscheiden. (genaue Position ist +/- 1m) | H39: Kein Aurabann | I39: Aura | J39: Will | K39: (M)*2m | L39: 1 | M39: sofort | N39: (M) sec | O39: 5 | P39: St | Q39: PSI_Magie_Zaubertabelle_1_421.xlsx
A40: psi_empathie | B40: 4 | C40: 10 | D40: 30 | F40: Empathie | G40: Der Zauberer bekommt St*2 Punkte und kann sie frei nach der unten gewählten Tabelle einsetzen: 14 Punkte = 1 gesehene Person Gesinnungsbogen Scannen 1 Punkt = 60° zusätzlicher Sichtwinkel 1 Punkt = Personen vorhanden, ja oder nein 3 Punkte = Personen Vorhanden, ja nein; ungefähre Anzahl 5 Punkte = Personen Vorhanden, ja nein; genaue Anzahl 7 Punkte = Personen Vorhanden, ja nein; genaue Anzahl; ungefähre Position 9 Punkte = Personen Vorhanden, ja nein; genaue Anzahl; genaue Position 11 Punkte = Personen Vorhanden, ja/nein; genaue Anzahl; genaue Position; Tier und Mensch unterscheiden. (genaue Position ist +/- 1m) | H40: Kein Aurabann | I40: Aura | J40: Will | K40: (M)*2m | L40: 1 | M40: sofort | N40: (M) sec | O40: 5 | P40: St | Q40: PSI_Magie_Zaubertabelle_1_421.xlsx
A41: psi_empathie | B41: 5 | C41: 13 | D41: 35 | F41: Empathie | G41: Der Zauberer bekommt St*2 Punkte und kann sie frei nach der unten gewählten Tabelle einsetzen: 14 Punkte = 1 gesehene Person Gesinnungsbogen Scannen 1 Punkt = 60° zusätzlicher Sichtwinkel 1 Punkt = Personen vorhanden, ja oder nein 3 Punkte = Personen Vorhanden, ja nein; ungefähre Anzahl 5 Punkte = Personen Vorhanden, ja nein; genaue Anzahl 7 Punkte = Personen Vorhanden, ja nein; genaue Anzahl; ungefähre Position 9 Punkte = Personen Vorhanden, ja nein; genaue Anzahl; genaue Position 11 Punkte = Personen Vorhanden, ja/nein; genaue Anzahl; genaue Position; Tier und Mensch unterscheiden. (genaue Position ist +/- 1m) | H41: Kein Aurabann | I41: Aura | J41: Will | K41: (M)*2m | L41: 1 | M41: sofort | N41: (M) sec | O41: 5 | P41: St | Q41: PSI_Magie_Zaubertabelle_1_421.xlsx
... A106: psi_hoehere_telekinese | B106: 7 | C106: 29 | D106: 150 | F106: Höhere Telekinese | G106: 1 Gegenstand / Nur Unbelebtes/ Aurabann St³ x kg oder Liter/ max. 10m/sec. | H106: Aurabann | I106: Gegenstand | J106: Will | K106: (M)*m | L106: 1 | M106: sofort | N106: (M) min | O106: 20 | P106: St*2 | Q106: PSI_Magie_Zaubertabelle_1_421.xlsx

Sheet KI-Baum-Kanten
A1: Faehigkeit | B1: Vorbedingung | C1: Mindest-TaW
A2: ki_abhaertung | B2: ki_konzentration | C2: 10
A3: ki_dauerlauf | B3: ki_konzentration | C3: 10
A4: ki_ewige_erinnerung | B4: ki_konzentration | C4: 10
A5: ki_froschlunge | B5: ki_konzentration | C5: 10
A6: ki_katzenauge | B6: ki_konzentration | C6: 10
A7: ki_heilender_schlaf | B7: ki_konzentration | C7: 10
A8: ki_ki_schutz | B8: ki_abhaertung | C8: 10
A9: ki_sprint | B9: ki_dauerlauf | C9: 10
A10: ki_kraftakt | B10: ki_froschlunge | C10: 10
A11: ki_fledermausohr_aalnase | B11: ki_katzenauge | C11: 10
A12: ki_erleuchtung | B12: ki_ewige_erinnerung | C12: 10
A13: ki_abwehr | B13: ki_ki_schutz | C13: 15
... A31: ki_konterattacke | B31: ki_paradeserie | C31: 30

Sheet Preisliste
A1: Art | B1: Name | C1: Anzahl | D1: Einheit | E1: Gewicht in kg | F1: Dublonen | H1: WHK | I1: Spezialisierung
A2: Reittiere | B2: Drache, Flug | C2: 1 | D2: Stück | E2: XXX | F2: ------ | G2: Selten | H2: Abrichten | I2: Drache
A3: Reittiere | B3: Greif, Flug | C3: 1 | D3: Stück | E3: XXX | F3: ------ | G3: Selten | H3: Abrichten | I3: Greife
A4: Reittiere | B4: Chocobo, Abgeh, | C4: 1 | D4: Stück | E4: XXX | F4: 470 | G4: Elf | H4: Abrichten | I4: Laufvogel
A5: Reittiere | B5: Chocobo, Alt | C5: 1 | D5: Stück | E5: XXX | F5: 282 | G5: Elf | H5: Abrichten | I5: Laufvogel
A6: Reittiere | B6: Chocobo, Reit | C6: 1 | D6: Stück | E6: XXX | F6: 750 | G6: Elf | H6: Abrichten | I6: Laufvogel
A7: Reittiere | B7: Chocobo, Schlacht | C7: 1 | D7: Stück | E7: XXX | F7: 2250 | G7: Elf | H7: Abrichten | I7: Laufvogel
A8: Reittiere | B8: Chocobo, Vollblut | C8: 1 | D8: Stück | E8: XXX | F8: 3380 | G8: Elf | H8: Abrichten | I8: Laufvogel
A9: Reittiere | B9: Pegasus, Flug | C9: 1 | D9: Stück | E9: XXX | F9: ------ | G9: Selten | H9: Abrichten | I9: Pegasus
A10: Reittiere | B10: Pferd, Abgehalftert | C10: 1 | D10: Stück | E10: XXX | F10: 250 | G10: Indianer, Dalkini | H10: Abrichten | I10: Pferd
A11: Reittiere | B11: Pferd, Alter Gaul | C11: 1 | D11: Stück | E11: XXX | F11: 150 | G11: Indianer, Dalkini | H11: Abrichten | I11: Pferd
A12: Reittiere | B12: Pferd, Reit | C12: 1 | D12: Stück | E12: XXX | F12: 400 | G12: Indianer, Dalkini | H12: Abrichten | I12: Pferd
A13: Reittiere | B13: Pferd, Schlachtross | C13: 1 | D13: Stück | E13: XXX | F13: 1200 | G13: Indianer, Dalkini | H13: Abrichten | I13: Pferd
A14: Reittiere | B14: Pferd, Vollblut | C14: 1 | D14: Stück | E14: XXX | F14: 1800 | G14: Indianer, Dalkini | H14: Abrichten | I14: Pferd
A15: Reittiere | B15: Ratte, Abgehalftert | C15: 1 | D15: Stück | E15: XXX | F15: 190 | G15: Goblin | H15: Abrichten | I15: Ratte
A16: Reittiere | B16: Ratte, Alt | C16: 1 | D16: Stück | E16: XXX | F16: 115 | G16: Goblin | H16: Abrichten | I16: Ratte
A17: Reittiere | B17: Ratte, Gefährlich | C17: 1 | D17: Stück | E17: XXX | F17: 1350 | G17: Goblin | H17: Abrichten | I17: Ratte
A18: Reittiere | B18: Ratte, Reit | C18: 1 | D18: Stück | E18: XXX | F18: 300 | G18: Goblin | H18: Abrichten | I18: Ratte
A19: Reittiere | B19: Ratte, Schlacht | C19: 1 | D19: Stück | E19: XXX | F19: 900 | G19: Goblin | H19: Abrichten | I19: Ratte
A20: Reittiere | B20: Assel, Abgehalftert | C20: 1 | D20: Stück | E20: XXX | F20: 282 | G20: Zwerg | H20: Abrichten | I20: Reitkrebse
A21: Reittiere | B21: Assel, Alt | C21: 1 | D21: Stück | E21: XXX | F21: 169 | G21: Zwerg | H21: Abrichten | I21: Reitkrebse
... A37: Reittiere | B37: Schildkröte, Schnell | C37: 1 | D37: Stück | E37: XXX | F37: 4500 | G37: Gnom | H37: Abrichten | I37: Reitreptilien
A38: Reittiere | B38: Roc, Flug | C38: 1 | D38: Stück | E38: XXX | F38: ------ | G38: Selten | H38: Abrichten | I38: Rok
A39: Reittiere | B39: Rollok, abgehalftert | C39: 1 | D39: Stück | E39: XXX | F39: 532 | G39: Troll | H39: Abrichten | I39: Rollok
A40: Reittiere | B40: Rollok, alt | C40: 1 | D40: Stück | E40: XXX | F40: 319 | G40: Troll | H40: Abrichten | I40: Rollok
A41: Reittiere | B41: Rollok, Reit | C41: 1 | D41: Stück | E41: XXX | F41: 850 | G41: Troll | H41: Abrichten | I41: Rollok
A42: Reittiere | B42: Rollok, Schlacht | C42: 1 | D42: Stück | E42: XXX | F42: 2550 | G42: Troll | H42: Abrichten | I42: Rollok
A43: Reittiere | B43: Rollok, übellaunig | C43: 1 | D43: Stück | E43: XXX | F43: 3850 | G43: Troll | H43: Abrichten | I43: Rollok
A44: Reittiere | B44: Warg, Abgehalftert | C44: 1 | D44: Stück | E44: XXX | F44: 375 | G44: Ork | H44: Abrichten | I44: Warg
A45: Reittiere | B45: Warg, Alt | C45: 1 | D45: Stück | E45: XXX | F45: 225 | G45: Ork | H45: Abrichten | I45: Warg
A46: Reittiere | B46: Warg, Elite | C46: 1 | D46: Stück | E46: XXX | F46: 2700 | G46: Ork | H46: Abrichten | I46: Warg
A47: Reittiere | B47: Warg, Reit | C47: 1 | D47: Stück | E47: XXX | F47: 600 | G47: Ork | H47: Abrichten | I47: Warg
A48: Reittiere | B48: Warg, Schlacht | C48: 1 | D48: Stück | E48: XXX | F48: 1800 | G48: Ork | H48: Abrichten | I48: Warg
A49: Alchemistische Stoffe | B49: Öl, Brand- | C49: 1 | D49: Fass | E49: 5 | F49: 35 | H49: Alchemie | I49: Brandbeschleuniger
A50: Alchemistische Stoffe | B50: Schwarzpulver | C50: 1 | D50: Sack | E50: 1 | F50: 85 | H50: Alchemie | I50: Brandbeschleuniger
A51: Alchemistische Stoffe | B51: Zwergisches Feuer | C51: 1 | D51: Flasche | E51: 1 | F51: 500 | H51: Alchemie | I51: Brandbeschleuniger
A52: Beleuchtung | B52: Streichhölzer 25St, | C52: 1 | D52: Schachtel | E52: 0.2 | F52: 1 | H52: Alchemie | I52: Brandbeschleuniger
A53: Alchemistische Stoffe | B53: Orazal (Lösung) | C53: 1 | D53: Bund | E53: 0.002 | F53: 92 | H53: Alchemie | I53: DSA-Material
A54: Schreibwaren | B54: Tinte | C54: 1 | D54: Phiole | E54: 0.1 | F54: 0.98 | H54: Alchemie | I54: Farbstoffe
A55: Schreibwaren | B55: Tusche | C55: 1 | D55: Phiole | E55: 0.1 | F55: 1.3 | H55: Alchemie | I55: Farbstoffe
...

Sheet Alchemika
A1: Kategorie | B1: magisch_y_n | C1: Name | D1: Potenz | E1: Dosierbar | F1: Zufuhr | G1: ZbS (Zeit bis Symptom) | H1: ZbW (Zeit bis Wirkung) | I1: Wirkungsdauer | J1: Wirkung | K1: Legalität | L1: Char_Unterwelt_Mod | M1: Verfügb | N1: Zutaten_Preis_in_D | O1: Kaufpreis_in_D | P1: Rezept-Erschwerung
A2: Gifte | B2: profan | C2: Leichtes Regigift | D2: 5 | E2: J | F2: Körper | G2: Sofort | H2: Sofort | I2: 12h | J2: Regenerationsklasse -2, leichter Schlaf | K2: 3 | L2: 0 | M2: 1 | N2: 0.25 | O2: =N2*(K2+L2) -> 0.75 | P2: 4
A3: Gifte | B3: profan | C3: Regigift | D3: 15 | E3: J | F3: Körper | G3: Sofort | H3: Sofort | I3: 12h | J3: Regenerationsklasse -4, leichter Schlaf | K3: 4 | L3: 0 | M3: 2 | N3: 0.5 | O3: =N3*(K3+L3) -> 2 | P3: 6
A4: Gifte | B4: profan | C4: Starkes Regigift | D4: 30 | E4: J | F4: Körper | G4: Sofort | H4: Sofort | I4: 12h | J4: Regenerationsklasse -7, leichter Schlaf | K4: 5 | L4: 0 | M4: 3 | N4: 1 | O4: =N4*(K4+L4) -> 5 | P4: 10
A5: Gifte | B5: profan | C5: Hässlichkeitsgift | D5: 15 | E5: J | F5: Körper | G5: Sofort | H5: Sofort | I5: 1d | J5: Alle Grundfertigkeits-, Sprach-, Kulur- und WHK-Proben auf Ausstrahlung um 10 erschwert | K5: 4 | L5: 0 | M5: 5 | N5: 50 | O5: =N5*(K5+L5) -> 200 | P5: 30
A6: Gifte | B6: profan | C6: Starkes Hässlichkeitsgift | D6: 30 | E6: J | F6: Körper | G6: Sofort | H6: Sofort | I6: 1d | J6: Alle Grundfertigkeits-, Sprach-, Kulur- und WHK-Proben auf Ausstrahlung um 15 erschwert | K6: 5 | L6: 0 | M6: 6 | N6: 150 | O6: =N6*(K6+L6) -> 750 | P6: 48
A7: Gifte | B7: profan | C7: Leichtes Hässlichkeitsgift | D7: 5 | E7: J | F7: Körper | G7: Sofort | H7: Sofort | I7: 1d | J7: Alle Grundfertigkeits-, Sprach-, Kulur- und WHK-Proben auf Ausstrahlung um 5 erschwert | K7: 3 | L7: 0 | M7: 4 | N7: 25 | O7: =N7*(K7+L7) -> 75 | P7: 18
A8: Gifte | B8: profan | C8: Leichtes Zungengift | D8: 5 | E8: J | F8: Körper | G8: 1 KR | H8: 3 KR | I8: 1h | J8: Artikuliertes Sprechen unmöglich | K8: 2 | L8: 0 | M8: 2 | N8: 1 | O8: =N8*(K8+L8) -> 2 | P8: 12
A9: Gifte | B9: profan | C9: Zungengift | D9: 15 | E9: J | F9: Körper | G9: 1 KR | H9: 3 KR | I9: 1h | J9: Artikuliertes Sprechen unmöglich | K9: 3 | L9: 0 | M9: 3 | N9: 2 | O9: =N9*(K9+L9) -> 6 | P9: 18
A10: Gifte | B10: profan | C10: Starkes Zungengift | D10: 30 | E10: J | F10: Körper | G10: 1 KR | H10: 3 KR | I10: 1h | J10: Artikuliertes Sprechen unmöglich | K10: 4 | L10: 0 | M10: 4 | N10: 4 | O10: =N10*(K10+L10) -> 16 | P10: 30
A11: Gifte | B11: profan | C11: Leichtes Taubheitsgift | D11: 5 | E11: J | F11: Körper | G11: 1 KR | H11: 3 KR | I11: 1h | J11: BE 2, Gefahrensinn -12 | K11: 2 | L11: 0 | M11: 2 | N11: 1 | O11: =N11*(K11+L11) -> 2 | P11: 12
A12: Gifte | B12: profan | C12: Taubheitsgift | D12: 15 | E12: J | F12: Körper | G12: 1 KR | H12: 3 KR | I12: 1h | J12: BE 2, Gefahrensinn -12 | K12: 3 | L12: 0 | M12: 3 | N12: 2 | O12: =N12*(K12+L12) -> 6 | P12: 18
A13: Gifte | B13: profan | C13: Starkes Taubheitsgift | D13: 30 | E13: J | F13: Körper | G13: 1 KR | H13: 3 KR | I13: 1h | J13: BE 2, Gefahrensinn -12 | K13: 4 | L13: 0 | M13: 4 | N13: 4 | O13: =N13*(K13+L13) -> 16 | P13: 30
... A119: Zustandstränke | B119: profan | C119: Geruchslossalbe | D119: 75 | E119: N | F119: Kontakt | G119: 2 KR | H119: 5 KR | I119: 6h | J119: Man verliert seinen Geruch komplett | K119: 2 | L119: 0 | M119: 5 | N119: 25 | O119: =N119*(K119+L119) -> 50 | P119: 12

Sheet Ruestungstabelle
B1: Kopf | C1: Verarbeitung | D1: Anpassung | E1: RS | F1: BE | G1: Preis | H1: NW | I1: AW
A2: Lage 1 | B2: Stoffrüstung | C2: Meisterarbeit | D2: angepasst | E2: 3 | F2: 1 | G2: 227 | H2: 3 | I2: 2
A3: Lage 2 | B3: Leichte Lederrüstung | C3: Meisterarbeit | D3: angepasst | E3: 4 | F3: 2 | G3: 274 | H3: 3 | I3: 2
A4: Lage 3 | B4: Stahl-Kettenpanzer | C4: Meisterarbeit | D4: angepasst | E4: 6 | F4: 3 | G4: 1830 | H4: 3 | I4: 2
A5: Lage 4 | B5: Schwerer Lederpanzer | C5: Meisterarbeit | D5: angepasst | E5: 6 | F5: 4 | G5: 562 | H5: 3 | I5: 2
A6: Lage 5 | B6: Keine Rüstung | E6: 0 | F6: 0 | G6: 0 | H6: 0 | I6: 0
C7: Kopf | D7: Gesamt: | E7: 19 | F7: 10 | G7: 2893
B8: Torso | C8: Verarbeitung | D8: Anpassung | E8: RS | F8: BE | G8: Preis | H8: NW | I8: AW
A9: Lage 1 | B9: Stoffrüstung | C9: Großmeisterarbeit | D9: perfekt angepasst | E9: 4 | F9: 1 | G9: 387 | H9: 5 | I9: 3
A10: Lage 2 | B10: Leichte Lederrüstung | C10: Gesellenarbeit | D10: angepasst | E10: 3 | F10: 2 | G10: 38 | H10: 3 | I10: 2
A11: Lage 3 | B11: Eisen-Kettenpanzer | C11: Gesellenarbeit | D11: angepasst | E11: 4 | F11: 3 | G11: 372 | H11: 3 | I11: 2
A12: Lage 4 | B12: Schwerer Faltstahlpanzer | C12: Einzelstück | D12: perfekt angepasst | E12: 14 | F12: 7 | G12: 6495 | H12: 7 | I12: 7
A13: Lage 5 | B13: Keine Rüstung | E13: 0 | F13: 0 | G13: 0 | H13: 0 | I13: 0
C14: Torso | D14: Gesamt: | E14: 25 | F14: 13 | G14: 7292
B15: Arme | C15: Verarbeitung | D15: Anpassung | E15: RS | F15: BE | G15: Preis | H15: NW | I15: AW
A16: Lage 1 | B16: Stoffrüstung | C16: Gesellenarbeit | D16: angepasst | E16: 2 | F16: 1 | G16: 50 | H16: 3 | I16: 2
A17: Lage 2 | B17: Leichte Lederrüstung | C17: Gesellenarbeit | D17: angepasst | E17: 3 | F17: 2 | G17: 38 | H17: 3 | I17: 2
A18: Lage 3 | B18: Eisen-Kettenpanzer | C18: Gesellenarbeit | D18: angepasst | E18: 4 | F18: 3 | G18: 372 | H18: 3 | I18: 2
A19: Lage 4 | B19: Schwerer Lederpanzer | C19: Gesellenarbeit | D19: angepasst | E19: 5 | F19: 4 | G19: 208 | H19: 3 | I19: 2
A20: Lage 5 | B20: Keine Rüstung | E20: 0 | F20: 0 | G20: 0 | H20: 0 | I20: 0
C21: Arme | D21: Gesamt: | E21: 14 | F21: 10 | G21: 668
B22: Beine | C22: Verarbeitung | D22: Anpassung | E22: RS | F22: BE | G22: Preis | H22: NW | I22: AW
A23: Lage 1 | B23: Stoffrüstung | C23: Gesellenarbeit | D23: angepasst | E23: 2 | F23: 1 | G23: 50 | H23: 3 | I23: 2
A24: Lage 2 | B24: Leichte Lederrüstung | C24: Gesellenarbeit | D24: angepasst | E24: 3 | F24: 2 | G24: 38 | H24: 3 | I24: 2
A25: Lage 3 | B25: Eisen-Kettenpanzer | C25: Gesellenarbeit | D25: angepasst | E25: 4 | F25: 3 | G25: 372 | H25: 3 | I25: 2
A26: Lage 4 | B26: Schwerer Lederpanzer | C26: Gesellenarbeit | D26: angepasst | E26: 5 | F26: 4 | G26: 208 | H26: 3 | I26: 2
A27: Lage 5 | B27: Keine Rüstung | E27: 0 | F27: 0 | G27: 0 | H27: 0 | I27: 0
C28: Beine | D28: Gesamt: | E28: 14 | F28: 10 | G28: 668
F29: BE | G29: Preis
C30: Rüstung | D30: Gesamt: | F30: 43 | G30: 11521
A31: Legende:
A32: Hals, Schultergelenk, Ellenbogen, Hände, Knie und Füße werden nur mit halbem RS geschützt. Augen werden nicht geschützt.Für alle nicht genannten kritischen Trefferzonen gilt der volle Rüstungswert.
A33: Jedes Rüstungsteil kann durch Verarbeitung und Anpassung einmalig modifiziert werden.
A34: Jedes Rüstungsteil hat seine Lage als Mindest-RBE. Lage 5 (Umhänge, Aufpanzerungen) sind hiervon ausgenommen.
A35: Drachenschuppen und andere Aufpanzerungen verfügen über bestimmte Boni, die derzeit noch in der alten Waffentabelle aufgeführt sind...
A36: Rüstung | B36: Lage | C36: RS | D36: BE | F36: Verfügbarkeit NW | G36: Verfügbarkeit AW | H36: Materialkosten | I36: Arbeitszeit/d
A37: Keine Rüstung
A38: Leichte Stoffrüstung | B38: 1 | C38: 1 | D38: 1 | F38: 1 | G38: 1 | H38: 16 | I38: 1
A39: Stoffrüstung | B39: 1 | C39: 2 | D39: 2 | F39: 1 | G39: 1 | H39: 32 | I39: 1
A40: Schwere Stoffrüstung | B40: 1 | C40: 3 | D40: 3 | F40: 1 | G40: 1 | H40: 48 | I40: 1
...

Sheet NK-Material
A1: Waffe | B1: Stä-Malus | C1: AT- | D1: PA- | E1: WK | F1: 1H min.Stä | G1: 2H min.Stä | H1: Preis | I1: Klingen-Brecher | J1: Klingen-Schutz | L1: Art/Specials | M1: Rezept-Mod | N1: Verfuegbarkeit-AW | O1: Verfuegbarkeit-NW
A2: Eisen | F2: 1 | G2: 1 | H2: 50 | K2: Dalkini, Draw, Elfen, Goblins, Orks, Trolle, Zentauren, Zwerge | M2: 10 | N2: 1 | O2: 1
A3: Stahl | B3: 1 | D3: 1 | E3: -0.5 | F3: 0.9 | G3: 0.9 | H3: 125 | I3: 1 | J3: 1 | K3: Dalkini, Draw, Elfen, Goblins, Orks, Trolle, Zwerge | M3: 12 | N3: 1 | O3: 2
A4: Qualitätsstahl | B4: 1 | D4: 1 | E4: -0.5 | F4: 0.9 | G4: 0.9 | H4: 175 | I4: 2 | J4: 2 | K4: Dalkini, Draw, Elfen, Goblins, Orks, Zwerge | M4: 18 | N4: 2 | O4: 4
A5: Faltstahl | B5: 2 | D5: 1 | E5: -0.5 | F5: 0.8 | G5: 0.8 | H5: 250 | I5: 3 | J5: 3 | K5: Dalkini, Draw, Elfen, Goblins, Orks, Zwerge | M5: 30 | N5: 3 | O5: 5
A6: Mithril | B6: -1 | D6: 2 | E6: -2 | F6: 0.5 | G6: 0.5 | H6: 1250 | I6: 0 | J6: 2 | K6: Elfen, Zwerge | M6: 20 | N6: 7 | O6: 7
A7: Kolharz | B7: -1 | C7: 1 | D7: 2 | E7: -1 | F7: 0.5 | G7: 0.5 | H7: 1500 | I7: 0 | J7: 0 | K7: Zentauren | M7: 5 | N7: 5 | O7: 7
A8: Alchemistensilber | B8: 0 | C8: -1 | F8: 1 | G8: 1 | H8: 1500 | I8: -1 | J8: -1 | K8: Dalkini, Elfen, Goblins, Orks, Zwerge | M8: 8 | N8: 5 | O8: 6
A9: Nasium | B9: 0 | C9: -1 | D9: -1 | E9: -1 | F9: 1.2 | G9: 1.2 | H9: 1500 | I9: -1 | J9: -1 | K9: Elfen, Zwerge | M9: 7 | N9: 7 | O9: 7
A10: Diamantspat | B10: 3 | D10: 1 | E10: -0.5 | F10: 0.8 | G10: 0.8 | H10: 88 | I10: 3 | J10: 3 | K10: Draw | L10: Zerfällt bei kontakt mit Sonnenlicht zu Staub | M10: 12 | N10: 7 | O10: 7
A11: Adamandit | B11: 3 | D11: 1 | E11: -0.5 | F11: 0.8 | G11: 0.8 | H11: 250000 | I11: 3 | J11: 6 | K11: Draw, Elfen, Goblins, Orks, Zwerge | M11: 120 | N11: M | O11: M
A12: Holz | B12: -3 | C12: 2 | D12: 2 | E12: -1.5 | F12: 0.5 | G12: 0.5 | H12: 0.1 | I12: -11 | J12: -7 | K12: ALLE | M12: 0 | N12: 1 | O12: 1
A13: Knochen | B13: 0 | C13: 1 | D13: 2 | E13: -1 | F13: 0.5 | G13: 0.5 | H13: 0.1 | I13: -4 | J13: -5 | K13: ALLE | M13: 2 | N13: 1 | O13: 1
A14: Stein | B14: 0 | C14: -3 | D14: -2 | E14: 1 | F14: 1.3 | G14: 1.3 | H14: 0.1 | I14: -2 | J14: -3 | K14: Indianer | M14: 5 | N14: 1 | O14: 1
A15: Schwarzfels | B15: 0 | C15: -2 | D15: -1 | E15: 1 | F15: 1.1 | G15: 1.1 | H15: 0.25 | I15: -2 | J15: -2 | K15: Indianer, Katzen | M15: 4 | N15: 5 | O15: 1
A16: Leder | B16: 0 | E16: 0 | F16: 1 | G16: 1 | H16: 0.3 | K16: ALLE | M16: 5 | N16: 1 | O16: 1
