Workbook
Name test1: #REF!
Name test2: #REF!

Sheet Werte
A1: Referenz | B1: Kategorie | C1: Beschreibung | D1: Abkürzung | E1: Info | F1: Parent | G1: Art | H1: Formel | I1: Pool | J1: Flag | K1: Grad | L1: Kosten | M1: Verfuegbarkeit | O1: Mindest-TaW | P1: Eig-Bonus | Q1: Wirkung
A2: spruchmagie_erdbeschwoerung_1_splitterwand | B2: Spruchmagie | C2: Splitterwand | F2: Erdbeschwörung | G2: Wert | J2: ACHTUNG: In der Quelle (NN_Spruchmagie_0.57) gibt es mehrere Zeilen mit gleichem Schule+Grad+Name aber abweichendem Wirkungstext (vermutlich alte+neue Version nebeneinander stehen geblieben) - hier wurde die letzte Version uebernommen, bitte pruefen. | K2: 1 | L2: WENN(wert=0;0;10+(wert-1)*grad) | P2: eig_bonus_k_staerke | Q2: Der Magier erschafft eine Wand aus Erde. Die Wahrnehmung durch diese Wand ist stark erschwert bis unmöglich: Alle FK-Attacken sind um Aura*2 erschwert. Wer versucht, die Wand zu durchdringen, erleidet Elementarschaden auf jeder TZ. Während der Effektdauer entfaltet die Wand nur die halbe Wirkung. Schaden: W4+Magie, RB 6 auf jede TZ.
A3: spruchmagie_erdbeschwoerung_2_splitterstrahl | B3: Spruchmagie | C3: Splitterstrahl | F3: Erdbeschwörung | G3: Wert | J3: ACHTUNG: In der Quelle (NN_Spruchmagie_0.57) gibt es mehrere Zeilen mit gleichem Schule+Grad+Name aber abweichendem Wirkungstext (vermutlich alte+neue Version nebeneinander stehen geblieben) - hier wurde die letzte Version uebernommen, bitte pruefen. | K3: 2 | L3: WENN(wert=0;0;10+(wert-1)*grad) | P3: eig_bonus_k_staerke | Q3: Aus der Handfläche des Magiers schießt ein (M) cm dicker Strahl aus Erde. Schaden: W10+Magie, RB 3, pro sec, Treffer auf eine FK-TZ mit 1 zusätzlichen TZ-Reroll.
A4: spruchmagie_erdbeschwoerung_3_steinschlag | B4: Spruchmagie | C4: Steinschlag | F4: Erdbeschwörung | G4: Wert | J4: ACHTUNG: In der Quelle (NN_Spruchmagie_0.57) gibt es mehrere Zeilen mit gleichem Schule+Grad+Name aber abweichendem Wirkungstext (vermutlich alte+neue Version nebeneinander stehen geblieben) - hier wurde die letzte Version uebernommen, bitte pruefen. | K4: 3 | L4: WENN(wert=0;0;10+(wert-1)*grad) | P4: eig_bonus_k_staerke | Q4: Der Magus erschafft um das Opfer eine Kugel aus Erde. Treffer auf FK-TZ mit 2 TZ-Rerolls auf die gewünschte Trefferzone. Schaden: 2W6 + Magie, RB 6.
A5: spruchmagie_erdbeschwoerung_4_grosse_splitterwand | B5: Spruchmagie | C5: Große Splitterwand | F5: Erdbeschwörung | G5: Wert | J5: ACHTUNG: In der Quelle (NN_Spruchmagie_0.57) gibt es mehrere Zeilen mit gleichem Schule+Grad+Name aber abweichendem Wirkungstext (vermutlich alte+neue Version nebeneinander stehen geblieben) - hier wurde die letzte Version uebernommen, bitte pruefen. | K5: 4 | L5: WENN(wert=0;0;10+(wert-1)*grad) | P5: eig_bonus_k_staerke | Q5: Der Magier erschafft eine Wand aus Erde. Die Wahrnehmung durch diese Wand ist stark erschwert bis unmöglich: Alle FK-Attacken sind um Aura*2 erschwert. Wer versucht, die Wand zu durchdringen, erleidet Elementarschaden auf jeder TZ. Während der Effektdauer entfaltet die Wand nur die halbe Wirkung. Schaden: 2W6 + Magie, RB 6. Länge max. (M) m, Breite max. (M)*5cm
A6: spruchmagie_erdbeschwoerung_5_grosse_splitteraura | B6: Spruchmagie | C6: Große Splitteraura | F6: Erdbeschwörung | G6: Wert | J6: ACHTUNG: In der Quelle (NN_Spruchmagie_0.57) gibt es mehrere Zeilen mit gleichem Schule+Grad+Name aber abweichendem Wirkungstext (vermutlich alte+neue Version nebeneinander stehen geblieben) - hier wurde die letzte Version uebernommen, bitte pruefen. | K6: 5 | L6: WENN(wert=0;0;10+(wert-1)*grad) | P6: eig_bonus_k_staerke | Q6: Der Magus hüllt sich in eine kugelförmige Aura aus Erde. Wer sich in die Aura begibt, erleidet auf jeder TZ innerhalb dieses Gebietes Elementarschaden. Der Magier kann aus der Aura heraus normal zielen, FK-Angriffe sind um Aura*2 erschwert. Feindliche Magie ist mit Ziel Aura hiervon nicht betroffen. Schaden: 2W6+Magie, RB 6, auf jede TZ.
A7: spruchmagie_erdbeschwoerung_5_grosser_steinschuss | B7: Spruchmagie | C7: Großer Steinschuss | F7: Erdbeschwörung | G7: Wert | J7: ACHTUNG: In der Quelle (NN_Spruchmagie_0.57) gibt es mehrere Zeilen mit gleichem Schule+Grad+Name aber abweichendem Wirkungstext (vermutlich alte+neue Version nebeneinander stehen geblieben) - hier wurde die letzte Version uebernommen, bitte pruefen. | K7: 5 | L7: WENN(wert=0;0;10+(wert-1)*grad) | P7: eig_bonus_k_staerke | Q7: Der Magus erschafft einen Bolzen aus Erde. Treffer auf FK-TZ. Schaden: 2W10 + Magie; RB: 6 + (M)/2
A8: spruchmagie_erdbeschwoerung_5_splittersturm | B8: Spruchmagie | C8: Splittersturm | F8: Erdbeschwörung | G8: Wert | J8: ACHTUNG: In der Quelle (NN_Spruchmagie_0.57) gibt es mehrere Zeilen mit gleichem Schule+Grad+Name aber abweichendem Wirkungstext (vermutlich alte+neue Version nebeneinander stehen geblieben) - hier wurde die letzte Version uebernommen, bitte pruefen. | K8: 5 | L8: WENN(wert=0;0;10+(wert-1)*grad) | P8: eig_bonus_k_staerke | Q8: Eine vom Magus ausgehende kugelförmige Explosion verursacht Elementarschaden. Es ist unmöglich, dem Schaden zu entgehen. Jede TZ wird getroffen. Schaden: W8 + Magie, RB 3.
A9: spruchmagie_erdbeschwoerung_6_grosser_splitterstrahl | B9: Spruchmagie | C9: Großer Splitterstrahl | F9: Erdbeschwörung | G9: Wert | J9: ACHTUNG: In der Quelle (NN_Spruchmagie_0.57) gibt es mehrere Zeilen mit gleichem Schule+Grad+Name aber abweichendem Wirkungstext (vermutlich alte+neue Version nebeneinander stehen geblieben) - hier wurde die letzte Version uebernommen, bitte pruefen. | K9: 6 | L9: WENN(wert=0;0;10+(wert-1)*grad) | P9: eig_bonus_k_staerke | Q9: Aus der Handfläche des Magiers schießt ein (M) cm dicker Strahl aus Erde. Schaden: 2W10 + Magie, RB 6, pro sec, Treffer auf eine FK-TZ mit 1 zusätzlichen TZ-Reroll.
A10: spruchmagie_erdbeschwoerung_6_grosser_steinschlag | B10: Spruchmagie | C10: Großer Steinschlag | F10: Erdbeschwörung | G10: Wert | J10: ACHTUNG: In der Quelle (NN_Spruchmagie_0.57) gibt es mehrere Zeilen mit gleichem Schule+Grad+Name aber abweichendem Wirkungstext (vermutlich alte+neue Version nebeneinander stehen geblieben) - hier wurde die letzte Version uebernommen, bitte pruefen. | K10: 6 | L10: WENN(wert=0;0;10+(wert-1)*grad) | P10: eig_bonus_k_staerke | Q10: Der Magus erschafft um das Opfer eine Kugel aus Erde. Treffer auf FK-TZ mit 2 TZ-Rerolls auf die gewünschte Trefferzone. Schaden: 2W12 + Magie, RB 9.
A11: spruchmagie_erdbeschwoerung_7_grosser_splittersturm | B11: Spruchmagie | C11: Großer Splittersturm | F11: Erdbeschwörung | G11: Wert | J11: ACHTUNG: In der Quelle (NN_Spruchmagie_0.57) gibt es mehrere Zeilen mit gleichem Schule+Grad+Name aber abweichendem Wirkungstext (vermutlich alte+neue Version nebeneinander stehen geblieben) - hier wurde die letzte Version uebernommen, bitte pruefen. | K11: 7 | L11: WENN(wert=0;0;10+(wert-1)*grad) | P11: eig_bonus_k_staerke | Q11: Eine vom Magus ausgehende kugelförmige Explosion verursacht Elementarschaden. Es ist unmöglich, dem Schaden zu entgehen. Jede TZ wird getroffen. Schaden: 2W15 + Magie, RB 15.
A12: spruchmagie_feuerbeschwoerung_1_flammenwand | B12: Spruchmagie | C12: Flammenwand | F12: Feuerbeschwörung | G12: Wert | J12: ACHTUNG: In der Quelle (NN_Spruchmagie_0.57) gibt es mehrere Zeilen mit gleichem Schule+Grad+Name aber abweichendem Wirkungstext (vermutlich alte+neue Version nebeneinander stehen geblieben) - hier wurde die letzte Version uebernommen, bitte pruefen. | K12: 1 | L12: WENN(wert=0;0;10+(wert-1)*grad) | P12: eig_bonus_g_mut | Q12: Der Magier erschafft eine Wand aus Feuer. Die Wahrnehmung durch diese Wand ist stark erschwert bis unmöglich: Alle FK-Attacken sind um Aura*2 erschwert. Wer versucht, die Wand zu durchdringen, erleidet Elementarschaden auf jeder TZ. Während der Effektdauer entfaltet die Wand nur die halbe Wirkung. Schaden: W6+Magie auf jede TZ.
A13: spruchmagie_feuerbeschwoerung_2_flammenaura | B13: Spruchmagie | C13: Flammenaura | F13: Feuerbeschwörung | G13: Wert | J13: ACHTUNG: In der Quelle (NN_Spruchmagie_0.57) gibt es mehrere Zeilen mit gleichem Schule+Grad+Name aber abweichendem Wirkungstext (vermutlich alte+neue Version nebeneinander stehen geblieben) - hier wurde die letzte Version uebernommen, bitte pruefen. | K13: 2 | L13: WENN(wert=0;0;10+(wert-1)*grad) | P13: eig_bonus_g_mut | Q13: Der Magus hüllt sich in eine kugelförmige Aura aus Feuer. Wer sich in die Aura begibt, erleidet auf jeder TZ innerhalb dieses Gebietes Elementarschaden. Der Magier kann aus der Aura heraus normal zielen, FK-Angriffe sind um Aura*2 erschwert. Feindliche Magie ist mit Ziel Aura hiervon nicht betroffen. Schaden: W6+Magie auf jede TZ.
... A71: spruchmagie_wasserbeschwoerung_7_grosse_frostbolzen_salve | B71: Spruchmagie | C71: Große Frostbolzen-Salve | F71: Wasserbeschwörung | G71: Wert | J71: ACHTUNG: In der Quelle (NN_Spruchmagie_0.57) gibt es mehrere Zeilen mit gleichem Schule+Grad+Name aber abweichendem Wirkungstext (vermutlich alte+neue Version nebeneinander stehen geblieben) - hier wurde die letzte Version uebernommen, bitte pruefen. | Referenz enthielt Bindestrich (mehrdeutig mit Subtraktion) - zu Unterstrich normalisiert. | K71: 7 | L71: WENN(wert=0;0;10+(wert-1)*grad) | P71: eig_bonus_k_athletik | Q71: Der Magus erschafft Magie/2 Bolzen aus Wasser. Jeweils Treffer auf FK-TZ. Schaden: 2W10 + Magie; RB: (M)/2. Pro 5 TP erleidet das Opfer zusätzliche BE 1, nur die höchste so erzielte BE zählt.
A72: ep_abenteuer | B72: Charakterwerte | C72: EP zum Abenteuerende | E72: S.1 | G72: Formel | H72: ep_gesamt-ep_start
A73: le_leberschutz | B73: Kampf | C73: Leberschutz | E73: S.3 | G73: Pool
A74: ep_gesamt | B74: Charakterwerte | C74: Gesamte Erfahrungspunke | E74: S.1 | G74: Wert
A75: ep_start | B75: Charakterwerte | C75: EP bei Abenteuerbeginn | E75: S.1 | G75: Wert
A76: whk_spez_kaufmann_gastwirt | B76: WHK | C76: -> Gastwirt | F76: Kaufmann | G76: Wert | L76: SVERWEIS(wert;'WHK-Spez-Kosten';3;1)
A77: whk_spez_kaufmann_sklavenhaendler | B77: WHK | C77: -> Sklavenhändler | F77: Kaufmann | G77: Wert | L77: SVERWEIS(wert;'WHK-Spez-Kosten';3;1)
A78: whk_spez_abrichten_drache | B78: WHK | C78: -> Drache | F78: Abrichten | G78: Wert | L78: SVERWEIS(wert;'WHK-Spez-Kosten';3;1)
A79: whk_spez_abrichten_laufvogel | B79: WHK | C79: -> Laufvogel | F79: Abrichten | G79: Wert | L79: SVERWEIS(wert;'WHK-Spez-Kosten';3;1)
A80: whk_spez_abrichten_reitkrebse | B80: WHK | C80: -> Reitkrebse | F80: Abrichten | G80: Wert | L80: SVERWEIS(wert;'WHK-Spez-Kosten';3;1)
A81: whk_spez_abrichten_reitreptilien | B81: WHK | C81: -> Reitreptilien | F81: Abrichten | G81: Wert | L81: SVERWEIS(wert;'WHK-Spez-Kosten';3;1)
A82: whk_spez_abrichten_rok | B82: WHK | C82: -> Rok | F82: Abrichten | G82: Wert | L82: SVERWEIS(wert;'WHK-Spez-Kosten';3;1)
A83: whk_spez_abrichten_warg | B83: WHK | C83: -> Warg | F83: Abrichten | G83: Wert | L83: SVERWEIS(wert;'WHK-Spez-Kosten';3;1)
A84: whk_spez_ruestungsschmied_tierruestungen | B84: WHK | C84: -> Tierrüstungen | F84: Rüstungsschmied | G84: Wert | L84: SVERWEIS(wert;'WHK-Spez-Kosten';3;1)
A85: bewegung_f_schnell_schwimmen | B85: Bewegung | C85: Schnell Schwimmen | E85: Meisterscreen S.3 | G85: Formel | H85: (eig_k_konstitution+eig_k_athletik+gr_schwimmen)/30
A86: bewegung_f_sprinten | B86: Bewegung | C86: Sprinten | E86: Meisterscreen S.3 | G86: Formel | H86: (eig_k_athletik+eig_k_schnelligkeit+gr_sprinten)/7+4
A87: spruchmagie_beherrschung_4_einschlaefern | B87: Spruchmagie | C87: Einschläfern | F87: Beherrschung | G87: Wert | K87: 4 | L87: WENN(wert=0;0;10+(wert-1)*grad) | P87: eig_bonus_k_ausstrahlung | Q87: Das Opfer schläft ein. Der Schlaf ist, wenn auch unnatürlich tief, wie normaler schlaf zu Behandeln. Sollte das Opfer also gerade stehen, so fällt es um und wacht durch den Sturz natürlich wieder auf. Auch das abfeuern einer Feuerwaffe in seiner nähe wird wohl, ohne Probe, zum Aufwachen führen. Gewohnte Geräusche gehören natürlich nicht dazu. Ein Heizer einer Dampfmaschine wird durch eben jene nicht Aufwachen.
A88: spruchmagie_beherrschung_7_maechtige_f_daemonen_herrschaft | B88: Spruchmagie | C88: Mächtige f.Dämonen Herrschaft | F88: Beherrschung | G88: Wert | K88: 7 | L88: WENN(wert=0;0;10+(wert-1)*grad) | P88: eig_bonus_k_ausstrahlung | Q88: Ein freier (nicht von einem anderen Magus beherrschter) Dämon hat eine Willenskraft-Probe erschwert um die Differenz von der (M) des Margus (Macht x2) und des Opfers (Macht x1). Und alle 24 Stunden eine weitere. Wenn sie gelingt fällt der Zauber.1 und 29 sind immer ein Erfolg. Ansonsten wird der Dämon zu einem Willenskraftenlosen Sklaven des Magus. Es wird aufs Wort hören, ganz so als währe es ein Absolut untertäniger Diner. Der Dämon weis zwar immer genau was der Magus von ihm Willenskraft ist aber nicht Intelligenzelligenter als vorher oder verfügt nicht über neue Fertigkeiten. Eine Stroh dummer Dämon wird es wohl nicht schaffen den Banksafe ohne Gewalt zu öffnen.
A89: spruchmagie_beherrschung_5_massen_besaenftigung | B89: Spruchmagie | C89: Massen Besänftigung | F89: Beherrschung | G89: Wert | K89: 5 | L89: WENN(wert=0;0;10+(wert-1)*grad) | P89: eig_bonus_k_ausstrahlung | Q89: Die Opfer werden ruhig und gelassen, sie verlieren jeglichen drang zu Töten (außer Einer ist ein Sadist und macht es aus Spaß). Sie wissen zwar noch alles, es ist aber nicht mehr so Dramatisch für Sie. Nach dem der Zauber vorbei ist, sind die Opfer immer noch ruhig, es hält Sie aber nichts davon ab wieder Wütend zu werden. Was natürlich auch sofort geschehen kann aber nicht muss, wenn sie sich daran erinnern dass man gerade ihr Dorf nieder gebrannt hat.
A90: spruchmagie_beherrschung_3_schmerzt_unterdruecken | B90: Spruchmagie | C90: Schmerzt unterdrücken | F90: Beherrschung | G90: Wert | K90: 3 | L90: WENN(wert=0;0;10+(wert-1)*grad) | P90: eig_bonus_g_willenskraft | Q90: Die Gefühle und Schmerzen des Opfers werden unterdrückt. Das Opfer fühlt sich so als würde es unter dem Einfluss eines Betäubungsmittels stehen. Es bekommt eine Generelle Behinderung von 1. Seine TS steigt um das 4 fache an und alle Behinderungen die das Opfer durch Kampfschäden bekommt oder bekommen hat sind gleich null.
A91: spruchmagie_beherrschung_2_zoegern | B91: Spruchmagie | C91: Zögern | F91: Beherrschung | G91: Wert | K91: 2 | L91: WENN(wert=0;0;10+(wert-1)*grad) | P91: eig_bonus_g_intelligenz | Q91: Das Opfer zögert, das zu tun, was es gerade wollte. Es greift nicht mehr an, sondern verteidigt sich nur noch. Sollte gerade keine Kampf Situation sein so bleibt es sehn und hält inne um seinen nächsten schritt noch mal zu überdenken. Das Opfer zögert maximal 1W4+Magie Sekunden lang.
A92: vn_angst_magie_10 | B92: Vor- und Nachteile | C92: Nervosität: Magie | E92: Auswahlgruppe angst_magie; maximal 1 Stufe; Angstwert 10; direkte Konfrontation: bei jeder erneuten direkten Konfrontation; bloße Gegenwart: BE -1. | F92: Angst: Magie | G92: Auswahl | J92: EP-Rate für 'magie' aus NN NPC-Rechner 0.75, Sheet 'NPC-Rechner' Formel '=AOxx*-10' (Zeile 52ff). Kosten = Stufenwert(10) * Rate(-10). | EXKLUSIV_ANGST=angst_magie | ANGST_INTERVALL=NEUE_KONFRONTATION | ANGST_DIREKTE_KONFRONTATION=1 | ANGST_BE=-1 | K92: 10 | L92: -100 | M92: S | Q92: Der Charakter reagiert auf alle Magie mit Nervosität und ist nicht in der Lage, irgendeine Form von Magie außer KI zu wirken. Bei direkter Konfrontation mit Magie, insbesondere wenn er gegen einen Magiewirker vorgeht, muss er bei jeder erneuten direkten Konfrontation eine um 10 erschwerte Mut-Probe bestehen, um handlungsfähig zu bleiben. Um Verzauberungen oder magische Heilung zuzulassen, ein Artefakt zu benutzen oder bewusst mit Magie zu interagieren, muss er einmalig eine um 10 erschwerte Willenskraft-Probe bestehen. Ist Magie zwar gegenwärtig, aber weder direkter Gegner noch Gegenstand, Wesen oder sonstiges Ziel, mit dem sich der Charakter aktuell befasst, sind keine Angst-Proben erforderlich; der Charakter erhält BE -1.
A93: vn_angst_magie_15 | B93: Vor- und Nachteile | C93: Furcht: Magie | E93: Auswahlgruppe angst_magie; maximal 1 Stufe; Angstwert 15; direkte Konfrontation: sofort, danach alle 10 KR; bloße Gegenwart: BE -2. | F93: Angst: Magie | G93: Auswahl | J93: EP-Rate für 'magie' aus NN NPC-Rechner 0.75, Sheet 'NPC-Rechner' Formel '=AOxx*-10' (Zeile 52ff). Kosten = Stufenwert(15) * Rate(-10). | EXKLUSIV_ANGST=angst_magie | ANGST_INTERVALL=10_KR | ANGST_DIREKTE_KONFRONTATION=1 | ANGST_BE=-2 | K93: 15 | L93: -150 | M93: S | Q93: Der Charakter reagiert auf alle Magie mit Furcht und ist nicht in der Lage, irgendeine Form von Magie außer KI zu wirken. Bei direkter Konfrontation mit Magie, insbesondere wenn er gegen einen Magiewirker vorgeht, muss er sofort, danach alle 10 KR eine um 15 erschwerte Mut-Probe bestehen, um handlungsfähig zu bleiben. Um Verzauberungen oder magische Heilung zuzulassen, ein Artefakt zu benutzen oder bewusst mit Magie zu interagieren, muss er einmalig eine um 15 erschwerte Willenskraft-Probe bestehen. Ist Magie zwar gegenwärtig, aber weder direkter Gegner noch Gegenstand, Wesen oder sonstiges Ziel, mit dem sich der Charakter aktuell befasst, sind keine Angst-Proben erforderlich; der Charakter erhält BE -2.
A94: vn_angst_magie_20 | B94: Vor- und Nachteile | C94: Angst: Magie | E94: Auswahlgruppe angst_magie; maximal 1 Stufe; Angstwert 20; direkte Konfrontation: sofort, danach alle 5 KR; bloße Gegenwart: BE -3. | F94: Angst: Magie | G94: Auswahl | J94: EP-Rate für 'magie' aus NN NPC-Rechner 0.75, Sheet 'NPC-Rechner' Formel '=AOxx*-10' (Zeile 52ff). Kosten = Stufenwert(20) * Rate(-10). | EXKLUSIV_ANGST=angst_magie | ANGST_INTERVALL=5_KR | ANGST_DIREKTE_KONFRONTATION=1 | ANGST_BE=-3 | K94: 20 | L94: -200 | M94: S | Q94: Der Charakter reagiert auf alle Magie mit Angst und ist nicht in der Lage, irgendeine Form von Magie außer KI zu wirken. Bei direkter Konfrontation mit Magie, insbesondere wenn er gegen einen Magiewirker vorgeht, muss er sofort, danach alle 5 KR eine um 20 erschwerte Mut-Probe bestehen, um handlungsfähig zu bleiben. Um Verzauberungen oder magische Heilung zuzulassen, ein Artefakt zu benutzen oder bewusst mit Magie zu interagieren, muss er einmalig eine um 20 erschwerte Willenskraft-Probe bestehen. Ist Magie zwar gegenwärtig, aber weder direkter Gegner noch Gegenstand, Wesen oder sonstiges Ziel, mit dem sich der Charakter aktuell befasst, sind keine Angst-Proben erforderlich; der Charakter erhält BE -3.
A95: vn_angst_magie_30 | B95: Vor- und Nachteile | C95: Phobie: Magie | E95: Auswahlgruppe angst_magie; maximal 1 Stufe; Angstwert 30; direkte Konfrontation: sofort, danach jede KR; bloße Gegenwart: BE -5. | F95: Angst: Magie | G95: Auswahl | J95: EP-Rate für 'magie' aus NN NPC-Rechner 0.75, Sheet 'NPC-Rechner' Formel '=AOxx*-10' (Zeile 52ff). Kosten = Stufenwert(30) * Rate(-10). | EXKLUSIV_ANGST=angst_magie | ANGST_INTERVALL=1_KR | ANGST_DIREKTE_KONFRONTATION=1 | ANGST_BE=-5 | K95: 30 | L95: -300 | M95: S | Q95: Der Charakter leidet unter einer Phobie gegenüber aller Magie und ist nicht in der Lage, irgendeine Form von Magie außer KI zu wirken. Bei direkter Konfrontation mit Magie, insbesondere wenn er gegen einen Magiewirker vorgeht, muss er sofort, danach jede KR eine um 30 erschwerte Mut-Probe bestehen, um handlungsfähig zu bleiben. Um Verzauberungen oder magische Heilung zuzulassen, ein Artefakt zu benutzen oder bewusst mit Magie zu interagieren, muss er einmalig eine um 30 erschwerte Willenskraft-Probe bestehen. Ist Magie zwar gegenwärtig, aber weder direkter Gegner noch Gegenstand, Wesen oder sonstiges Ziel, mit dem sich der Charakter aktuell befasst, sind keine Angst-Proben erforderlich; der Charakter erhält BE -5.
A96: vn_angst_magie_5 | B96: Vor- und Nachteile | C96: Unbehagen: Magie | E96: Auswahlgruppe angst_magie; maximal 1 Stufe; Angstwert 5; direkte Konfrontation: einmal pro Situation; bloße Gegenwart: BE 0. | F96: Angst: Magie | G96: Auswahl | J96: EP-Rate für 'magie' aus NN NPC-Rechner 0.75, Sheet 'NPC-Rechner' Formel '=AOxx*-10' (Zeile 52ff). Kosten = Stufenwert(5) * Rate(-10). | EXKLUSIV_ANGST=angst_magie | ANGST_INTERVALL=SITUATION | ANGST_DIREKTE_KONFRONTATION=1 | ANGST_BE=0 | K96: 5 | L96: -50 | M96: S | Q96: Der Charakter empfindet Unbehagen gegenüber aller Magie und ist nicht in der Lage, irgendeine Form von Magie außer KI zu wirken. Bei direkter Konfrontation mit Magie, insbesondere wenn er gegen einen Magiewirker vorgeht, muss er einmal pro Situation eine um 5 erschwerte Mut-Probe bestehen, um handlungsfähig zu bleiben. Um Verzauberungen oder magische Heilung zuzulassen, ein Artefakt zu benutzen oder bewusst mit Magie zu interagieren, muss er einmalig eine um 5 erschwerte Willenskraft-Probe bestehen.
A97: vn_schlechte_eigenschaft_ausstrahlung | B97: Vor- und Nachteile | C97: Schlechte Eigenschaft: Ausstrahlung | E97: Max=9 (ab Kreis 3); Erstellungs-Max=7; nicht uebersteigerbar | G97: Auswahl | J97: Ersetzt die normale Voelker-Maxima-Tabelle fuer diese Eigenschaft komplett (nicht MIN() mit dem Volkswert - die Regel ignoriert explizit die Erstellungs-/Kreis-3-Minima/Maxima und setzt eigene feste Werte). | L97: -200 | M97: E
...

Sheet EP-Stufe-Kreis
A1: EP ab | B1: Stufe | C1: Kreis
A2: 0 | B2: 0 | C2: 0
A3: 20 | B3: 1 | C3: 1
A4: 60 | B4: 2 | C4: 1
A5: 120 | B5: 3 | C5: 1
A6: 200 | B6: 4 | C6: 2
A7: 300 | B7: 5 | C7: 2
A8: 400 | B8: 6 | C8: 2
A9: 500 | B9: 7 | C9: 2
A10: 600 | B10: 8 | C10: 2
A11: 700 | B11: 9 | C11: 3
A12: 850 | B12: 10 | C12: 3
A13: 1000 | B13: 11 | C13: 3
... A65: 15150 | B65: 63 | C65: 7

Sheet WHK-Spez-Kosten
A1: Wert | B1: EP-Kosten (Schritt) | C1: Gesamt-EP
A2: 0 | B2: 0 | C2: 0
A3: 1 | B3: 4 | C3: 4
A4: 2 | B4: 1 | C4: 5
A5: 3 | B5: 1 | C5: 6
A6: 4 | B6: 1 | C6: 7
A7: 5 | B7: 2 | C7: 9
A8: 6 | B8: 2 | C8: 11
A9: 7 | B9: 2 | C9: 13
A10: 8 | B10: 3 | C10: 16
A11: 9 | B11: 3 | C11: 19
A12: 10 | B12: 3 | C12: 22
A13: 11 | B13: 4 | C13: 26
... A41: 39 | B41: 13 | C41: 264

Sheet Eigenschaften-Kosten
A1: Wert | B1: Gesamt-EP | C1: EP-Kosten (Schritt)
A2: 0 | B2: 0 | C2: 0
A3: 1 | B3: 30 | C3: 30
A4: 2 | B4: 60 | C4: 30
A5: 3 | B5: 90 | C5: 30
A6: 4 | B6: 120 | C6: 30
A7: 5 | B7: 150 | C7: 30
A8: 6 | B8: 180 | C8: 30
A9: 7 | B9: 210 | C9: 30
A10: 8 | B10: 240 | C10: 30
A11: 9 | B11: 270 | C11: 30
A12: 10 | B12: 300 | C12: 30
A13: 11 | B13: 330 | C13: 30
... A66: 64 | B66: 6213 | C66: 189

Sheet Voelker-Maxima
A1: Volk | B1: Eigenschaft | C1: Erstellungs-Min | D1: Erstellungs-Max | E1: Max (ab Kreis 3)
A2: Dalkini | B2: Ausstrahlung | C2: 9 | D2: 21 | E2: 31
A3: Dalkini | B3: Intelligenz | C3: 9 | D3: 21 | E3: 31
A4: Dalkini | B4: Mut | C4: 10 | D4: 22 | E4: 31
A5: Dalkini | B5: Sinnesschaerfe | C5: 9 | D5: 21 | E5: 31
A6: Dalkini | B6: Willenskraft | C6: 15 | D6: 27 | E6: 31
A7: Dalkini | B7: Athletik | C7: 10 | D7: 22 | E7: 31
A8: Dalkini | B8: Geschicklichkeit | C8: 10 | D8: 22 | E8: 31
A9: Dalkini | B9: Konstitution | C9: 11 | D9: 23 | E9: 31
A10: Dalkini | B10: Schnelligkeit | C10: 10 | D10: 22 | E10: 31
A11: Dalkini | B11: Staerke | C11: 11 | D11: 23 | E11: 31
A12: Draw | B12: Ausstrahlung | C12: 11 | D12: 23 | E12: 31
A13: Draw | B13: Intelligenz | C13: 12 | D13: 24 | E13: 31
... A111: Zwerge | B111: Staerke | C111: 12 | D111: 24 | E111: 31

Sheet PSI-Zauberstufen
A1: Referenz | B1: Stufe | C1: Erschwerung | D1: ASP-Kosten
A2: psi_telekinese | B2: 1 | C2: 3 | D2: 10
A3: psi_telekinese | B3: 2 | C3: 6 | D3: 15
A4: psi_telekinese | B4: 3 | C4: 9 | D4: 25
A5: psi_telekinese | B5: 4 | C5: 12 | D5: 40
A6: psi_telekinese | B6: 5 | C6: 15 | D6: 60
A7: psi_telekinese | B7: 6 | C7: 18 | D7: 80
A8: psi_telekinese | B8: 7 | C8: 21 | D8: 105
A9: psi_telekinese_griff | B9: 1 | C9: 4 | D9: 20
A10: psi_telekinese_griff | B10: 2 | C10: 7 | D10: 30
A11: psi_telekinese_griff | B11: 3 | C11: 10 | D11: 40
A12: psi_telekinese_griff | B12: 4 | C12: 14 | D12: 55
A13: psi_telekinese_griff | B13: 5 | C13: 18 | D13: 75
... A106: psi_kryokinese | B106: 7 | C106: 29 | D106: 100

Sheet KI-Baum-Kanten
A1: Faehigkeit | B1: Vorbedingung | C1: Mindest-TaW
A2: ki_ki-schutz | B2: ki_abhaertung | C2: 10
A3: ki_geschossen_ausweichen | B3: ki_abwehr | C3: 15
A4: ki_geschossen_ausweichen | B4: ki_adlerauge | C4: 30
A5: ki_magie_aufspueren | B5: ki_adlerauge | C5: 20
A6: ki_erleuchtung | B6: ki_charisma | C6: 15
A7: ki_sprint | B7: ki_dauerlauf | C7: 10
A8: ki_heilender_schlaf | B8: ki_erleuchtung | C8: 10
A9: ki_adlerauge | B9: ki_fledermausohr_aalnase | C9: 15
A10: ki_kraftakt | B10: ki_froschlunge | C10: 10
A11: ki_paradeserie | B11: ki_geschossen_ausweichen | C11: 25
A12: ki_geschossen_ausweichen | B12: ki_gleichgewicht_&_feingefuehl | C12: 30
A13: ki_fledermausohr_aalnase | B13: ki_katzenauge | C13: 10
... A30: ki_katzenauge | B30: ki_konzentration | C30: 10

Sheet Preisliste
A1: Art | B1: Name | C1: Anzahl | D1: Einheit | E1: Gewicht in kg | F1: Dublonen | H1: WHK | I1: Spezialisierung
A2: Reittiere | B2: Drache, Flug | C2: 1 | D2: Stück | E2: XXX | F2: ------ | G2: Selten | H2: Abrichten | I2: Drache
A3: Reittiere | B3: Greif, Flug | C3: 1 | D3: Stück | E3: XXX | F3: ------ | G3: Selten | H3: Abrichten | I3: Greife
A4: Reittiere | B4: Chocobo, Abgeh, | C4: 1 | D4: Stück | E4: XXX | F4: 470 | G4: Elf | H4: Abrichten | I4: Laufvogel
A5: Reittiere | B5: Chocobo, Alt | C5: 1 | D5: Stück | E5: XXX | F5: 282 | G5: Elf | H5: Abrichten | I5: Laufvogel
A6: Reittiere | B6: Chocobo, Reit | C6: 1 | D6: Stück | E6: XXX | F6: 750 | G6: Elf | H6: Abrichten | I6: Laufvogel
A7: Reittiere | B7: Chocobo, Schlacht | C7: 1 | D7: Stück | E7: XXX | F7: 2250 | G7: Elf | H7: Abrichten | I7: Laufvogel
A8: Reittiere | B8: Chocobo, Vollblut | C8: 1 | D8: Stück | E8: XXX | F8: 3380 | G8: Elf | H8: Abrichten | I8: Laufvogel
A9: Reittiere | B9: Pegasus, Flug | C9: 1 | D9: Stück | E9: XXX | F9: ------ | G9: Selten | H9: Abrichten | I9: Pegasus
A10: Reittiere | B10: Pferd, Abgehalftert | C10: 1 | D10: Stück | E10: XXX | F10: 250 | G10: Indianer, Dalkini | H10: Abrichten | I10: Pferd
A11: Reittiere | B11: Pferd, Alter Gaul | C11: 1 | D11: Stück | E11: XXX | F11: 150 | G11: Indianer, Dalkini | H11: Abrichten | I11: Pferd
A12: Reittiere | B12: Pferd, Reit | C12: 1 | D12: Stück | E12: XXX | F12: 400 | G12: Indianer, Dalkini | H12: Abrichten | I12: Pferd
A13: Reittiere | B13: Pferd, Schlachtross | C13: 1 | D13: Stück | E13: XXX | F13: 1200 | G13: Indianer, Dalkini | H13: Abrichten | I13: Pferd
A14: Reittiere | B14: Pferd, Vollblut | C14: 1 | D14: Stück | E14: XXX | F14: 1800 | G14: Indianer, Dalkini | H14: Abrichten | I14: Pferd
A15: Reittiere | B15: Ratte, Abgehalftert | C15: 1 | D15: Stück | E15: XXX | F15: 190 | G15: Goblin | H15: Abrichten | I15: Ratte
A16: Reittiere | B16: Ratte, Alt | C16: 1 | D16: Stück | E16: XXX | F16: 115 | G16: Goblin | H16: Abrichten | I16: Ratte
A17: Reittiere | B17: Ratte, Gefährlich | C17: 1 | D17: Stück | E17: XXX | F17: 1350 | G17: Goblin | H17: Abrichten | I17: Ratte
A18: Reittiere | B18: Ratte, Reit | C18: 1 | D18: Stück | E18: XXX | F18: 300 | G18: Goblin | H18: Abrichten | I18: Ratte
A19: Reittiere | B19: Ratte, Schlacht | C19: 1 | D19: Stück | E19: XXX | F19: 900 | G19: Goblin | H19: Abrichten | I19: Ratte
A20: Reittiere | B20: Assel, Abgehalftert | C20: 1 | D20: Stück | E20: XXX | F20: 282 | G20: Zwerg | H20: Abrichten | I20: Reitkrebse
A21: Reittiere | B21: Assel, Alt | C21: 1 | D21: Stück | E21: XXX | F21: 169 | G21: Zwerg | H21: Abrichten | I21: Reitkrebse
... A37: Reittiere | B37: Schildkröte, Schnell | C37: 1 | D37: Stück | E37: XXX | F37: 4500 | G37: Gnom | H37: Abrichten | I37: Reitreptilien
A38: Reittiere | B38: Roc, Flug | C38: 1 | D38: Stück | E38: XXX | F38: ------ | G38: Selten | H38: Abrichten | I38: Rok
A39: Reittiere | B39: Rollok, abgehalftert | C39: 1 | D39: Stück | E39: XXX | F39: 532 | G39: Troll | H39: Abrichten | I39: Rollok
A40: Reittiere | B40: Rollok, alt | C40: 1 | D40: Stück | E40: XXX | F40: 319 | G40: Troll | H40: Abrichten | I40: Rollok
A41: Reittiere | B41: Rollok, Reit | C41: 1 | D41: Stück | E41: XXX | F41: 850 | G41: Troll | H41: Abrichten | I41: Rollok
A42: Reittiere | B42: Rollok, Schlacht | C42: 1 | D42: Stück | E42: XXX | F42: 2550 | G42: Troll | H42: Abrichten | I42: Rollok
A43: Reittiere | B43: Rollok, übellaunig | C43: 1 | D43: Stück | E43: XXX | F43: 3850 | G43: Troll | H43: Abrichten | I43: Rollok
A44: Reittiere | B44: Warg, Abgehalftert | C44: 1 | D44: Stück | E44: XXX | F44: 375 | G44: Ork | H44: Abrichten | I44: Warg
A45: Reittiere | B45: Warg, Alt | C45: 1 | D45: Stück | E45: XXX | F45: 225 | G45: Ork | H45: Abrichten | I45: Warg
A46: Reittiere | B46: Warg, Elite | C46: 1 | D46: Stück | E46: XXX | F46: 2700 | G46: Ork | H46: Abrichten | I46: Warg
A47: Reittiere | B47: Warg, Reit | C47: 1 | D47: Stück | E47: XXX | F47: 600 | G47: Ork | H47: Abrichten | I47: Warg
A48: Reittiere | B48: Warg, Schlacht | C48: 1 | D48: Stück | E48: XXX | F48: 1800 | G48: Ork | H48: Abrichten | I48: Warg
A49: Alchemistische Stoffe | B49: Öl, Brand- | C49: 1 | D49: Fass | E49: 5 | F49: 35 | H49: Alchemie | I49: Brandbeschleuniger
A50: Alchemistische Stoffe | B50: Schwarzpulver | C50: 1 | D50: Sack | E50: 1 | F50: 85 | H50: Alchemie | I50: Brandbeschleuniger
A51: Alchemistische Stoffe | B51: Zwergisches Feuer | C51: 1 | D51: Flasche | E51: 1 | F51: 500 | H51: Alchemie | I51: Brandbeschleuniger
A52: Beleuchtung | B52: Streichhölzer 25St, | C52: 1 | D52: Schachtel | E52: 0.2 | F52: 1 | H52: Alchemie | I52: Brandbeschleuniger
A53: Alchemistische Stoffe | B53: Orazal (Lösung) | C53: 1 | D53: Bund | E53: 0.002 | F53: 92 | H53: Alchemie | I53: DSA-Material
A54: Schreibwaren | B54: Tinte | C54: 1 | D54: Phiole | E54: 0.1 | F54: 0.98 | H54: Alchemie | I54: Farbstoffe
A55: Schreibwaren | B55: Tusche | C55: 1 | D55: Phiole | E55: 0.1 | F55: 1.3 | H55: Alchemie | I55: Farbstoffe
...

Sheet Alchemika
A1: Kategorie | B1: magisch_y_n | C1: Name | D1: Potenz | E1: Dosierbar | F1: Zufuhr | G1: ZbS (Zeit bis Symptom) | H1: ZbW (Zeit bis Wirkung) | I1: Wirkungsdauer | J1: Wirkung | K1: Legalität | L1: Char_Unterwelt_Mod | M1: Verfügb | N1: Zutaten_Preis_in_D | O1: Kaufpreis_in_D | P1: Rezept-Erschwerung
A2: Gifte | B2: profan | C2: Leichtes Regigift | D2: 5 | E2: J | F2: Körper | G2: Sofort | H2: Sofort | I2: 12h | J2: Regenerationsklasse -2, leichter Schlaf | K2: 3 | L2: 0 | M2: 1 | N2: 0.25 | O2: =N2*(K2+L2) -> 0.75 | P2: 4
A3: Gifte | B3: profan | C3: Regigift | D3: 15 | E3: J | F3: Körper | G3: Sofort | H3: Sofort | I3: 12h | J3: Regenerationsklasse -4, leichter Schlaf | K3: 4 | L3: 0 | M3: 2 | N3: 0.5 | O3: =N3*(K3+L3) -> 2 | P3: 6
A4: Gifte | B4: profan | C4: Starkes Regigift | D4: 30 | E4: J | F4: Körper | G4: Sofort | H4: Sofort | I4: 12h | J4: Regenerationsklasse -7, leichter Schlaf | K4: 5 | L4: 0 | M4: 3 | N4: 1 | O4: =N4*(K4+L4) -> 5 | P4: 10
A5: Gifte | B5: profan | C5: Hässlichkeitsgift | D5: 15 | E5: J | F5: Körper | G5: Sofort | H5: Sofort | I5: 1d | J5: Alle Grundfertigkeits-, Sprach-, Kulur- und WHK-Proben auf Ausstrahlung um 10 erschwert | K5: 4 | L5: 0 | M5: 5 | N5: 50 | O5: =N5*(K5+L5) -> 200 | P5: 30
A6: Gifte | B6: profan | C6: Starkes Hässlichkeitsgift | D6: 30 | E6: J | F6: Körper | G6: Sofort | H6: Sofort | I6: 1d | J6: Alle Grundfertigkeits-, Sprach-, Kulur- und WHK-Proben auf Ausstrahlung um 15 erschwert | K6: 5 | L6: 0 | M6: 6 | N6: 150 | O6: =N6*(K6+L6) -> 750 | P6: 48
A7: Gifte | B7: profan | C7: Leichtes Hässlichkeitsgift | D7: 5 | E7: J | F7: Körper | G7: Sofort | H7: Sofort | I7: 1d | J7: Alle Grundfertigkeits-, Sprach-, Kulur- und WHK-Proben auf Ausstrahlung um 5 erschwert | K7: 3 | L7: 0 | M7: 4 | N7: 25 | O7: =N7*(K7+L7) -> 75 | P7: 18
A8: Gifte | B8: profan | C8: Leichtes Zungengift | D8: 5 | E8: J | F8: Körper | G8: 1 KR | H8: 3 KR | I8: 1h | J8: Artikuliertes Sprechen unmöglich | K8: 2 | L8: 0 | M8: 2 | N8: 1 | O8: =N8*(K8+L8) -> 2 | P8: 12
A9: Gifte | B9: profan | C9: Zungengift | D9: 15 | E9: J | F9: Körper | G9: 1 KR | H9: 3 KR | I9: 1h | J9: Artikuliertes Sprechen unmöglich | K9: 3 | L9: 0 | M9: 3 | N9: 2 | O9: =N9*(K9+L9) -> 6 | P9: 18
A10: Gifte | B10: profan | C10: Starkes Zungengift | D10: 30 | E10: J | F10: Körper | G10: 1 KR | H10: 3 KR | I10: 1h | J10: Artikuliertes Sprechen unmöglich | K10: 4 | L10: 0 | M10: 4 | N10: 4 | O10: =N10*(K10+L10) -> 16 | P10: 30
A11: Gifte | B11: profan | C11: Leichtes Taubheitsgift | D11: 5 | E11: J | F11: Körper | G11: 1 KR | H11: 3 KR | I11: 1h | J11: BE 2, Gefahrensinn -12 | K11: 2 | L11: 0 | M11: 2 | N11: 1 | O11: =N11*(K11+L11) -> 2 | P11: 12
A12: Gifte | B12: profan | C12: Taubheitsgift | D12: 15 | E12: J | F12: Körper | G12: 1 KR | H12: 3 KR | I12: 1h | J12: BE 2, Gefahrensinn -12 | K12: 3 | L12: 0 | M12: 3 | N12: 2 | O12: =N12*(K12+L12) -> 6 | P12: 18
A13: Gifte | B13: profan | C13: Starkes Taubheitsgift | D13: 30 | E13: J | F13: Körper | G13: 1 KR | H13: 3 KR | I13: 1h | J13: BE 2, Gefahrensinn -12 | K13: 4 | L13: 0 | M13: 4 | N13: 4 | O13: =N13*(K13+L13) -> 16 | P13: 30
... A119: Zustandstränke | B119: profan | C119: Geruchslossalbe | D119: 75 | E119: N | F119: Kontakt | G119: 2 KR | H119: 5 KR | I119: 6h | J119: Man verliert seinen Geruch komplett | K119: 2 | L119: 0 | M119: 5 | N119: 25 | O119: =N119*(K119+L119) -> 50 | P119: 12

Sheet Ruestungstabelle
B1: Kopf | C1: Verarbeitung | D1: Anpassung | E1: RS | F1: BE | G1: Preis | H1: NW | I1: AW
A2: Lage 1 | B2: Stoffrüstung | C2: Meisterarbeit | D2: angepasst | E2: 3 | F2: 1 | G2: 227 | H2: 3 | I2: 2
A3: Lage 2 | B3: Leichte Lederrüstung | C3: Meisterarbeit | D3: angepasst | E3: 4 | F3: 2 | G3: 274 | H3: 3 | I3: 2
A4: Lage 3 | B4: Stahl-Kettenpanzer | C4: Meisterarbeit | D4: angepasst | E4: 6 | F4: 3 | G4: 1830 | H4: 3 | I4: 2
A5: Lage 4 | B5: Schwerer Lederpanzer | C5: Meisterarbeit | D5: angepasst | E5: 6 | F5: 4 | G5: 562 | H5: 3 | I5: 2
A6: Lage 5 | B6: Keine Rüstung | E6: 0 | F6: 0 | G6: 0 | H6: 0 | I6: 0
C7: Kopf | D7: Gesamt: | E7: 19 | F7: 10 | G7: 2893
B8: Torso | C8: Verarbeitung | D8: Anpassung | E8: RS | F8: BE | G8: Preis | H8: NW | I8: AW
A9: Lage 1 | B9: Stoffrüstung | C9: Großmeisterarbeit | D9: perfekt angepasst | E9: 4 | F9: 1 | G9: 387 | H9: 5 | I9: 3
A10: Lage 2 | B10: Leichte Lederrüstung | C10: Gesellenarbeit | D10: angepasst | E10: 3 | F10: 2 | G10: 38 | H10: 3 | I10: 2
A11: Lage 3 | B11: Eisen-Kettenpanzer | C11: Gesellenarbeit | D11: angepasst | E11: 4 | F11: 3 | G11: 372 | H11: 3 | I11: 2
A12: Lage 4 | B12: Schwerer Faltstahlpanzer | C12: Einzelstück | D12: perfekt angepasst | E12: 14 | F12: 7 | G12: 6495 | H12: 7 | I12: 7
A13: Lage 5 | B13: Keine Rüstung | E13: 0 | F13: 0 | G13: 0 | H13: 0 | I13: 0
C14: Torso | D14: Gesamt: | E14: 25 | F14: 13 | G14: 7292
B15: Arme | C15: Verarbeitung | D15: Anpassung | E15: RS | F15: BE | G15: Preis | H15: NW | I15: AW
A16: Lage 1 | B16: Stoffrüstung | C16: Gesellenarbeit | D16: angepasst | E16: 2 | F16: 1 | G16: 50 | H16: 3 | I16: 2
A17: Lage 2 | B17: Leichte Lederrüstung | C17: Gesellenarbeit | D17: angepasst | E17: 3 | F17: 2 | G17: 38 | H17: 3 | I17: 2
A18: Lage 3 | B18: Eisen-Kettenpanzer | C18: Gesellenarbeit | D18: angepasst | E18: 4 | F18: 3 | G18: 372 | H18: 3 | I18: 2
A19: Lage 4 | B19: Schwerer Lederpanzer | C19: Gesellenarbeit | D19: angepasst | E19: 5 | F19: 4 | G19: 208 | H19: 3 | I19: 2
A20: Lage 5 | B20: Keine Rüstung | E20: 0 | F20: 0 | G20: 0 | H20: 0 | I20: 0
C21: Arme | D21: Gesamt: | E21: 14 | F21: 10 | G21: 668
B22: Beine | C22: Verarbeitung | D22: Anpassung | E22: RS | F22: BE | G22: Preis | H22: NW | I22: AW
A23: Lage 1 | B23: Stoffrüstung | C23: Gesellenarbeit | D23: angepasst | E23: 2 | F23: 1 | G23: 50 | H23: 3 | I23: 2
A24: Lage 2 | B24: Leichte Lederrüstung | C24: Gesellenarbeit | D24: angepasst | E24: 3 | F24: 2 | G24: 38 | H24: 3 | I24: 2
A25: Lage 3 | B25: Eisen-Kettenpanzer | C25: Gesellenarbeit | D25: angepasst | E25: 4 | F25: 3 | G25: 372 | H25: 3 | I25: 2
A26: Lage 4 | B26: Schwerer Lederpanzer | C26: Gesellenarbeit | D26: angepasst | E26: 5 | F26: 4 | G26: 208 | H26: 3 | I26: 2
A27: Lage 5 | B27: Keine Rüstung | E27: 0 | F27: 0 | G27: 0 | H27: 0 | I27: 0
C28: Beine | D28: Gesamt: | E28: 14 | F28: 10 | G28: 668
F29: BE | G29: Preis
C30: Rüstung | D30: Gesamt: | F30: 43 | G30: 11521
A31: Legende:
A32: Hals, Schultergelenk, Ellenbogen, Hände, Knie und Füße werden nur mit halbem RS geschützt. Augen werden nicht geschützt.Für alle nicht genannten kritischen Trefferzonen gilt der volle Rüstungswert.
A33: Jedes Rüstungsteil kann durch Verarbeitung und Anpassung einmalig modifiziert werden.
A34: Jedes Rüstungsteil hat seine Lage als Mindest-RBE. Lage 5 (Umhänge, Aufpanzerungen) sind hiervon ausgenommen.
A35: Drachenschuppen und andere Aufpanzerungen verfügen über bestimmte Boni, die derzeit noch in der alten Waffentabelle aufgeführt sind...
A36: Rüstung | B36: Lage | C36: RS | D36: BE | F36: Verfügbarkeit NW | G36: Verfügbarkeit AW | H36: Materialkosten | I36: Arbeitszeit/d
A37: Keine Rüstung
A38: Leichte Stoffrüstung | B38: 1 | C38: 1 | D38: 1 | F38: 1 | G38: 1 | H38: 16 | I38: 1
A39: Stoffrüstung | B39: 1 | C39: 2 | D39: 2 | F39: 1 | G39: 1 | H39: 32 | I39: 1
A40: Schwere Stoffrüstung | B40: 1 | C40: 3 | D40: 3 | F40: 1 | G40: 1 | H40: 48 | I40: 1
...

Sheet NK-Material
A1: Waffe | B1: Stä-Malus | C1: AT- | D1: PA- | E1: WK | F1: 1H min.Stä | G1: 2H min.Stä | H1: Preis | I1: Klingen-Brecher | J1: Klingen-Schutz | L1: Art/Specials | M1: Rezept-Mod
A2: Eisen | F2: 1 | G2: 1 | H2: 50 | K2: Standard | M2: 10
A3: Stahl | B3: 1 | D3: 1 | E3: -0.5 | F3: 0.9 | G3: 0.9 | H3: 125 | I3: 1 | J3: 1 | K3: ALLE | M3: 12
A4: Qualitätsstahl | B4: 1 | D4: 1 | E4: -0.5 | F4: 0.9 | G4: 0.9 | H4: 175 | I4: 2 | J4: 2 | K4: ALLE | M4: 18
A5: Faltstahl | B5: 2 | D5: 1 | E5: -0.5 | F5: 0.8 | G5: 0.8 | H5: 250 | I5: 3 | J5: 3 | K5: ALLE | M5: 30
A6: Mithril | B6: -1 | D6: 2 | E6: -2 | F6: 0.5 | G6: 0.5 | H6: 1250 | I6: 0 | J6: 2 | K6: ALLE | M6: 20
A7: Kolhartz | B7: -1 | C7: 1 | D7: 2 | E7: -1 | F7: 0.5 | G7: 0.5 | H7: 1500 | I7: 0 | J7: 0 | K7: Zentauren | M7: 5
A8: Alchemistensilb. | B8: 0 | C8: -1 | F8: 1 | G8: 1 | H8: 1500 | I8: -1 | J8: -1 | K8: ALLE | M8: 8
A9: Nasium | B9: 0 | C9: -1 | D9: -1 | E9: -1 | F9: 1.2 | G9: 1.2 | H9: 1500 | I9: -1 | J9: -1 | K9: ALLE | M9: 7
A10: Diamantspat | B10: 3 | D10: 1 | E10: -0.5 | F10: 0.8 | G10: 0.8 | H10: 88 | I10: 3 | J10: 3 | K10: Drow | L10: Zerfällt bei kontakt mit Sonnenlicht zu Staub | M10: 12
A11: Adamandit | B11: 3 | D11: 1 | E11: -0.5 | F11: 0.8 | G11: 0.8 | H11: 250000 | I11: 3 | J11: 6 | K11: ALLE | M11: 120
A12: Holz | B12: -3 | C12: 2 | D12: 2 | E12: -1.5 | F12: 0.5 | G12: 0.5 | H12: 0.1 | I12: -11 | J12: -7 | K12: ALLE | M12: 0
A13: Knochen | B13: 0 | C13: 1 | D13: 2 | E13: -1 | F13: 0.5 | G13: 0.5 | H13: 0.1 | I13: -4 | J13: -5 | K13: ALLE | M13: 2
A14: Stein | B14: 0 | C14: -3 | D14: -2 | E14: 1 | F14: 1.3 | G14: 1.3 | H14: 0.1 | I14: -2 | J14: -3 | K14: ALLE | M14: 5
A15: Schwarzfells | B15: 0 | C15: -2 | D15: -1 | E15: 1 | F15: 1.1 | G15: 1.1 | H15: 0.25 | I15: -2 | J15: -2 | K15: Indianer | M15: 4
A16: Leder | B16: 0 | E16: 0 | F16: 1 | G16: 1 | H16: 0.3 | K16: ALLE | M16: 5
A17: Hartholz | B17: -2 | C17: 1 | D17: 2 | E17: -1 | F17: 0.7 | G17: 0.7 | H17: 3 | I17: -7 | J17: -5 | K17: ALLE | L17: Der Schaden wird zur hälfte auf Ausdauer verteielt | M17: 3
A18: Vulkanglas | B18: -1 | C18: -3 | D18: -2 | E18: -1 | F18: 1.1 | G18: 1.1 | H18: 3 | I18: -4 | J18: -5 | K18: Indianer | M18: 5
A19: Chitin | B19: 0 | C19: -1 | D19: 2 | E19: -1 | F19: 0.5 | G19: 0.5 | H19: 20 | I19: -2 | K19: ALLE | M19: 3
A20: Bronze | B20: -1 | C20: -1 | E20: 0.5 | F20: 1.1 | G20: 1.1 | H20: 25 | I20: -2 | J20: -2 | K20: ALLE | M20: 5

Sheet NK-Anpassung
A1: Anpassung | B1: Stä-Malus | C1: AT- | D1: PA- | E1: WK | F1: Min.Stä. 1H | G1: Min.Stä. 2H | H1: Preis | I1: Klingen Brecher | J1: Klingen Schutz | K1: Volk | L1: Art/Specials | N1: Arbeitszeit/d
A2: Von der Stange | H2: 1 | K2: Standard | M2: 0 | N2: 0
A3: angepasst | C3: 1 | D3: 1 | G3: -2 | H3: 2 | K3: ALLE | M3: 6 | N3: 1
A4: Perfekt angepasst | C4: 2 | D4: 2 | G4: -4 | H4: 5 | K4: ALLE | M4: 12 | N4: 2

Sheet NK-Schaftmaterial
A1: Verstärkung des Schafts | B1: Stä-Malus | C1: AT- | D1: PA- | E1: WK | F1: Min.Stä. 1H | G1: Min.Stä. 2H | H1: Preis/m | I1: Klingen Brecher | J1: Klingen Schutz | K1: Volk | L1: Art/Specials
A2: Standard | M2: 0
A3: Eisen Verstärkt | C3: -1 | D3: -1 | G3: 2 | H3: 37.5 | J3: 2 | K3: ALLE | M3: 10 | N3: 0.5
A4: Eisen Voll | C4: -2 | D4: -2 | G4: 3 | H4: 275 | J4: 3 | K4: ALLE | M4: 10 | N4: 0.5
A5: Stahl Verstärkt | C5: -1 | D5: -1 | G5: 2 | H5: 93.75 | J5: 3 | K5: ALLE | M5: 12 | N5: 0.5
A6: Stahl Voll | C6: -2 | D6: -2 | G6: 3 | H6: 687.5 | J6: 4 | K6: ALLE | M6: 12 | N6: 0.5
A7: Qualitätsstahl | C7: -1 | D7: -1 | G7: 2 | H7: 131.25 | J7: 4 | K7: ALLE | M7: 18 | N7: 0.5
A8: Qualitätsstahl Voll | C8: -2 | D8: -2 | G8: 3 | H8: 962.5 | J8: 5 | K8: ALLE | M8: 18 | N8: 0.5
A9: Faltstahl Verstärkt | C9: -1 | D9: -1 | G9: 2 | H9: 187.5 | J9: 5 | K9: ALLE | M9: 30 | N9: 0.5
A10: Faltstahl Voll | C10: -2 | D10: -2 | G10: 3 | H10: 1375 | J10: 6 | K10: ALLE | M10: 30 | N10: 0.5
A11: Mithril Verstärkt | C11: 0 | D11: -1 | G11: 1 | H11: 1875 | J11: 2 | K11: ALLE | M11: 20 | N11: 0.5
A12: Mithril Voll | C12: -1 | D12: -1 | G12: 1 | H12: 13750 | J12: 3 | K12: ALLE | M12: 20 | N12: 0.5
A13: Adamandit Verst. | C13: -1 | D13: -1 | G13: 2 | H13: 187500 | J13: 6 | K13: ALLE | M13: 120 | N13: 0.5
A14: Adamantit Voll | C14: -2 | D14: -2 | G14: 3 | H14: 137500 | J14: 7 | K14: ALLE | M14: 120 | N14: 0.5
... A16: Bronze Voll | C16: -2 | D16: -2 | G16: 3 | H16: 137.5 | J16: 2 | K16: ALLE | M16: 5 | N16: 0.5

Sheet NK-Fertigung
A1: Fertigung | B1: Stä-Malus | C1: AT- | D1: PA- | E1: WK | F1: Min.Stä. 1H | G1: Min.Stä. 2H | H1: Preis | I1: Klingen Brecher | J1: Klingen Schutz | K1: Volk | L1: Art/Specials
A2: Ausschuss | H2: 1.5 | I2: -3 | J2: -6 | K2: ALLE | M2: -6
A3: Goblin Massenfab. | H3: 2 | I3: -2 | J3: -3 | K3: Goblin | M3: -4
A4: Massenfabrikation | H4: 4 | I4: -1 | J4: -1 | K4: ALLE | M4: -3
A5: Gesellenarbeit | H5: 6 | K5: Standard | M5: 0
A6: Meisterarbeit | H6: 65 | I6: 1 | J6: 1 | K6: ALLE | M6: 6
A7: Großmeisterarbeit | H7: 71 | I7: 2 | J7: 2 | K7: ALLE | M7: 12
A8: Einzelstück | H8: 142 | I8: 3 | J8: 3 | K8: ALLE | M8: 24

Sheet NK-Waffen-Basis
A1: Hauptfertigkeit | B1: Spezialisierung | C1: Waffe | D1: Ini | E1: WK-Basis | F1: Schadenswuerfel-1 | G1: Schadenswuerfel-2 | H1: Staerke-Teiler | I1: Staerke-Malus-Basis | J1: RB | K1: AT-Basis | L1: PA-Basis | M1: Min-Staerke-1H-Basis | N1: Min-Staerke-2H-Basis | O1: Laenge-m | P1: Tarnung | Q1: Art-Specials | R1: Klingenbrecher-Basis | S1: Klingenschutz-Basis | T1: Rezept-Mod-Basis | U1: Materialpreis-Faktor | V1: Arbeitszeit-Tag-Basis | W1: Volk | X1: Fert-Spez-Maximum | Y1: RS-Basis | Z1: Preis-Basis
A2: Unbewaffnet | B2: Armklingen | C2: Armklingen | D2: 5 | E2: 3 | F2: W10 | G2: W6 | H2: 3 | I2: -6 | J2: 0 | K2: -2 | L2: -4 | M2: 8 | O2: 0.5 | P2: 0 | Q2: Schnell | R2: 12 | S2: 14 | T2: 10 | U2: 0.7 | V2: 3
A3: Stichwaffen | B3: Fechtwaffen | C3: Armklingen | D3: 5 | E3: 3 | F3: W10 | G3: W6 | H3: 3 | I3: -6 | J3: 0 | K3: -2 | L3: -4 | M3: 8 | O3: 0.5 | P3: 0 | Q3: Schnell | R3: 12 | S3: 14 | T3: 10 | U3: 0.7 | V3: 3
A4: Unbewaffnet | B4: Armklingen | C4: Armklingen elfisch | D4: 5 | E4: 2.5 | F4: W12 | G4: W4 | H4: 3 | I4: -6 | J4: 0 | K4: -2 | L4: -3 | M4: 7 | O4: 0.5 | P4: 0 | Q4: Schnell | R4: 12 | S4: 13 | T4: 12 | U4: 0.6 | V4: 4
A5: Hiebwaffen | B5: Äxte | C5: Axt | D5: 7 | E5: 6 | F5: W20 | H5: 2 | I5: -6 | J5: 0 | K5: -4 | L5: -5 | M5: 17 | N5: 10 | O5: 0.72 | P5: 3 | Q5: Holzschaft | R5: 17 | S5: 7 | T5: 8 | U5: 1.8 | V5: 1.5
A6: Stichwaffen | B6: Fechtwaffen | C6: Bajonett abgepflanzt | D6: 6 | E6: 3 | F6: W12 | G6: W4 | H6: 5 | I6: -3 | J6: 0 | K6: -3 | L6: -5 | M6: 7 | N6: 5 | O6: 0.6 | P6: 4 | R6: 9 | S6: 15 | T6: 5 | U6: 0.6 | V6: 1
A7: Stangenwaffen | B7: Speere | C7: Bajonett aufgepflanzt | D7: 21 | E7: 3 | F7: W12 | G7: W4 | H7: 5 | I7: -4 | J7: 0 | K7: -5 | L7: -5 | M7: wie Feuerwaffe*2 | N7: wie Feuerwaffe | O7: 2 | P7: 4 | R7: 3 | S7: 8 | T7: 5 | U7: 0.6 | V7: 1
A8: Hiebwaffen | B8: Beidhand-Hiebwaffen | C8: Barbarendoppelaxt | D8: 14 | E8: 8 | F8: W20 | G8: [2W12] | H8: 1.5 | I8: -16 | J8: 0 | K8: -7 | L8: -7 | M8: 36 | N8: 20 | O8: 1.4 | P8: -- | Q8: Holzschaft | R8: 23 | S8: 8 | T8: 24 | U8: 3.5 | V8: 2.5
A9: Klingenwaffen | B9: Schwerter | C9: Barbarenschwert | D9: 11 | E9: 6 | F9: W10 | G9: W8 | H9: 2 | I9: -5 | J9: 0 | K9: -5 | L9: -5 | M9: 16 | N9: 12 | O9: 1.1 | P9: -- | R9: 14 | S9: 15 | T9: 16 | U9: 1.5 | V9: 4
A10: Klingenwaffen | B10: Zweihänder | C10: Barbarenschwert | D10: 11 | E10: 6 | F10: W10 | G10: W8 | H10: 2 | I10: -5 | J10: 0 | K10: -5 | L10: -5 | M10: 16 | N10: 12 | O10: 1.1 | P10: -- | R10: 14 | S10: 15 | T10: 16 | U10: 1.5 | V10: 4
A11: Klingenwaffen | B11: Schwerter | C11: Bastardschwert | D11: 13 | E11: 6 | F11: W15 | G11: W10 | H11: 2 | I11: -8 | J11: 0 | K11: -5 | L11: -4 | M11: 20 | N11: 13 | O11: 1.3 | P11: -- | R11: 14 | S11: 15 | T11: 19 | U11: 2 | V11: 4
A12: Klingenwaffen | B12: Zweihänder | C12: Bastardschwert | D12: 13 | E12: 6 | F12: W15 | G12: W10 | H12: 2 | I12: -8 | J12: 0 | K12: -5 | L12: -4 | M12: 20 | N12: 13 | O12: 1.3 | P12: -- | R12: 14 | S12: 15 | T12: 19 | U12: 2 | V12: 4
A13: Klingenwaffen | B13: Zweihänder | C13: Bat'leth orkisch | D13: 11 | E13: 5.5 | F13: W10 | G13: W10 | H13: 2 | I13: -8 | J13: 0 | K13: -3 | L13: -3 | M13: 15 | N13: 9 | O13: 1.16 | P13: -- | Q13: Schnell | R13: 14 | S13: 14 | T13: 24 | U13: 3 | V13: 8
A14: Stangenwaffen | B14: Stäbe | C14: Bat'leth kurz | D14: 10 | E14: 4 | F14: W12 | G14: W6 | H14: 2 | I14: -8 | J14: 0 | K14: -3 | L14: -4 | M14: 13 | N14: 8 | O14: 1 | P14: 0 | R14: 14 | S14: 14 | T14: 20 | U14: 2 | V14: 8
A15: Klingenwaffen | B15: Zweihänder | C15: Bat'leth kurz | D15: 10 | E15: 4 | F15: W12 | G15: W6 | H15: 2 | I15: -8 | J15: 0 | K15: -3 | L15: -4 | M15: 13 | N15: 8 | O15: 1 | P15: 0 | R15: 14 | S15: 14 | T15: 20 | U15: 2 | V15: 8
A16: Hiebwaffen | B16: Äxte | C16: Beil | D16: 4 | E16: 5 | F16: W20 | H16: 3 | I16: -5 | J16: 0 | K16: -5 | L16: -5 | M16: 12 | N16: 8 | O16: 0.4 | P16: 6 | Q16: Holzschaft | R16: 16 | S16: 7 | T16: 6 | U16: 0.6 | V16: 1
A17: Hiebwaffen | B17: Beidhand-Hiebwaffen | C17: Berdysch | D17: 13 | E17: 6.5 | F17: W20 | G17: W6 | H17: 2 | I17: -8 | J17: 0 | K17: -6 | L17: -5 | M17: 24 | N17: 14 | O17: 1.4 | P17: -- | Q17: Holzschaft | R17: 18 | S17: 7 | T17: 18 | U17: 2 | V17: 2
A18: Stangenwaffen | B18: Hellebarden | C18: Berdysch | D18: 13 | E18: 6.5 | F18: W20 | G18: W6 | H18: 2 | I18: -8 | J18: 0 | K18: -6 | L18: -5 | M18: 24 | N18: 14 | O18: 1.4 | P18: -- | Q18: Holzschaft | R18: 18 | S18: 7 | T18: 18 | U18: 2 | V18: 2
A19: Klingenwaffen | B19: Schwerter | C19: Breitschwert | D19: 9 | E19: 6 | F19: W10 | G19: W10 | H19: 3 | I19: -4 | J19: 0 | K19: -4 | L19: -4 | M19: 14 | N19: 10 | O19: 0.9 | P19: 2 | R19: 16 | S19: 15 | T19: 14 | U19: 1 | V19: 4
A20: Klingenwaffen | B20: Zweihänder | C20: Claymore | D20: 16 | E20: 7.5 | F20: W15 | G20: W12 | H20: 1.5 | I20: -11 | J20: 0 | K20: -7 | L20: -6 | M20: 28 | N20: 16 | O20: 1.6 | P20: -- | R20: 17 | S20: 13 | T20: 24 | U20: 2.5 | V20: 5
A21: Klingenwaffen | B21: Zweihänder | C21: Dai Katana | D21: 14 | E21: 6.5 | F21: 2W12 | H21: 2 | I21: -8 | J21: 0 | K21: -4 | L21: -4 | M21: 22 | N21: 13 | O21: 1.35 | P21: -- | R21: 16 | S21: 14 | T21: 25 | U21: 1.2 | V21: 5
A22: Stichwaffen | B22: Fechtwaffen | C22: Degen | D22: 13 | E22: 3.5 | F22: W15 | H22: 7 | I22: -2 | J22: 0 | K22: -2 | L22: 0 | M22: 9 | N22: 6 | O22: 1.2 | P22: 1 | R22: 7 | S22: 14 | T22: 18 | U22: 0.75 | V22: 4
A23: Stichwaffen | B23: Dolche | C23: Dolch | D23: 3 | E23: 2 | F23: W15 | H23: 5 | I23: -3 | J23: 0 | K23: -1 | L23: -6 | M23: 6 | N23: 4 | O23: 0.3 | P23: 8 | R23: 12 | S23: 17 | T23: 5 | U23: 0.3 | V23: 1
A24: Stichwaffen | B24: Dolche | C24: Dolch ork, Blutrinne | D24: 3 | E24: 1 | F24: W15 | H24: 6 | I24: -3 | J24: 0 | K24: -1 | L24: -6 | M24: 6 | N24: 4 | O24: 0.3 | P24: 8 | Q24: Starke Blutung (x2) | R24: 12 | S24: 15 | T24: 7 | U24: 0.4 | V24: 2
A25: Stichwaffen | B25: Dolche | C25: Dolch orkisch, breit | D25: 3 | E25: 2 | F25: W15 | H25: 4 | I25: -4 | J25: 0 | K25: -2 | L25: -5 | M25: 7 | N25: 5 | O25: 0.3 | P25: 7 | R25: 12 | S25: 18 | T25: 5 | U25: 0.4 | V25: 1
A26: Stichwaffen | B26: Dolche | C26: Dolch orkisch, mit 3 eingedrehten Klingen | D26: 3 | E26: 3 | F26: W20 | H26: 3 | I26: -7 | J26: 0 | K26: -2 | L26: -5 | M26: 10 | N26: 8 | O26: 0.35 | P26: 4 | R26: 13 | S26: 18 | T26: 15 | U26: 0.5 | V26: 4
A27: Hiebwaffen | B27: Äxte | C27: Doppelaxt leicht | D27: 8 | E27: 6 | F27: W20 | H27: 3 | I27: -4 | J27: 0 | K27: -5 | L27: -6 | M27: 20 | N27: 14 | O27: 0.8 | P27: 0 | Q27: Holzschaft | R27: 17 | S27: 8 | T27: 15 | U27: 2.2 | V27: 2.5
A28: Hiebwaffen | B28: Äxte | C28: Doppelaxt zwergisch | D28: 9 | E28: 7.5 | F28: W20 | G28: W15 | H28: 2 | I28: -12 | J28: 0 | K28: -7 | L28: -6 | M28: 28 | N28: 16 | O28: 0.9 | P28: -- | Q28: Holzschaft | R28: 22 | S28: 8 | T28: 19 | U28: 2.5 | V28: 3
A29: Hiebwaffen | B29: Äxte | C29: Doppelbeil Zw. kurz | D29: 5 | E29: 6 | F29: W20 | G29: [2W10] | H29: 3 | I29: -11 | J29: 0 | K29: -5 | L29: -4 | M29: 18 | N29: 12 | O29: 0.55 | P29: 3 | Q29: Holzschaft | R29: 18 | S29: 8 | T29: 19 | U29: 1.5 | V29: 3
A30: Stangenwaffen | B30: Hellebarden | C30: Doppelblatthellebarde | D30: 18 | E30: 7 | F30: W20 | G30: W4 | H30: 2 | I30: -9 | J30: 0 | K30: -6 | L30: -6 | M30: 36 | N30: 16 | O30: 1.8 | P30: -- | Q30: Holzschaft | R30: 17 | S30: 7 | T30: 19 | U30: 3 | V30: 5
A31: Stangenwaffen | B31: Stäbe | C31: Doppelhellebarde (Kampfstab 2 Hellebarden) | D31: 10 | E31: 6 | F31: W15 | G31: W8 | H31: 3 | I31: -7 | J31: 0 | K31: -4 | L31: -4 | M31: 46 | N31: 18 | O31: 1.8 | P31: -- | Q31: Holzschaft | R31: 16 | S31: 7 | T31: 16 | U31: 3 | V31: 5
A32: Stangenwaffen | B32: Hellebarden | C32: Doppelsense | D32: 10 | E32: 5 | F32: W15 | G32: W6 | H32: 4 | I32: -6 | J32: 0 | K32: -5 | L32: -5 | M32: 33 | N32: 11 | O32: 1.8 | P32: -- | Q32: Holzschaft, Schnell | R32: 12 | S32: 6 | T32: 12 | U32: 1 | V32: 1
A33: Klingenwaffen | B33: Zweihänder | C33: Doppelsense | D33: 10 | E33: 5 | F33: W15 | G33: W6 | H33: 4 | I33: -6 | J33: 0 | K33: -5 | L33: -5 | M33: 33 | N33: 11 | O33: 1.8 | P33: -- | Q33: Holzschaft, Schnell | R33: 12 | S33: 6 | T33: 12 | U33: 1 | V33: 1
A34: Hiebwaffen | B34: Beidhand-Hiebwaffen | C34: Dornenkeule troll, | D34: 16 | E34: 8 | F34: W15 | G34: W12 | H34: 1.5 | I34: -11 | J34: 2 | K34: -6 | L34: -7 | M34: 35 | N34: 20 | O34: 1.8 | P34: -- | Q34: Holzschaft | R34: 14 | S34: 11 | T34: 1 | U34: 0.25 | V34: 1
A35: Unbewaffnet | B35: Peitschen | C35: Dornenpeitsche | D35: 28 | E35: 0 | F35: W4 | G35: W4 | H35: 5 | I35: -1 | J35: 0 | K35: -7 | L35: -15 | M35: 10 | N35: 7 | O35: 3 | P35: 6 | R35: 1 | S35: 7 | T35: 7 | U35: 0.1 | V35: 0.5
A36: Unbewaffnet | B36: Schild | C36: Drachenschild | E36: 11 | F36: 2W8 | H36: 3 | I36: -5 | J36: 0 | K36: -7 | L36: 9 | M36: 19 | P36: -- | R36: 15 | S36: 13 | T36: 15 | Y36: 17 | Z36: 600
A37: Unbewaffnet | B37: Armklingen | C37: Drei Langklauen | D37: 4 | E37: 3 | F37: W8 | G37: W6 | H37: 3 | I37: -5 | J37: 0 | K37: -3 | L37: -6 | M37: 8 | O37: 0.4 | P37: 0 | R37: 7 | S37: 11 | T37: 8 | U37: 0.4 | V37: 1
A38: Unbewaffnet | B38: Schild | C38: Dreiecksschild | E38: 8 | F38: W8 | G38: W6 | H38: 3 | I38: -5 | J38: 0 | K38: -6 | L38: 7 | M38: 17 | P38: -- | R38: 15 | S38: 15 | T38: 15 | Y38: 16 | Z38: 400
A39: Unbewaffnet | B39: Schild | C39: Dreiecksschild klein | E39: 6 | F39: W8 | G39: W6 | H39: 3 | I39: -5 | J39: 0 | K39: -5 | L39: 6 | M39: 15 | P39: -- | R39: 15 | S39: 15 | T39: 15 | Y39: 15 | Z39: 300
A40: Stangenwaffen | B40: Speere | C40: Dreizack | D40: 18 | E40: 5 | F40: W12 | G40: W8 | H40: 3 | I40: -6 | J40: 0 | K40: -5 | L40: -3 | M40: 22 | N40: 12 | O40: 1.8 | P40: -- | Q40: Holzschaft | R40: 7 | S40: 7 | T40: 5 | U40: 1 | V40: 1.5
...

Sheet Entwickeln
A1: Bereich | B1: Thema | C1: Beschreibung | D1: Status | E1: Hinzugefuegt
A2: Ausruestung/Schilde | B2: Schild-Preise/Rezept/Materialpreis | C2: 14 Schildzeilen mit #WERT!-Fehlern in NK-Waffen-Basis: Preis/Rezeptschwierigkeit/Materialpreis nicht uebernommen. Die Schilde-Quelltabelle (NN Schilde v0.1.xlsx) hat Materialpreis/Arbeitszeit/Rezept-Mod-Basis komplett unausgefuellt ('x'/'X'), und ihre Basiswerte gelten teils mit Holz statt Eisen als Grundmaterial, nicht kompatibel mit dem NK-Waffen-Materialsystem. Zeilen sind uebernommen, aber als 'aktuell nicht ausruestbar' markiert. Muss von Grund auf neu entwickelt werden (eigenes Material-/Preissystem fuer Schilde, ggf. eigene Normalisierung auf ein einheitliches Basismaterial). -- GELOEST 2026-07-16: 'Schilde v1.4.docx' vom Nutzer bereitgestellt, enthaelt saubere Preis-Basis (100D-1200D) je Schild sowie eigene Material-/Fertigungs-/Bespannungs-Tabellen (multiplikatives Preissystem, siehe Sheets Schild-Material/Schild-Fertigung/Schild-Bespannung). Ausserdem dabei einen Vorzeichenfehler gefunden und korrigiert: 11 der 12 Schilde hatten Staerke-Malus-Basis=+5 statt korrekt -5 in NK-Waffen-Basis. | D2: Geloest | E2: 2026-07-16
A3: Ausruestung/Ruestung | B3: Panzerhandschuhe, Panzerschienen, Eisenkappenstiefel, Orkischer Kampfhandschuh | C3: Ruestungswerte fehlen fuer diese vier Gegenstaende in der Ruestungstabelle (es existiert kein Haende-/Fuesse-Slot, nur Kopf/Torso/Arme/Beine). Rezept-Mod-Basis/Materialpreis-Faktor/Arbeitszeit-Tag-Basis in NK-Waffen-Basis daher = X/x/x. Braucht: (a) Ruestungswerte-System fuer Haende/Fuesse allgemein, (b) konkrete Werte fuer diese 4 Items. | D3: Offen | E3: 2026-07-16
A4: Ausruestung/Ruestung | B4: Ruestungsmodifikatoren/Ruestungsteile-System | C4: Es existiert kein Pendant zu NK-Material/NK-Fertigung/NK-Anpassung/NK-Schaftmaterial fuer Ruestung. Muss komplett neu entwickelt werden, analog zur NK-Waffen-Modifikatorkette. -- GELOEST 2026-07-16: System steckte bereits vollstaendig in NN NPC-Rechner 0.76.xlsx, Sheet 'RS-Sheet' (Nutzerhinweis). Als Sheets Ruestung-Basis (20 Ruestungsteile), Ruestung-Addons (4 Aufpanzerungen, Lage 5), Ruestung-Verarbeitung (4 Stufen), Ruestung-Anpassung (4 Stufen) umgesetzt. Formel (RS = Basis + Verarbeitung; BE = MAX(Lage; Basis+Verarbeitung+Anpassung); Preis = Materialkosten + Lohn*(Arbeitszeit+Zusatztage); Verfuegbarkeit = MAX ueber alle 3 Komponenten) gegen das bestehende Beispiel-Set in Sheet Ruestungstabelle verifiziert (Stoffruestung+Meisterarbeit+angepasst -> RS=3/BE=1/Preis=227/NW=3/AW=2, alle 5 Werte exakt reproduziert). | D4: Geloest | E4: 2026-07-16
A5: Ausruestung/Waffen | B5: Ork'sche (FK/NK-Hybrid) | C5: Pistole/Muskete, die gleichzeitig als Nahkampfwaffe zaehlt. Nur ueber Fertigung/Anpassung modifizierbar, Preis stammt aus der FK-Tabelle; die NK-Version wird beim Kauf der FK-Waffe automatisch mitgeliefert. Grenzfall zwischen FK- und NK-System, noch nicht in NK-Waffen-Basis integriert. | D5: Offen | E5: 2026-07-16
A6: Ausruestung/NK-Waffen | B6: Rezeptschwierigkeit generell | C6: 14 Zeilen mit Rezept-Mod-Basis=X: Wert in der Originalquelle (NN NK-Waffentabelle v1.12) nie ausgefuellt. Korrelation Rezeptschwierigkeit vs. Preis rechnerisch getestet (r=0.007) - kein statistischer Zusammenhang, kann nicht aus dem Preis rekonstruiert werden. Bleibt offen, bis eine inhaltliche Einschaetzung (Spielleitung) vorliegt. | D6: Offen | E6: 2026-07-16
A7: Nahkampf/Unbewaffnet | B7: Voelkerbeschraenkungen bei Unbewaffnet-Kampfstilen | C7: Boxen (Dalkini/Zwerg/Ork), Elfische Kunst der Selbstverteidigung (Elf), Goblinische Kampfkunst (Goblin), Katzenmenschen Kampfkunst (Katzenmensch), Orkisch' Raufen (Ork), Schattenkampf (Drow) sind laut Quelle (Nahkampftabelle Unbewaffnet.doc, 2004) an bestimmte Voelker gebunden. Diese Beschraenkung ist inhaltlich nicht geprueft/nachvollzogen (Nutzer: 'sehe ich persoenlich nicht ein') und sollte ueberarbeitet werden - ebenso die Kampfstile/Faehigkeiten selbst generell (Balance, Aktualitaet, Formulierung der Specials). | D7: Offen | E7: 2026-07-16
A8: Nahkampf/Unbewaffnet | B8: Dynamische Schadenswerte (Boxen, Ringen, Elfische Kunst) | C8: Boxen und Ringen haben Schaden/Staerke-Mod = 'wie unbewaffnet' (haengt von der Rasse des Charakters ab, siehe rassenabhaengige Unbewaffnet-Basiswerte in NK-Waffen-Basis). Elfische Kunst der Selbstverteidigung hat Schaden = 'gegnerischer' (spiegelt den Schaden des Gegners). Beides ist aktuell nur als Text in NK-Waffen-Basis hinterlegt, keine Formel - fehlt eine mechanische Aufloesung im Formel-System (Werte-Sheet). | D8: Offen | E8: 2026-07-16
A9: Nahkampf/Unbewaffnet | B9: Fert/Spez-Maximum Mechanik unklar | C9: Die Quelle gibt pro Kampfstil ein 'Fert/Spez-Maximum' an (z.B. 20/20, 25/30, 30/20). Rohwerte wurden 1:1 in NK-Waffen-Basis Spalte 'Fert-Spez-Maximum' uebernommen, aber die Bedeutung/Wirkung ist ungeklaert (Deckelt es nk_unbewaffnet? Die Spezialisierung? Beides getrennt?). | D9: Offen | E9: 2026-07-16
A10: Nahkampf/Unbewaffnet | B10: 'Staerkebonus' vs. 'Staerke-Mod' bei Biss-Angriffen | C10: Bei Ork- und Katzenmensch-Biss wird der Schaden mit '+[Staerkebonus]' angegeben - eine andere Notation als das sonst genutzte Staerke-Teiler/Staerke-Malus-System (z.B. '(Staerke:3)-7' bei Troll-Biss/Zentaur-Huftritt). Unklar, ob 'Staerkebonus' ein bereits vorhandener Wert im System ist oder neu definiert werden muss. | D10: Offen | E10: 2026-07-16
A11: Nahkampf/Unbewaffnet | B11: Vitalitaet als Ruestungsschutz gegen Unbewaffnet-/Fallschaden | C11: Laut Quelle gibt Vitalitaet einen zusaetzlichen Ruestungsschutz (RS) gegen Schaden durch Unbewaffnet-Angriffe oder Sturz/Fall. Noch nicht ins Ruestungs-/Schadenssystem integriert. | D11: Offen | E11: 2026-07-16
A12: Ausruestung/Schilde | B12: Chitin/Kolhartz Preis-Faktor als Spanne | C12: Schild-Material: Chitin ('*2,5 - *4') und Kolhartz ('*0,1 - *1000') geben in Schilde v1.4.docx eine Preis-Spanne statt eines Einzelwerts an (vermutlich abhaengig von Qualitaet/Seltenheit des Rohmaterials, analog zur Waffen-Materialtabelle, wo Chitin ebenfalls '*2,5 - *4' hat). Braucht eine Entscheidung, wie die Spanne genutzt wird (fester Wert? Wuerfelspanne? Spielleiter-Ermessen?). | D12: Offen | E12: 2026-07-16
... A37: Fernkampf/Sonderfertigkeit | B37: Ladeschuetze Schleuder | C37: Ladeschuetze Schleuder existiert als Sonderfertigkeit (sf_ladeschuetze_schleuder) und Talent (talente_ladeschuetze_schleuder), aber die Waffe 'Schleuder' existiert nicht als Fernkampf-Kategorie (nur Boegen/Blasrohre/Schusswaffen/Wurfwaffen existieren dort). Da die Sichtbarkeit der Ladeschuetze-SF im Sonderfertigkeit-Tab jetzt an die zugehoerige fk_*-Fertigkeit>0 gekoppelt ist, waere Ladeschuetze Schleuder nie freischaltbar gewesen. Auf Nutzerentscheidung 2026-07-19 deaktiviert (# vor Referenz in Werte-Sheet Zeile 192/1152 - Konvention siehe generate_data_ts.py read_rules()). | D37: Deaktiviert | E37: 2026-07-19

Sheet Schild-Material
A1: Material | B1: Staerke-Malus-Mod | C1: AT-Mod | D1: PA-Mod | E1: WK-Mod | F1: Klingenbrecher-Mod | G1: Klingenschutz-Mod | H1: RS-Mod | I1: Min-Staerke-Faktor | J1: Preis-Faktor | K1: Art-Specials
A2: Holz | B2: -6 | C2: 2 | D2: 2 | E2: -1.5 | F2: -11 | G2: -10 | H2: -5 | I2: 0.5 | J2: 0.2
A3: Hart Holz | B3: -5 | C3: 1 | D3: 2 | E3: -1 | F3: -4 | G3: -5 | H3: -3 | I3: 0.7 | J3: 3
A4: Leder | B4: 0 | C4: 3 | D4: 3 | E4: 0 | F4: -20 | G4: -15 | H4: -7 | I4: 0.45 | J4: 0.1
A5: Spinnenwebe | B5: -6 | C5: 3 | D5: 4 | E5: -2 | F5: -11 | G5: -5 | H5: 3 | I5: 0.4 | J5: 6 | K5: Nur Fernkampf-RS
A6: Chitin | B6: 0 | C6: 1 | D6: 2 | E6: -1 | F6: -2 | G6: 0 | H6: -4 | I6: 0.5 | J6: 3
A7: Drachensch. | B7: 0 | C7: 1 | D7: 2 | E7: -1 | F7: -2 | G7: 0 | H7: -3 | I7: 0.5 | J7: Meister (individuell durch Spielleitung)
A8: Stein | B8: 0 | C8: -3 | D8: -2 | E8: 1 | F8: -2 | G8: -3 | H8: -3 | I8: 1.3 | J8: 0.25
A9: Schwarzfells | B9: 0 | C9: -2 | D9: -1 | E9: 1 | F9: -2 | G9: -2 | H9: -1 | I9: 1.1 | J9: 0.5
A10: Diamantspart | B10: 3 | C10: 0 | D10: 1 | E10: -0.5 | F10: 3 | G10: 3 | H10: 6 | I10: 0.8 | J10: 1.75 | K10: 2 Wuerfe beim Bruchtest
A11: Bronze | B11: -1 | C11: -1 | D11: 0 | E11: 0.5 | F11: -2 | G11: -2 | H11: -2 | I11: 1.1 | J11: 0.5
